Workbook
Name tc: Set!$N$1
Name tc: Ago!$N$1

Sheet Abr (2)
A1: Período de Cálculo: | E1: 43191 | U1: Días en el mes | W1: =DATE(YEAR(E1),MONTH(E1)+1,1)-DATE(YEAR(E1),MONTH(E1),1) -> 30
A2: PERUPETRO S.A.
A3: DETERMINACION DEL CANON, SOBRECANON y PARTICIPACION (US$)
A4: ="Correspondiente a "&TEXT(E1,"MMMMMMM YYYY") -> Correspondiente a Abril 2018
A5: ="Tipo de Cambio= "&TEXT(F1,"0.000") -> Tipo de Cambio= 0.000
A7: Localidad | C7: Modalidad de Contrato | D7: Calculo del Canon | F7: Volumen Producción / Venta | I7: Canasta o Valor Venta (US$/Unidad) | K7: Deducción de Gastos para determinación de valor de producción en Punto de Fiscalización (US$) | O7: Valor de la Producción (US$) | P7: Canon y Sobrecanon / Participación (US$) | U7: Resumen por Petróleo y Condensados | AA7: Resumen por Gas Natural | AG7: Control
A8: - Lote | D8: Período | E8: Fórmula | F8: Unidades | G8: 1ra. Q | H8: 2da. Q / Mes | I8: 1ra. Q | J8: 2da. Q / Mes | K8: Flete Marítimo | L8: Comercialización | M8: Oleoducto | N8: Fiscalización | P8: Total | Q8: Localidad 1 | S8: Localidad 2 | U8: Producción / Venta | X8: Valor Prod | Y8: Valor Canon | AA8: Producción / Venta | AD8: Valor Prod | AE8: Valor Canon | AG8: Total
A9: Piura / Tumbes | Q9: Piura | S9: Tumbes | U9: Bls/Mes | V9: V P (US$) | W9: Bls/Día | X9: US$/Bl | Y9: US$/Bl | Z9: US$ | AA9: MM BTU/Mes | AB9: V P (US$) | AC9: MM BTU/Día | AD9: US$/MM BTU | AE9: US$/MM BTU | AF9: US$ | AG9: Canon
A10: - | B10: I | C10: Servicios | D10: Mes | E10: F1 | F10: Bls | H10: 21812 | J10: 69.0374 | N10: 675.6 | O10: =ROUND(G10*I10,2)+ROUND(H10*J10,2)-K10-L10-M10-N10 -> 1505168.2 | P10: =ROUND(18.75%*O10,2) -> 282219.03 | Q10: =ROUND($O10*R10,2) -> 225775.23 | R10: 0.15 | S10: =ROUND($O10*T10,2) -> 56443.81 | T10: 0.0375 | U10: =IF($F10&"/Día"=W$9,SUM($G10:$H10),"") -> 21812 | V10: =IF(U10<>"",$O10,"") -> 1505168.2 | W10: =IF($F10&"/Día"=W$9,ROUND(U10/$W$1,1),"") -> 727.1 | X10: =IF(U10=0,0,IF($F10&"/Día"=W$9,ROUND(V10/U10,4),"")) -> 69.0064 | Y10: =IF(U10=0,0,IF($F10&"/Día"=W$9,ROUND(Z10/U10,4),"")) -> 12.9387 | Z10: =IF(U10<>"",$P10,"") -> 282219.03 | AA10: =IF($F10&"/Día"=AC$9,SUM($G10:$H10),"") | AB10: =IF(AA10<>"",$O10,"") | AC10: =IF($F10&"/Día"=AC$9,ROUND(AA10/$W$1,1),"") | AD10: =IF(AA10=0,0,IF($F10&"/Día"=AC$9,ROUND(AB10/AA10,4),"")) | AE10: =IF(AA10=0,0,IF($F10&"/Día"=AC$9,ROUND(AF10/AA10,4),"")) | AF10: =IF(AA10<>"",$P10,"")
A11: - | B11: I GAS | C11: Servicios | D11: Mes | E11: F1 | F11: MM BTU | H11: 207427.64 | J11: 2.934 | N11: 1891.7 | O11: =ROUND(G11*I11,2)+ROUND(H11*J11,2)-K11-L11-M11-N11 -> 606701 | P11: =ROUND(18.75%*O11,2) -> 113756.44 | Q11: =ROUND($O11*R11,2) -> 91005.15 | R11: 0.15 | S11: =ROUND($O11*T11,2) -> 22751.29 | T11: 0.0375 | U11: =IF($F11&"/Día"=W$9,SUM($G11:$H11),"") | V11: =IF(U11<>"",$O11,"") | W11: =IF($F11&"/Día"=W$9,ROUND(U11/$W$1,1),"") | X11: =IF(U11=0,0,IF($F11&"/Día"=W$9,ROUND(V11/U11,4),"")) | Y11: =IF(U11=0,0,IF($F11&"/Día"=W$9,ROUND(Z11/U11,4),"")) | Z11: =IF(U11<>"",$P11,"") | AA11: =IF($F11&"/Día"=AC$9,SUM($G11:$H11),"") -> 207427.64 | AB11: =IF(AA11<>"",$O11,"") -> 606701 | AC11: =IF($F11&"/Día"=AC$9,ROUND(AA11/$W$1,1),"") -> 6914.3 | AD11: =IF(AA11=0,0,IF($F11&"/Día"=AC$9,ROUND(AB11/AA11,4),"")) -> 2.9249 | AE11: =IF(AA11=0,0,IF($F11&"/Día"=AC$9,ROUND(AF11/AA11,4),"")) -> 0.5484 | AF11: =IF(AA11<>"",$P11,"") -> 113756.44
A12: - | B12: II | C12: Licencia | D12: Quincena | E12: F2 | F12: Bls | G12: 4240 | H12: 4760 | I12: 65.1052 | J12: 68.4188 | N12: 1744.22 | O12: =ROUND(G12*I12,2)+ROUND(H12*J12,2)-K12-L12-M12-N12 -> 599975.32 | P12: =ROUND(18.75%*O12,2) -> 112495.37 | Q12: =ROUND($O12*R12,2) -> 89996.3 | R12: 0.15 | S12: =ROUND($O12*T12,2) -> 22499.07 | T12: 0.0375 | U12: =IF($F12&"/Día"=W$9,SUM($G12:$H12),"") -> 9000 | V12: =IF(U12<>"",$O12,"") -> 599975.32 | W12: =IF($F12&"/Día"=W$9,ROUND(U12/$W$1,1),"") -> 300 | X12: =IF(U12=0,0,IF($F12&"/Día"=W$9,ROUND(V12/U12,4),"")) -> 66.6639 | Y12: =IF(U12=0,0,IF($F12&"/Día"=W$9,ROUND(Z12/U12,4),"")) -> 12.4995 | Z12: =IF(U12<>"",$P12,"") -> 112495.37 | AA12: =IF($F12&"/Día"=AC$9,SUM($G12:$H12),"") | AB12: =IF(AA12<>"",$O12,"") | AC12: =IF($F12&"/Día"=AC$9,ROUND(AA12/$W$1,1),"") | AD12: =IF(AA12=0,0,IF($F12&"/Día"=AC$9,ROUND(AB12/AA12,4),"")) | AE12: =IF(AA12=0,0,IF($F12&"/Día"=AC$9,ROUND(AF12/AA12,4),"")) | AF12: =IF(AA12<>"",$P12,"")
A13: - | B13: II-GAS | C13: Servicios | D13: Mes | E13: F1 | F13: MM BTU | G13: 38460.027 | H13: 37277.294 | I13: 2.1591 | J13: 2.1609 | N13: 1862.53 | O13: =ROUND(G13*I13,2)+ROUND(H13*J13,2)-K13-L13-M13-N13 -> 161729.01 | P13: =ROUND(18.75%*O13,2) -> 30324.19 | Q13: =ROUND($P13*R13/(R13+T13),2) -> 24259.35 | R13: 0.15 | S13: =P13-Q13 -> 6064.84 | T13: 0.0375 | U13: =IF($F13&"/Día"=W$9,SUM($G13:$H13),"") | V13: =IF(U13<>"",$O13,"") | W13: =IF($F13&"/Día"=W$9,ROUND(U13/$W$1,1),"") | X13: =IF(U13=0,0,IF($F13&"/Día"=W$9,ROUND(V13/U13,4),"")) | Y13: =IF(U13=0,0,IF($F13&"/Día"=W$9,ROUND(Z13/U13,4),"")) | Z13: =IF(U13<>"",$P13,"") | AA13: =IF($F13&"/Día"=AC$9,SUM($G13:$H13),"") -> 75737.321 | AB13: =IF(AA13<>"",$O13,"") -> 161729.01 | AC13: =IF($F13&"/Día"=AC$9,ROUND(AA13/$W$1,1),"") -> 2524.6 | AD13: =IF(AA13=0,0,IF($F13&"/Día"=AC$9,ROUND(AB13/AA13,4),"")) -> 2.1354 | AE13: =IF(AA13=0,0,IF($F13&"/Día"=AC$9,ROUND(AF13/AA13,4),"")) -> 0.4004 | AF13: =IF(AA13<>"",$P13,"") -> 30324.19
A14: - | B14: III | C14: Licencia | D14: Quincena | E14: F2 | F14: Bls | G14: 11055 | H14: 11288 | I14: 66.8811 | J14: 70.8015 | N14: 1242.63 | O14: =ROUND(G14*I14,2)+ROUND(H14*J14,2)-K14-L14-M14-N14 -> 1537335.3 | P14: =ROUND(18.75%*O14,2) -> 288250.36 | Q14: =ROUND($O14*R14,2) -> 230600.29 | R14: 0.15 | S14: =ROUND($O14*T14,2) -> 57650.07 | T14: 0.0375 | U14: =IF($F14&"/Día"=W$9,SUM($G14:$H14),"") -> 22343 | V14: =IF(U14<>"",$O14,"") -> 1537335.3 | W14: =IF($F14&"/Día"=W$9,ROUND(U14/$W$1,1),"") -> 744.8 | X14: =IF(U14=0,0,IF($F14&"/Día"=W$9,ROUND(V14/U14,4),"")) -> 68.8061 | Y14: =IF(U14=0,0,IF($F14&"/Día"=W$9,ROUND(Z14/U14,4),"")) -> 12.9011 | Z14: =IF(U14<>"",$P14,"") -> 288250.36 | AA14: =IF($F14&"/Día"=AC$9,SUM($G14:$H14),"") | AB14: =IF(AA14<>"",$O14,"") | AC14: =IF($F14&"/Día"=AC$9,ROUND(AA14/$W$1,1),"") | AD14: =IF(AA14=0,0,IF($F14&"/Día"=AC$9,ROUND(AB14/AA14,4),"")) | AE14: =IF(AA14=0,0,IF($F14&"/Día"=AC$9,ROUND(AF14/AA14,4),"")) | AF14: =IF(AA14<>"",$P14,"")
A15: - | B15: IV | C15: Licencia | D15: Quincena | E15: F2 | F15: Bls | G15: 30621 | H15: 31021 | I15: 66.8811 | J15: 70.8015 | N15: 3209.33 | O15: =ROUND(G15*I15,2)+ROUND(H15*J15,2)-K15-L15-M15-N15 -> 4241090.2 | P15: =ROUND(18.75%*O15,2) -> 795204.41 | Q15: =ROUND($O15*R15,2) -> 636163.52 | R15: 0.15 | S15: =ROUND($O15*T15,2) -> 159040.88 | T15: 0.0375 | U15: =IF($F15&"/Día"=W$9,SUM($G15:$H15),"") -> 61642 | V15: =IF(U15<>"",$O15,"") -> 4241090.2 | W15: =IF($F15&"/Día"=W$9,ROUND(U15/$W$1,1),"") -> 2054.7 | X15: =IF(U15=0,0,IF($F15&"/Día"=W$9,ROUND(V15/U15,4),"")) -> 68.802 | Y15: =IF(U15=0,0,IF($F15&"/Día"=W$9,ROUND(Z15/U15,4),"")) -> 12.9004 | Z15: =IF(U15<>"",$P15,"") -> 795204.41 | AA15: =IF($F15&"/Día"=AC$9,SUM($G15:$H15),"") | AB15: =IF(AA15<>"",$O15,"") | AC15: =IF($F15&"/Día"=AC$9,ROUND(AA15/$W$1,1),"") | AD15: =IF(AA15=0,0,IF($F15&"/Día"=AC$9,ROUND(AB15/AA15,4),"")) | AE15: =IF(AA15=0,0,IF($F15&"/Día"=AC$9,ROUND(AF15/AA15,4),"")) | AF15: =IF(AA15<>"",$P15,"")
A16: - | B16: V | C16: Servicios | D16: Mes | E16: F1 | F16: Bls | H16: 4328 | J16: 69.0374 | N16: 1470.21 | O16: =ROUND(G16*I16,2)+ROUND(H16*J16,2)-K16-L16-M16-N16 -> 297323.66 | P16: =ROUND(18.75%*O16,2) -> 55748.19 | Q16: =ROUND($O16*R16,2) -> 44598.55 | R16: 0.15 | S16: =ROUND($O16*T16,2) -> 11149.64 | T16: 0.0375 | U16: =IF($F16&"/Día"=W$9,SUM($G16:$H16),"") -> 4328 | V16: =IF(U16<>"",$O16,"") -> 297323.66 | W16: =IF($F16&"/Día"=W$9,ROUND(U16/$W$1,1),"") -> 144.3 | X16: =IF(U16=0,0,IF($F16&"/Día"=W$9,ROUND(V16/U16,4),"")) -> 68.6977 | Y16: =IF(U16=0,0,IF($F16&"/Día"=W$9,ROUND(Z16/U16,4),"")) -> 12.8808 | Z16: =IF(U16<>"",$P16,"") -> 55748.19 | AA16: =IF($F16&"/Día"=AC$9,SUM($G16:$H16),"") | AB16: =IF(AA16<>"",$O16,"") | AC16: =IF($F16&"/Día"=AC$9,ROUND(AA16/$W$1,1),"") | AD16: =IF(AA16=0,0,IF($F16&"/Día"=AC$9,ROUND(AB16/AA16,4),"")) | AE16: =IF(AA16=0,0,IF($F16&"/Día"=AC$9,ROUND(AF16/AA16,4),"")) | AF16: =IF(AA16<>"",$P16,"")
A17: - | B17: VII/VI | C17: Licencia | D17: Quincena | E17: F2 | F17: Bls | G17: 53887 | H17: 57472 | I17: 66.3311 | J17: 70.2515 | N17: 2195.94 | O17: =ROUND(G17*I17,2)+ROUND(H17*J17,2)-K17-L17-M17-N17 -> 7609682.3 | P17: =ROUND(18.75%*O17,2) -> 1426815.4 | Q17: =ROUND($O17*R17,2) -> 1141452.3 | R17: 0.15 | S17: =ROUND($O17*T17,2) -> 285363.08 | T17: 0.0375 | U17: =IF($F17&"/Día"=W$9,SUM($G17:$H17),"") -> 111359 | V17: =IF(U17<>"",$O17,"") -> 7609682.3 | W17: =IF($F17&"/Día"=W$9,ROUND(U17/$W$1,1),"") -> 3712 | X17: =IF(U17=0,0,IF($F17&"/Día"=W$9,ROUND(V17/U17,4),"")) -> 68.3347 | Y17: =IF(U17=0,0,IF($F17&"/Día"=W$9,ROUND(Z17/U17,4),"")) -> 12.8128 | Z17: =IF(U17<>"",$P17,"") -> 1426815.4 | AA17: =IF($F17&"/Día"=AC$9,SUM($G17:$H17),"") | AB17: =IF(AA17<>"",$O17,"") | AC17: =IF($F17&"/Día"=AC$9,ROUND(AA17/$W$1,1),"") | AD17: =IF(AA17=0,0,IF($F17&"/Día"=AC$9,ROUND(AB17/AA17,4),"")) | AE17: =IF(AA17=0,0,IF($F17&"/Día"=AC$9,ROUND(AF17/AA17,4),"")) | AF17: =IF(AA17<>"",$P17,"")
A18: - | B18: VII | C18: Servicios | D18: Mes | E18: F1 | F18: Bls | O18: =ROUND(G18*I18,2)+ROUND(H18*J18,2)-K18-L18-M18-N18 -> 0 | P18: =ROUND(18.75%*O18,2) -> 0 | Q18: =ROUND($O18*R18,2) -> 0 | R18: 0.15 | S18: =ROUND($O18*T18,2) -> 0 | T18: 0.0375 | U18: =IF($F18&"/Día"=W$9,SUM($G18:$H18),"") -> 0 | V18: =IF(U18<>"",$O18,"") -> 0 | W18: =IF($F18&"/Día"=W$9,ROUND(U18/$W$1,1),"") -> 0 | X18: =IF(U18=0,0,IF($F18&"/Día"=W$9,ROUND(V18/U18,4),"")) -> 0 | Y18: =IF(U18=0,0,IF($F18&"/Día"=W$9,ROUND(Z18/U18,4),"")) -> 0 | Z18: =IF(U18<>"",$P18,"") -> 0 | AA18: =IF($F18&"/Día"=AC$9,SUM($G18:$H18),"") | AB18: =IF(AA18<>"",$O18,"") | AC18: =IF($F18&"/Día"=AC$9,ROUND(AA18/$W$1,1),"") | AD18: =IF(AA18=0,0,IF($F18&"/Día"=AC$9,ROUND(AB18/AA18,4),"")) | AE18: =IF(AA18=0,0,IF($F18&"/Día"=AC$9,ROUND(AF18/AA18,4),"")) | AF18: =IF(AA18<>"",$P18,"")
A19: - | B19: VII/VI-GAS | C19: Licencia | D19: Quincena | E19: F2 | F19: MM BTU | G19: 57333.39 | H19: 47484.57 | I19: 0.8 | J19: 0.8 | N19: 2096.88 | O19: =ROUND(G19*I19,2)+ROUND(H19*J19,2)-K19-L19-M19-N19 -> 81757.49 | P19: =ROUND(18.75%*O19,2) -> 15329.53 | Q19: =ROUND($O19*R19,2) -> 12263.62 | R19: 0.15 | S19: =ROUND($O19*T19,2) -> 3065.91 | T19: 0.0375 | U19: =IF($F19&"/Día"=W$9,SUM($G19:$H19),"") | V19: =IF(U19<>"",$O19,"") | W19: =IF($F19&"/Día"=W$9,ROUND(U19/$W$1,1),"") | X19: =IF(U19=0,0,IF($F19&"/Día"=W$9,ROUND(V19/U19,4),"")) | Y19: =IF(U19=0,0,IF($F19&"/Día"=W$9,ROUND(Z19/U19,4),"")) | Z19: =IF(U19<>"",$P19,"") | AA19: =IF($F19&"/Día"=AC$9,SUM($G19:$H19),"") -> 104817.96 | AB19: =IF(AA19<>"",$O19,"") -> 81757.49 | AC19: =IF($F19&"/Día"=AC$9,ROUND(AA19/$W$1,1),"") -> 3493.9 | AD19: =IF(AA19=0,0,IF($F19&"/Día"=AC$9,ROUND(AB19/AA19,4),"")) -> 0.78 | AE19: =IF(AA19=0,0,IF($F19&"/Día"=AC$9,ROUND(AF19/AA19,4),"")) -> 0.1462 | AF19: =IF(AA19<>"",$P19,"") -> 15329.53
A20: - | B20: IX | C20: Licencia | D20: Quincena | E20: F2 | F20: Bls | G20: 2124 | H20: 3038 | I20: 66.8811 | J20: 70.8015 | N20: 729.17 | O20: =ROUND(G20*I20,2)+ROUND(H20*J20,2)-K20-L20-M20-N20 -> 356421.25 | P20: =ROUND(18.75%*O20,2) -> 66828.98 | Q20: =ROUND($O20*R20,2) -> 53463.19 | R20: 0.15 | S20: =ROUND($O20*T20,2) -> 13365.8 | T20: 0.0375 | U20: =IF($F20&"/Día"=W$9,SUM($G20:$H20),"") -> 5162 | V20: =IF(U20<>"",$O20,"") -> 356421.25 | W20: =IF($F20&"/Día"=W$9,ROUND(U20/$W$1,1),"") -> 172.1 | X20: =IF(U20=0,0,IF($F20&"/Día"=W$9,ROUND(V20/U20,4),"")) -> 69.0471 | Y20: =IF(U20=0,0,IF($F20&"/Día"=W$9,ROUND(Z20/U20,4),"")) -> 12.9463 | Z20: =IF(U20<>"",$P20,"") -> 66828.98 | AA20: =IF($F20&"/Día"=AC$9,SUM($G20:$H20),"") | AB20: =IF(AA20<>"",$O20,"") | AC20: =IF($F20&"/Día"=AC$9,ROUND(AA20/$W$1,1),"") | AD20: =IF(AA20=0,0,IF($F20&"/Día"=AC$9,ROUND(AB20/AA20,4),"")) | AE20: =IF(AA20=0,0,IF($F20&"/Día"=AC$9,ROUND(AF20/AA20,4),"")) | AF20: =IF(AA20<>"",$P20,"")
A21: - | B21: X | C21: Licencia | D21: Quincena | E21: F2 | F21: Bls | G21: 192441 | H21: 192657 | I21: 66.8811 | J21: 70.8015 | N21: 4283.58 | O21: =ROUND(G21*I21,2)+ROUND(H21*J21,2)-K21-L21-M21-N21 -> 26506787 | P21: =ROUND(18.75%*O21,2) -> 4970022.5 | Q21: =ROUND($O21*R21,2) -> 3976018 | R21: 0.15 | S21: =ROUND($O21*T21,2) -> 994004.5 | T21: 0.0375 | U21: =IF($F21&"/Día"=W$9,SUM($G21:$H21),"") -> 385098 | V21: =IF(U21<>"",$O21,"") -> 26506787 | W21: =IF($F21&"/Día"=W$9,ROUND(U21/$W$1,1),"") -> 12836.6 | X21: =IF(U21=0,0,IF($F21&"/Día"=W$9,ROUND(V21/U21,4),"")) -> 68.8313 | Y21: =IF(U21=0,0,IF($F21&"/Día"=W$9,ROUND(Z21/U21,4),"")) -> 12.9059 | Z21: =IF(U21<>"",$P21,"") -> 4970022.5 | AA21: =IF($F21&"/Día"=AC$9,SUM($G21:$H21),"") | AB21: =IF(AA21<>"",$O21,"") | AC21: =IF($F21&"/Día"=AC$9,ROUND(AA21/$W$1,1),"") | AD21: =IF(AA21=0,0,IF($F21&"/Día"=AC$9,ROUND(AB21/AA21,4),"")) | AE21: =IF(AA21=0,0,IF($F21&"/Día"=AC$9,ROUND(AF21/AA21,4),"")) | AF21: =IF(AA21<>"",$P21,"")
A22: - | B22: X-GAS | C22: Licencia | D22: Mes | E22: F2 | F22: MM BTU | G22: 245652.84 | H22: 253188.98 | I22: 1.7112 | J22: 1.7112 | N22: 2209.07 | O22: =ROUND(G22*I22,2)+ROUND(H22*J22,2)-K22-L22-M22-N22 -> 851409.05 | P22: =ROUND(18.75%*O22,2) -> 159639.2 | Q22: =ROUND($O22*R22,2) -> 127711.36 | R22: 0.15 | S22: =ROUND($O22*T22,2) -> 31927.84 | T22: 0.0375 | U22: =IF($F22&"/Día"=W$9,SUM($G22:$H22),"") | V22: =IF(U22<>"",$O22,"") | W22: =IF($F22&"/Día"=W$9,ROUND(U22/$W$1,1),"") | X22: =IF(U22=0,0,IF($F22&"/Día"=W$9,ROUND(V22/U22,4),"")) | Y22: =IF(U22=0,0,IF($F22&"/Día"=W$9,ROUND(Z22/U22,4),"")) | Z22: =IF(U22<>"",$P22,"") | AA22: =IF($F22&"/Día"=AC$9,SUM($G22:$H22),"") -> 498841.82 | AB22: =IF(AA22<>"",$O22,"") -> 851409.05 | AC22: =IF($F22&"/Día"=AC$9,ROUND(AA22/$W$1,1),"") -> 16628.1 | AD22: =IF(AA22=0,0,IF($F22&"/Día"=AC$9,ROUND(AB22/AA22,4),"")) -> 1.7068 | AE22: =IF(AA22=0,0,IF($F22&"/Día"=AC$9,ROUND(AF22/AA22,4),"")) -> 0.32 | AF22: =IF(AA22<>"",$P22,"") -> 159639.2
A23: - | B23: XIV | C23: Licencia | D23: Mes | E23: F2 | F23: Bls | O23: =ROUND(G23*I23,2)+ROUND(H23*J23,2)-K23-L23-M23-N23 -> 0 | P23: =ROUND(18.75%*O23,2) -> 0 | Q23: =ROUND($O23*R23,2) -> 0 | R23: 0.15 | S23: =ROUND($O23*T23,2) -> 0 | T23: 0.0375 | U23: =IF($F23&"/Día"=W$9,SUM($G23:$H23),"") -> 0 | V23: =IF(U23<>"",$O23,"") -> 0 | W23: =IF($F23&"/Día"=W$9,ROUND(U23/$W$1,1),"") -> 0 | X23: =IF(U23=0,0,IF($F23&"/Día"=W$9,ROUND(V23/U23,4),"")) -> 0 | Y23: =IF(U23=0,0,IF($F23&"/Día"=W$9,ROUND(Z23/U23,4),"")) -> 0 | Z23: =IF(U23<>"",$P23,"") -> 0 | AA23: =IF($F23&"/Día"=AC$9,SUM($G23:$H23),"") | AB23: =IF(AA23<>"",$O23,"") | AC23: =IF($F23&"/Día"=AC$9,ROUND(AA23/$W$1,1),"") | AD23: =IF(AA23=0,0,IF($F23&"/Día"=AC$9,ROUND(AB23/AA23,4),"")) | AE23: =IF(AA23=0,0,IF($F23&"/Día"=AC$9,ROUND(AF23/AA23,4),"")) | AF23: =IF(AA23<>"",$P23,"")
A24: - | B24: XV | C24: Licencia | D24: Quincena | E24: F2 | F24: Bls | G24: 557 | H24: 544 | I24: 67.6937 | J24: 70.8609 | N24: 792.9 | O24: =ROUND(G24*I24,2)+ROUND(H24*J24,2)-K24-L24-M24-N24 -> 75460.82 | P24: =ROUND(18.75%*O24,2) -> 14148.9 | Q24: =ROUND($O24*R24,2) -> 11319.12 | R24: 0.15 | S24: =ROUND($O24*T24,2) -> 2829.78 | T24: 0.0375 | U24: =IF($F24&"/Día"=W$9,SUM($G24:$H24),"") -> 1101 | V24: =IF(U24<>"",$O24,"") -> 75460.82 | W24: =IF($F24&"/Día"=W$9,ROUND(U24/$W$1,1),"") -> 36.7 | X24: =IF(U24=0,0,IF($F24&"/Día"=W$9,ROUND(V24/U24,4),"")) -> 68.5384 | Y24: =IF(U24=0,0,IF($F24&"/Día"=W$9,ROUND(Z24/U24,4),"")) -> 12.851 | Z24: =IF(U24<>"",$P24,"") -> 14148.9 | AA24: =IF($F24&"/Día"=AC$9,SUM($G24:$H24),"") | AB24: =IF(AA24<>"",$O24,"") | AC24: =IF($F24&"/Día"=AC$9,ROUND(AA24/$W$1,1),"") | AD24: =IF(AA24=0,0,IF($F24&"/Día"=AC$9,ROUND(AB24/AA24,4),"")) | AE24: =IF(AA24=0,0,IF($F24&"/Día"=AC$9,ROUND(AF24/AA24,4),"")) | AF24: =IF(AA24<>"",$P24,"")
A25: - | B25: XIII Crudo | C25: Licencia | D25: Quincena | E25: F2 | F25: Bls | G25: 25730 | H25: 31508 | I25: 66.8811 | J25: 70.8015 | N25: 1512.61 | O25: =ROUND(G25*I25,2)+ROUND(H25*J25,2)-K25-L25-M25-N25 -> 3950151.8 | P25: =ROUND(18.75%*O25,2) -> 740653.45 | Q25: =ROUND($O25*R25,2) -> 592522.76 | R25: 0.15 | S25: =ROUND($O25*T25,2) -> 148130.69 | T25: 0.0375 | U25: =IF($F25&"/Día"=W$9,SUM($G25:$H25),"") -> 57238 | V25: =IF(U25<>"",$O25,"") -> 3950151.8 | W25: =IF($F25&"/Día"=W$9,ROUND(U25/$W$1,1),"") -> 1907.9 | X25: =IF(U25=0,0,IF($F25&"/Día"=W$9,ROUND(V25/U25,4),"")) -> 69.0127 | Y25: =IF(U25=0,0,IF($F25&"/Día"=W$9,ROUND(Z25/U25,4),"")) -> 12.9399 | Z25: =IF(U25<>"",$P25,"") -> 740653.45 | AA25: =IF($F25&"/Día"=AC$9,SUM($G25:$H25),"") | AB25: =IF(AA25<>"",$O25,"") | AC25: =IF($F25&"/Día"=AC$9,ROUND(AA25/$W$1,1),"") | AD25: =IF(AA25=0,0,IF($F25&"/Día"=AC$9,ROUND(AB25/AA25,4),"")) | AE25: =IF(AA25=0,0,IF($F25&"/Día"=AC$9,ROUND(AF25/AA25,4),"")) | AF25: =IF(AA25<>"",$P25,"")
A26: - | B26: XIII COND | C26: Licencia | D26: Quincena | E26: F2 | F26: Bls | O26: =ROUND(G26*I26,2)+ROUND(H26*J26,2)-K26-L26-M26-N26 -> 0 | P26: =ROUND(18.75%*O26,2) -> 0 | Q26: =ROUND($O26*R26,2) -> 0 | R26: 0.15 | S26: =ROUND($O26*T26,2) -> 0 | T26: 0.0375 | U26: =IF($F26&"/Día"=W$9,SUM($G26:$H26),"") -> 0 | V26: =IF(U26<>"",$O26,"") -> 0 | W26: =IF($F26&"/Día"=W$9,ROUND(U26/$W$1,1),"") -> 0 | X26: =IF(U26=0,0,IF($F26&"/Día"=W$9,ROUND(V26/U26,4),"")) -> 0 | Y26: =IF(U26=0,0,IF($F26&"/Día"=W$9,ROUND(Z26/U26,4),"")) -> 0 | Z26: =IF(U26<>"",$P26,"") -> 0 | AA26: =IF($F26&"/Día"=AC$9,SUM($G26:$H26),"") | AB26: =IF(AA26<>"",$O26,"") | AC26: =IF($F26&"/Día"=AC$9,ROUND(AA26/$W$1,1),"") | AD26: =IF(AA26=0,0,IF($F26&"/Día"=AC$9,ROUND(AB26/AA26,4),"")) | AE26: =IF(AA26=0,0,IF($F26&"/Día"=AC$9,ROUND(AF26/AA26,4),"")) | AF26: =IF(AA26<>"",$P26,"")
A27: - | B27: XIII Gas | C27: Licencia | D27: Quincena | E27: F2 | F27: MM BTU | G27: =104778.0799+72373.8704 -> 177151.95 | H27: =107745.4041+80578.4653 -> 188323.87 | I27: 2.5397374 | J27: 2.5926134 | N27: 3126.36 | O27: =ROUND(G27*I27,2)+ROUND(H27*J27,2)-K27-L27-M27-N27 -> 935044.05 | P27: =ROUND(18.75%*O27,2) -> 175320.76 | Q27: =ROUND($O27*R27,2) -> 140256.61 | R27: 0.15 | S27: =ROUND($O27*T27,2) -> 35064.15 | T27: 0.0375 | U27: =IF($F27&"/Día"=W$9,SUM($G27:$H27),"") | V27: =IF(U27<>"",$O27,"") | W27: =IF($F27&"/Día"=W$9,ROUND(U27/$W$1,1),"") | X27: =IF(U27=0,0,IF($F27&"/Día"=W$9,ROUND(V27/U27,4),"")) | Y27: =IF(U27=0,0,IF($F27&"/Día"=W$9,ROUND(Z27/U27,4),"")) | Z27: =IF(U27<>"",$P27,"") | AA27: =IF($F27&"/Día"=AC$9,SUM($G27:$H27),"") -> 365475.82 | AB27: =IF(AA27<>"",$O27,"") -> 935044.05 | AC27: =IF($F27&"/Día"=AC$9,ROUND(AA27/$W$1,1),"") -> 12182.5 | AD27: =IF(AA27=0,0,IF($F27&"/Día"=AC$9,ROUND(AB27/AA27,4),"")) -> 2.5584 | AE27: =IF(AA27=0,0,IF($F27&"/Día"=AC$9,ROUND(AF27/AA27,4),"")) -> 0.4797 | AF27: =IF(AA27<>"",$P27,"") -> 175320.76
A28: - | B28: Z-2B | C28: Servicios | D28: Mes | E28: F1 | F28: Bls | G28: =41580+38551+37557+37373+40740+39453+34290 -> 269544 | H28: =38140+200235 -> 238375 | I28: 3.0405943 | J28: 66.808616 | N28: 2417.19 | O28: =ROUND(G28*I28,2)+ROUND(H28*J28,2)-K28-L28-M28-N28 -> 16742661 | P28: =ROUND(18.75%*O28,2) -> 3139248.9 | Q28: =ROUND($O28*R28,2) -> 2511399.1 | R28: 0.15 | S28: =ROUND($O28*T28,2) -> 627849.77 | T28: 0.0375 | U28: =IF($F28&"/Día"=W$9,SUM($G28:$H28),"") -> 507919 | V28: =IF(U28<>"",$O28,"") -> 16742661 | W28: =IF($F28&"/Día"=W$9,ROUND(U28/$W$1,1),"") -> 16930.6 | X28: =IF(U28=0,0,IF($F28&"/Día"=W$9,ROUND(V28/U28,4),"")) -> 32.9632 | Y28: =IF(U28=0,0,IF($F28&"/Día"=W$9,ROUND(Z28/U28,4),"")) -> 6.1806 | Z28: =IF(U28<>"",$P28,"") -> 3139248.9 | AA28: =IF($F28&"/Día"=AC$9,SUM($G28:$H28),"") | AB28: =IF(AA28<>"",$O28,"") | AC28: =IF($F28&"/Día"=AC$9,ROUND(AA28/$W$1,1),"") | AD28: =IF(AA28=0,0,IF($F28&"/Día"=AC$9,ROUND(AB28/AA28,4),"")) | AE28: =IF(AA28=0,0,IF($F28&"/Día"=AC$9,ROUND(AF28/AA28,4),"")) | AF28: =IF(AA28<>"",$P28,"")
A29: - | B29: Z-2B GAS | C29: Servicios | D29: Mes | E29: F1 | F29: MM BTU | H29: =1153.36+20956.56+116077.1 -> 138187.02 | J29: 5.5796026 | N29: 2131.57 | O29: =ROUND(G29*I29,2)+ROUND(H29*J29,2)-K29-L29-M29-N29 -> 768897.09 | P29: =ROUND(18.75%*O29,2) -> 144168.2 | Q29: =ROUND($O29*R29,2) -> 115334.56 | R29: 0.15 | S29: =ROUND($O29*T29,2) -> 28833.64 | T29: 0.0375 | U29: =IF($F29&"/Día"=W$9,SUM($G29:$H29),"") | V29: =IF(U29<>"",$O29,"") | W29: =IF($F29&"/Día"=W$9,ROUND(U29/$W$1,1),"") | X29: =IF(U29=0,0,IF($F29&"/Día"=W$9,ROUND(V29/U29,4),"")) | Y29: =IF(U29=0,0,IF($F29&"/Día"=W$9,ROUND(Z29/U29,4),"")) | Z29: =IF(U29<>"",$P29,"") | AA29: =IF($F29&"/Día"=AC$9,SUM($G29:$H29),"") -> 138187.02 | AB29: =IF(AA29<>"",$O29,"") -> 768897.09 | AC29: =IF($F29&"/Día"=AC$9,ROUND(AA29/$W$1,1),"") -> 4606.2 | AD29: =IF(AA29=0,0,IF($F29&"/Día"=AC$9,ROUND(AB29/AA29,4),"")) -> 5.5642 | AE29: =IF(AA29=0,0,IF($F29&"/Día"=AC$9,ROUND(AF29/AA29,4),"")) -> 1.0433 | AF29: =IF(AA29<>"",$P29,"") -> 144168.2
A30: - | B30: XX | C30: Licencia | D30: Quincena | E30: F2 | F30: Bls | G30: 329 | H30: 329 | I30: 66.8811 | J30: 70.8015 | N30: 465.7 | O30: =ROUND(G30*I30,2)+ROUND(H30*J30,2)-K30-L30-M30-N30 -> 44831.87 | P30: =ROUND(18.75%*O30,2) -> 8405.98 | Q30: =ROUND($O30*R30,2) -> 1681.2 | R30: 0.0375 | S30: =ROUND($O30*T30,2) -> 6724.78 | T30: 0.15 | U30: =IF($F30&"/Día"=W$9,SUM($G30:$H30),"") -> 658 | V30: =IF(U30<>"",$O30,"") -> 44831.87 | W30: =IF($F30&"/Día"=W$9,ROUND(U30/$W$1,1),"") -> 21.9 | X30: =IF(U30=0,0,IF($F30&"/Día"=W$9,ROUND(V30/U30,4),"")) -> 68.1335 | Y30: =IF(U30=0,0,IF($F30&"/Día"=W$9,ROUND(Z30/U30,4),"")) -> 12.775 | Z30: =IF(U30<>"",$P30,"") -> 8405.98 | AA30: =IF($F30&"/Día"=AC$9,SUM($G30:$H30),"") | AB30: =IF(AA30<>"",$O30,"") | AC30: =IF($F30&"/Día"=AC$9,ROUND(AA30/$W$1,1),"") | AD30: =IF(AA30=0,0,IF($F30&"/Día"=AC$9,ROUND(AB30/AA30,4),"")) | AE30: =IF(AA30=0,0,IF($F30&"/Día"=AC$9,ROUND(AF30/AA30,4),"")) | AF30: =IF(AA30<>"",$P30,"")
A31: - | B31: Z1 Crudo | C31: Licencia | D31: Quincena | E31: F2 | F31: Bls | N31: 1434.04 | O31: =ROUND(G31*I31,2)+ROUND(H31*J31,2)-K31-L31-M31-N31 -> -1434.04 | P31: =ROUND(18.75%*O31,2) -> -268.88 | Q31: =ROUND($O31*R31,2) -> -53.78 | R31: 0.0375 | S31: =ROUND($O31*T31,2) -> -215.11 | T31: 0.15 | U31: =IF($F31&"/Día"=W$9,SUM($G31:$H31),"") -> 0 | V31: =IF(U31<>"",$O31,"") -> -1434.04 | W31: =IF($F31&"/Día"=W$9,ROUND(U31/$W$1,1),"") -> 0 | X31: =IF(U31=0,0,IF($F31&"/Día"=W$9,ROUND(V31/U31,4),"")) -> 0 | Y31: =IF(U31=0,0,IF($F31&"/Día"=W$9,ROUND(Z31/U31,4),"")) -> 0 | Z31: =IF(U31<>"",$P31,"") -> -268.88 | AA31: =IF($F31&"/Día"=AC$9,SUM($G31:$H31),"") | AB31: =IF(AA31<>"",$O31,"") | AC31: =IF($F31&"/Día"=AC$9,ROUND(AA31/$W$1,1),"") | AD31: =IF(AA31=0,0,IF($F31&"/Día"=AC$9,ROUND(AB31/AA31,4),"")) | AE31: =IF(AA31=0,0,IF($F31&"/Día"=AC$9,ROUND(AF31/AA31,4),"")) | AF31: =IF(AA31<>"",$P31,"")
A32: - | B32: Z1 Gas | C32: Licencia | D32: Quincena | E32: F2 | F32: MM BTU | O32: =ROUND(G32*I32,2)+ROUND(H32*J32,2)-K32-L32-M32-N32 -> 0 | P32: =ROUND(18.75%*O32,2) -> 0 | Q32: =ROUND($O32*R32,2) -> 0 | R32: 0.0375 | S32: =ROUND($O32*T32,2) -> 0 | T32: 0.15 | U32: =IF($F32&"/Día"=W$9,SUM($G32:$H32),"") | V32: =IF(U32<>"",$O32,"") | W32: =IF($F32&"/Día"=W$9,ROUND(U32/$W$1,1),"") | X32: =IF(U32=0,0,IF($F32&"/Día"=W$9,ROUND(V32/U32,4),"")) | Y32: =IF(U32=0,0,IF($F32&"/Día"=W$9,ROUND(Z32/U32,4),"")) | Z32: =IF(U32<>"",$P32,"") | AA32: =IF($F32&"/Día"=AC$9,SUM($G32:$H32),"") -> 0 | AB32: =IF(AA32<>"",$O32,"") -> 0 | AC32: =IF($F32&"/Día"=AC$9,ROUND(AA32/$W$1,1),"") -> 0 | AD32: =IF(AA32=0,0,IF($F32&"/Día"=AC$9,ROUND(AB32/AA32,4),"")) -> 0 | AE32: =IF(AA32=0,0,IF($F32&"/Día"=AC$9,ROUND(AF32/AA32,4),"")) -> 0 | AF32: =IF(AA32<>"",$P32,"") -> 0
A33: - | B33: Z-2B - LGN | C33: Servicios | D33: Mes | E33: F1 | F33: Bls | H33: =27634+5264 -> 32898 | J33: 54.9433 | N33: 2321.9 | O33: =ROUND(G33*I33,2)+ROUND(H33*J33,2)-K33-L33-M33-N33 -> 1805202.8 | P33: =ROUND(18.75%*O33,2) -> 338475.52 | Q33: =ROUND($O33*R33,2) -> 270780.42 | R33: 0.15 | S33: =ROUND($O33*T33,2) -> 67695.1 | T33: 0.0375 | U33: =IF($F33&"/Día"=W$9,SUM($G33:$H33),"") -> 32898 | V33: =IF(U33<>"",$O33,"") -> 1805202.8 | W33: =IF($F33&"/Día"=W$9,ROUND(U33/$W$1,1),"") -> 1096.6 | X33: =IF(U33=0,0,IF($F33&"/Día"=W$9,ROUND(V33/U33,4),"")) -> 54.8727 | Y33: =IF(U33=0,0,IF($F33&"/Día"=W$9,ROUND(Z33/U33,4),"")) -> 10.2886 | Z33: =IF(U33<>"",$P33,"") -> 338475.52 | AA33: =IF($F33&"/Día"=AC$9,SUM($G33:$H33),"") | AB33: =IF(AA33<>"",$O33,"") | AC33: =IF($F33&"/Día"=AC$9,ROUND(AA33/$W$1,1),"") | AD33: =IF(AA33=0,0,IF($F33&"/Día"=AC$9,ROUND(AB33/AA33,4),"")) | AE33: =IF(AA33=0,0,IF($F33&"/Día"=AC$9,ROUND(AF33/AA33,4),"")) | AF33: =IF(AA33<>"",$P33,"")
A34: - | B34: Z-6 | C34: Licencia | D34: Quincena | E34: F2 | F34: MM BTU | O34: =ROUND(G34*I34,2)+ROUND(H34*J34,2)-K34-L34-M34-N34 -> 0 | P34: =ROUND(18.75%*O34,2) -> 0 | Q34: =ROUND($O34*R34,2) -> 0 | R34: 0.15 | S34: =ROUND($O34*T34,2) -> 0 | T34: 0.0375
A35: - | B35: Ajustes meses anteriores (1) | O35: =O440 -> -23593.12 | P35: =P440 -> -4423.71 | Q35: =Q440 -> -3538.97 | S35: =S440 -> -884.74 | U35: =IF($F35&"/Día"=W$9,SUM($G35:$H35),"") | V35: =IF(U35<>"",$O35,"") | W35: =IF($F35&"/Día"=W$9,ROUND(U35/$W$1,1),"") | X35: =IF(U35=0,0,IF($F35&"/Día"=W$9,ROUND(V35/U35,4),"")) | Y35: =IF(U35=0,0,IF($F35&"/Día"=W$9,ROUND(Z35/U35,4),"")) | Z35: =IF(U35<>"",$P35,"") | AA35: =IF($F35&"/Día"=AC$9,SUM($G35:$H35),"") | AB35: =IF(AA35<>"",$O35,"") | AC35: =IF($F35&"/Día"=AC$9,ROUND(AA35/$W$1,1),"") | AD35: =IF(AA35=0,0,IF($F35&"/Día"=AC$9,ROUND(AB35/AA35,4),"")) | AE35: =IF(AA35=0,0,IF($F35&"/Día"=AC$9,ROUND(AF35/AA35,4),"")) | AF35: =IF(AA35<>"",$P35,"")
B36: Subtotal | C36: =TEXT(A$9,)&" US$" -> Piura / Tumbes US$ | O36: =SUM(O10:O35) -> 68652601 | P36: =SUM(P10:P35) -> 12872363 | Q36: =SUM(Q10:Q35) -> 10293008 | S36: =SUM(S10:S35) -> 2579354.8 | U36: =SUM(U10:U35) -> 1220558 | V36: =SUM(V10:V35) -> 65270657 | W36: =SUM(W10:W35) -> 40685.3 | X36: =ROUND(V36/U36,4) -> 53.4761 | Y36: =ROUND(Z36/U36,4) -> 10.0268 | Z36: =SUM(Z10:Z35) -> 12238248 | AA36: =SUM(AA10:AA35) -> 1390487.6 | AB36: =SUM(AB10:AB35) -> 3405537.7 | AC36: =SUM(AC10:AC35) -> 46349.6 | AD36: =ROUND(AB36/AA36,4) -> 2.4492 | AE36: =ROUND(AF36/AA36,4) -> 0.4592 | AF36: =SUM(AF10:AF35) -> 638538.32 | AG36: =P36-Z36-AF36 -> -4423.71
C37: =TEXT(A$9,)&" S/." -> Piura / Tumbes S/. | P37: =ROUND($F$1*P36,2) -> 0 | Q37: =ROUND($F$1*Q36,2) -> 0 | S37: =ROUND($F$1*S36,2) -> 0
A38: Provincia Puerto Inca Huanuco | Q38: Puerto Inca
A39: - | B39: 31-D | C39: Licencia | D39: Quincena | E39: F2 | F39: Bls | N39: 1099.45 | O39: =ROUND(G39*I39,2)+ROUND(H39*J39,2)-K39-L39-M39-N39 -> -1099.45 | P39: =ROUND(15%*O39,2) -> -164.92 | Q39: =ROUND($O39*R39,2) -> -164.92 | R39: 0.15 | U39: =IF($F39&"/Día"=W$9,SUM($G39:$H39),"") -> 0 | V39: =IF(U39<>"",$O39,"") -> -1099.45 | W39: =IF($F39&"/Día"=W$9,ROUND(U39/$W$1,1),"") -> 0 | X39: =IF(U39=0,0,IF($F39&"/Día"=W$9,ROUND(V39/U39,4),"")) -> 0 | Y39: =IF(U39=0,0,IF($F39&"/Día"=W$9,ROUND(Z39/U39,4),"")) -> 0 | Z39: =IF(U39<>"",$P39,"") -> -164.92 | AA39: =IF($F39&"/Día"=AC$9,SUM($G39:$H39),"") | AB39: =IF(AA39<>"",$O39,"") | AC39: =IF($F39&"/Día"=AC$9,ROUND(AA39/$W$1,1),"") | AD39: =IF(AA39=0,0,IF($F39&"/Día"=AC$9,ROUND(AB39/AA39,4),"")) | AE39: =IF(AA39=0,0,IF($F39&"/Día"=AC$9,ROUND(AF39/AA39,4),"")) | AF39: =IF(AA39<>"",$P39,"")
A40: - | B40: 131 | C40: Licencia | D40: Quincena | E40: F2 | F40: Bls | G40: 44053 | H40: 44299 | I40: 65.1058 | J40: 68.7299 | N40: 9334.62 | O40: =ROUND(G40*I40,2)+ROUND(H40*J40,2)-K40-L40-M40-N40 -> 5903437 | P40: =ROUND(15%*O40,2) -> 885515.55 | Q40: =ROUND($O40*R40,2) -> 885515.55 | R40: 0.15 | U40: =IF($F40&"/Día"=W$9,SUM($G40:$H40),"") -> 88352 | V40: =IF(U40<>"",$O40,"") -> 5903437 | W40: =IF($F40&"/Día"=W$9,ROUND(U40/$W$1,1),"") -> 2945.1 | X40: =IF(U40=0,0,IF($F40&"/Día"=W$9,ROUND(V40/U40,4),"")) -> 66.8172 | Y40: =IF(U40=0,0,IF($F40&"/Día"=W$9,ROUND(Z40/U40,4),"")) -> 10.0226 | Z40: =IF(U40<>"",$P40,"") -> 885515.55 | AA40: =IF($F40&"/Día"=AC$9,SUM($G40:$H40),"") | AB40: =IF(AA40<>"",$O40,"") | AC40: =IF($F40&"/Día"=AC$9,ROUND(AA40/$W$1,1),"") | AD40: =IF(AA40=0,0,IF($F40&"/Día"=AC$9,ROUND(AB40/AA40,4),"")) | AE40: =IF(AA40=0,0,IF($F40&"/Día"=AC$9,ROUND(AF40/AA40,4),"")) | AF40: =IF(AA40<>"",$P40,"")
A41: - | B41: Ajustes meses anteriores (2) | O41: =O442 -> 147042.22 | P41: =P442 -> 22056.33 | Q41: =Q442 -> 22056.33 | U41: =IF($F41&"/Día"=W$9,SUM($G41:$H41),"") | V41: =IF(U41<>"",$O41,"") | W41: =IF($F41&"/Día"=W$9,ROUND(U41/$W$1,1),"") | X41: =IF(U41=0,0,IF($F41&"/Día"=W$9,ROUND(V41/U41,4),"")) | Y41: =IF(U41=0,0,IF($F41&"/Día"=W$9,ROUND(Z41/U41,4),"")) | Z41: =IF(U41<>"",$P41,"") | AA41: =IF($F41&"/Día"=AC$9,SUM($G41:$H41),"") | AB41: =IF(AA41<>"",$O41,"") | AC41: =IF($F41&"/Día"=AC$9,ROUND(AA41/$W$1,1),"") | AD41: =IF(AA41=0,0,IF($F41&"/Día"=AC$9,ROUND(AB41/AA41,4),"")) | AE41: =IF(AA41=0,0,IF($F41&"/Día"=AC$9,ROUND(AF41/AA41,4),"")) | AF41: =IF(AA41<>"",$P41,"")
...

Sheet Ene
A1: Período de Cálculo: | E1: 45688 | F1: 3.69
A2: PERUPETRO S.A.
A3: DETERMINACION DEL CANON, SOBRECANON y PARTICIPACION (US$)
A4: Correspondiente a Enero 2025
A5: Tipo de Cambio= 3.690
A7: Localidad | C7: Modalidad de Contrato | D7: Calculo del Canon | F7: Volumen Producción / Venta | I7: Canasta o Valor Venta (US$/Unidad) | K7: Deducción de Gastos para determinación de valor de producción en Punto de Fiscalización (US$) | O7: Valor de la Producción (US$) | P7: Canon y Sobrecanon / Participación (US$)
A8: - Lote | D8: Período | E8: Fórmula | F8: Unidades | G8: 1ra. Q | H8: 2da. Q / Mes | I8: 1ra. Q | J8: 2da. Q / Mes | K8: Flete Marítimo | L8: Comercialización | M8: Oleoducto | N8: Fiscalización | P8: Total | Q8: Localidad 1 | S8: Localidad 2
A9: Piura / Tumbes | Q9: Piura | S9: Tumbes
A10: - | B10: I | C10: Licencia | D10: Quincena | E10: F2 | F10: Bls | G10: 4669 | H10: 12235 | I10: 78.909 | J10: 80.6475 | N10: 79.05 | O10: 1355069.2 | P10: 254075.48 | Q10: 203260.38 | R10: 0.15 | S10: 50815.1 | T10: 0.0375
A11: - | B11: I GAS | C11: Licencia | D11: Quincena | E11: F2 | F11: MM BTU | G11: 46200.457 | H11: 52886.764 | I11: 3.8633 | J11: 3.8633 | N11: 221.34 | O11: 382582.32 | P11: 71734.19 | Q11: 57387.35 | R11: 0.15 | S11: 14346.84 | T11: 0.0375
A12: - | B12: II | C12: Licencia | D12: Quincena | E12: F2 | F12: Bls | G12: 4868 | H12: 5386 | I12: 78.4058 | J12: 78.2365 | N12: 635.56 | O12: 802425.66 | P12: 150454.81 | Q12: 120363.85 | R12: 0.15 | S12: 30090.96 | T12: 0.0375
A13: - | B13: II-GAS | C13: Licencia | D13: Quincena | E13: F2 | F13: MM BTU | G13: 11396.981 | H13: 16566.773 | I13: 2.8114 | J13: 2.8114 | N13: 679.83 | O13: 77937.46 | P13: 14613.27 | Q13: 11690.62 | R13: 0.15 | S13: 2922.65 | T13: 0.0375
A14: - | B14: III | C14: Licencia | D14: Quincena | E14: F2 | F14: Bls | G14: 29174 | H14: 31872 | I14: 78.909 | J14: 80.6475 | N14: 1053.85 | O14: 4871434.4 | P14: 913393.96 | Q14: 730715.17 | R14: 0.15 | S14: 182678.79 | T14: 0.0375
A15: - | B15: III-GAS | C15: Licencia | D15: Quincena | E15: F2 | F15: MM BTU | G15: 8444.6128 | H15: 13057.577 | I15: 3.2 | J15: 3.2 | O15: 68807.01 | P15: 12901.31 | Q15: 10321.05 | R15: 0.15 | S15: 2580.26 | T15: 0.0375
A16: - | B16: IV | C16: Licencia | D16: Quincena | E16: F2 | F16: Bls | G16: 40970 | H16: 44264 | I16: 78.909 | J16: 80.6475 | N16: 1771.63 | O16: 6800911 | P16: 1275170.8 | Q16: 1020136.7 | R16: 0.15 | S16: 255034.16 | T16: 0.0375
A17: - | B17: IV-GAS | C17: Licencia | D17: Quincena | E17: F2 | F17: Bls | G17: 55338.229 | H17: 40417.509 | I17: 3.6086 | J17: 3.6086 | N17: 601.69 | O17: 344942.46 | P17: 64676.71 | Q17: 51741.37 | R17: 0.15 | S17: 12935.34 | T17: 0.0375
A18: - | B18: V | C18: Licencia | D18: Quincena | E18: F2 | F18: Bls | G18: 3925 | H18: 3200 | I18: 78.4158 | J18: 78.2507 | N18: 414.22 | O18: 557770.04 | P18: 104581.88 | Q18: 83665.51 | R18: 0.15 | S18: 20916.38 | T18: 0.0375
A19: - | B19: VI (T) | C19: Licencia | D19: Quincena | E19: F2 | F19: Bls | G19: 20783 | H19: 27532 | I19: 78.909 | J19: 80.6475 | N19: 499.59 | O19: 3859853.1 | P19: 723722.46 | Q19: 578977.97 | R19: 0.15 | S19: 144744.49 | T19: 0.0375
A20: - | B20: VI - GAS | C20: Licencia | D20: Quincena | E20: F2 | F20: MM BTU | G20: 58375.693 | H20: 57555.927 | I20: 3.8449 | J20: 3.8449 | N20: 215.02 | O20: 445530.46 | P20: 83536.96 | Q20: 66829.57 | R20: 0.15 | S20: 16707.39 | T20: 0.0375
A21: - | B21: VII (T) | C21: Licencia | D21: Quincena | E21: F2 | F21: Bls | G21: 14360 | H21: 17820 | I21: 78.4158 | J21: 78.2507 | N21: 246.63 | O21: 2520231.7 | P21: 472543.45 | Q21: 378034.76 | R21: 0.15 | S21: 94508.69 | T21: 0.0375
A22: - | B22: IX | C22: Licencia | D22: Quincena | E22: F2 | F22: Bls | G22: 1515 | H22: 3095 | I22: 78.909 | J22: 80.6475 | N22: 265.61 | O22: 368885.54 | P22: 69166.04 | Q22: 55332.83 | R22: 0.15 | S22: 13833.21 | T22: 0.0375
A23: - | B23: X | C23: Licencia | D23: Quincena | E23: F2 | F23: Bls | G23: 116840 | H23: 127940 | I23: 79.663 | J23: 79.6289 | N23: 1207.9 | O23: 19494338 | P23: 3655188.5 | Q23: 2924150.8 | R23: 0.15 | S23: 731037.69 | T23: 0.0375
A24: - | B24: X-GAS | C24: Licencia | D24: Quincena | E24: F2 | F24: MM BTU | G24: 204250.66 | H24: 226421.16 | I24: 2.9 | J24: 2.9 | N24: 916.99 | O24: 1248031.3 | P24: 234005.87 | Q24: 187204.69 | R24: 0.15 | S24: 46801.17 | T24: 0.0375
A25: - | B25: XV | C25: Licencia | D25: Quincena | E25: F2 | F25: Bls | G25: 286 | H25: 273 | I25: 78.4158 | J25: 78.2507 | N25: 287.74 | O25: 43501.62 | P25: 8156.55 | Q25: 6525.24 | R25: 0.15 | S25: 1631.31 | T25: 0.0375
A26: - | B26: XIII Crudo | C26: Licencia | D26: Quincena | E26: F2 | F26: Bls | G26: 14571 | H26: 15247 | I26: 76.269 | J26: 80.5775 | N26: 2741.44 | O26: 2337139.3 | P26: 438213.62 | Q26: 350570.9 | R26: 0.15 | S26: 87642.72 | T26: 0.0375
A27: - | B27: XIII Gas | C27: Licencia | D27: Quincena | E27: F2 | F27: MM BTU | G27: 407996.3 | H27: 427347.64 | I27: 3.1923192 | J27: 3.3871628 | N27: 1141.48 | O27: 2748809 | P27: 515401.68 | Q27: 412321.35 | R27: 0.15 | S27: 103080.34 | T27: 0.0375
A28: - | B28: XX | C28: Licencia | D28: Quincena | E28: F2 | F28: Bls | G28: 174 | H28: 180 | I28: 78.909 | J28: 80.6475 | N28: 170.75 | O28: 28075.97 | P28: 5264.24 | Q28: 1052.85 | R28: 0.0375 | S28: 4211.4 | T28: 0.15
A29: - | B29: Z1 Crudo | C29: Licencia | D29: Quincena | E29: F2 | F29: Bls | H29: 57356 | J29: 77.8975 | N29: 863.22 | O29: 4467025.8 | P29: 837567.34 | Q29: 167513.47 | R29: 0.0375 | S29: 670053.87 | T29: 0.15
A30: - | B30: Z-69 Crudo | C30: Licencia | D30: Quincena | E30: F2 | F30: Bls | G30: 48651 | H30: 66320 | I30: 78.159 | J30: 78.5075 | N30: 439.52 | O30: 9008691.4 | P30: 1689129.6 | Q30: 1351303.7 | R30: 0.15 | S30: 337825.93 | T30: 0.0375
A31: - | B31: Z-69 Gas | C31: Licencia | D31: Quincena | E31: F2 | F31: MM BTU | G31: 120928.26 | H31: 149821.44 | I31: 2.8377994 | J31: 2.8284847 | N31: 388.92 | O31: 766548.87 | P31: 143727.91 | Q31: 114982.34 | R31: 0.15 | S31: 28745.58 | T31: 0.0375
A32: - | B32: Z-69 Lgn | C32: Licencia | D32: Quincena | E32: F2 | F32: Bls | G32: 10318 | H32: 11016 | I32: 61.4685 | J32: 47.6842 | N32: 423.71 | O32: 1159097.4 | P32: 217330.77 | Q32: 173864.61 | R32: 0.15 | S32: 43466.15 | T32: 0.0375
A33: - | B33: Ajustes meses anteriores (1) | O33: -11688.41 | P33: -2191.58 | Q33: -1753.27 | S33: -438.31
B34: Subtotal | C34: Piura / Tumbes US$ | O34: 63745951 | P34: 11952366 | Q34: 9056193.8 | S34: 2896172.1 | T34: 0
C35: Piura / Tumbes S/. | P35: 44104230 | Q35: 33417355 | S35: 10686875
A36: Provincia Puerto Inca Huanuco | Q36: Puerto Inca
A37: - | B37: 131 | C37: Licencia | D37: Quincena | E37: F2 | F37: Bls | G37: 8116 | H37: 10054 | I37: 67.261 | J37: 67.1331 | N37: 3402.29 | O37: 1217444.2 | P37: 182616.63 | Q37: 182616.63 | R37: 0.15
A38: - | B38: Ajustes meses anteriores (2)
B39: Subtotal | C39: Provincia Puerto Inca Huanuco US$ | O39: 1217444.2 | P39: 182616.63 | Q39: 182616.63 | S39: 0
C40: Provincia Puerto Inca Huanuco S/. | P40: 673855.36 | Q40: 673855.36 | S40: 0
A41: Loreto / Ucayali | Q41: Loreto | S41: Ucayali
...

Sheet Ene-2
A1: Período de Cálculo: | E1: 43101 | U1: Días en el mes | W1: =DATE(YEAR(E1),MONTH(E1)+1,1)-DATE(YEAR(E1),MONTH(E1),1) -> 31
A2: PERUPETRO S.A.
A3: DETERMINACION DEL CANON, SOBRECANON y PARTICIPACION (US$)
A4: ="Correspondiente a "&TEXT(E1,"MMMMMMM YYYY") -> Correspondiente a Enero 2018
A5: ="Tipo de Cambio= "&TEXT(F1,"0.000") -> Tipo de Cambio= 0.000
A7: Localidad | C7: Modalidad de Contrato | D7: Calculo del Canon | F7: Volumen Producción / Venta | I7: Canasta o Valor Venta (US$/Unidad) | K7: Deducción de Gastos para determinación de valor de producción en Punto de Fiscalización (US$) | O7: Valor de la Producción (US$) | P7: Canon y Sobrecanon / Participación (US$) | U7: Resumen por Petróleo y Condensados | AA7: Resumen por Gas Natural | AG7: Control
A8: - Lote | D8: Período | E8: Fórmula | F8: Unidades | G8: 1ra. Q | H8: 2da. Q / Mes | I8: 1ra. Q | J8: 2da. Q / Mes | K8: Flete Marítimo | L8: Comercialización | M8: Oleoducto | N8: Fiscalización | P8: Total | Q8: Localidad 1 | S8: Localidad 2 | U8: Producción / Venta | X8: Valor Prod | Y8: Valor Canon | AA8: Producción / Venta | AD8: Valor Prod | AE8: Valor Canon | AG8: Total
A9: Piura / Tumbes | Q9: Piura | S9: Tumbes | U9: Bls/Mes | V9: V P (US$) | W9: Bls/Día | X9: US$/Bl | Y9: US$/Bl | Z9: US$ | AA9: MM BTU/Mes | AB9: V P (US$) | AC9: MM BTU/Día | AD9: US$/MM BTU | AE9: US$/MM BTU | AF9: US$ | AG9: Canon
A10: - | B10: I | C10: Servicios | D10: Mes | E10: F1 | F10: Bls | H10: 24582 | J10: 67.0812 | N10: 683.58 | O10: =ROUND(G10*I10,2)+ROUND(H10*J10,2)-K10-L10-M10-N10 -> 1648306.5 | P10: =ROUND(18.75%*O10,2) -> 309057.47 | Q10: =ROUND($O10*R10,2) -> 247245.97 | R10: 0.15 | S10: =ROUND($O10*T10,2) -> 61811.49 | T10: 0.0375 | U10: =IF($F10&"/Día"=W$9,SUM($G10:$H10),"") -> 24582 | V10: =IF(U10<>"",$O10,"") -> 1648306.5 | W10: =IF($F10&"/Día"=W$9,ROUND(U10/$W$1,1),"") -> 793 | X10: =IF(U10=0,0,IF($F10&"/Día"=W$9,ROUND(V10/U10,4),"")) -> 67.0534 | Y10: =IF(U10=0,0,IF($F10&"/Día"=W$9,ROUND(Z10/U10,4),"")) -> 12.5725 | Z10: =IF(U10<>"",$P10,"") -> 309057.47 | AA10: =IF($F10&"/Día"=AC$9,SUM($G10:$H10),"") | AB10: =IF(AA10<>"",$O10,"") | AC10: =IF($F10&"/Día"=AC$9,ROUND(AA10/$W$1,1),"") | AD10: =IF(AA10=0,0,IF($F10&"/Día"=AC$9,ROUND(AB10/AA10,4),"")) | AE10: =IF(AA10=0,0,IF($F10&"/Día"=AC$9,ROUND(AF10/AA10,4),"")) | AF10: =IF(AA10<>"",$P10,"")
A11: - | B11: I GAS | C11: Servicios | D11: Mes | E11: F1 | F11: MM BTU | H11: 253218.78 | J11: 2.9822 | N11: 1914.05 | O11: =ROUND(G11*I11,2)+ROUND(H11*J11,2)-K11-L11-M11-N11 -> 753235 | P11: =ROUND(18.75%*O11,2) -> 141231.56 | Q11: =ROUND($O11*R11,2) -> 112985.25 | R11: 0.15 | S11: =ROUND($O11*T11,2) -> 28246.31 | T11: 0.0375 | U11: =IF($F11&"/Día"=W$9,SUM($G11:$H11),"") | V11: =IF(U11<>"",$O11,"") | W11: =IF($F11&"/Día"=W$9,ROUND(U11/$W$1,1),"") | X11: =IF(U11=0,0,IF($F11&"/Día"=W$9,ROUND(V11/U11,4),"")) | Y11: =IF(U11=0,0,IF($F11&"/Día"=W$9,ROUND(Z11/U11,4),"")) | Z11: =IF(U11<>"",$P11,"") | AA11: =IF($F11&"/Día"=AC$9,SUM($G11:$H11),"") -> 253218.78 | AB11: =IF(AA11<>"",$O11,"") -> 753235 | AC11: =IF($F11&"/Día"=AC$9,ROUND(AA11/$W$1,1),"") -> 8168.3 | AD11: =IF(AA11=0,0,IF($F11&"/Día"=AC$9,ROUND(AB11/AA11,4),"")) -> 2.9746 | AE11: =IF(AA11=0,0,IF($F11&"/Día"=AC$9,ROUND(AF11/AA11,4),"")) -> 0.5577 | AF11: =IF(AA11<>"",$P11,"") -> 141231.56
A12: - | B12: II | C12: Licencia | D12: Quincena | E12: F2 | F12: Bls | G12: 4562 | H12: 4721 | I12: 64.1613 | J12: 65.1575 | N12: 1764.83 | O12: =ROUND(G12*I12,2)+ROUND(H12*J12,2)-K12-L12-M12-N12 -> 598547.58 | P12: =ROUND(18.75%*O12,2) -> 112227.67 | Q12: =ROUND($O12*R12,2) -> 89782.14 | R12: 0.15 | S12: =ROUND($O12*T12,2) -> 22445.53 | T12: 0.0375 | U12: =IF($F12&"/Día"=W$9,SUM($G12:$H12),"") -> 9283 | V12: =IF(U12<>"",$O12,"") -> 598547.58 | W12: =IF($F12&"/Día"=W$9,ROUND(U12/$W$1,1),"") -> 299.5 | X12: =IF(U12=0,0,IF($F12&"/Día"=W$9,ROUND(V12/U12,4),"")) -> 64.4778 | Y12: =IF(U12=0,0,IF($F12&"/Día"=W$9,ROUND(Z12/U12,4),"")) -> 12.0896 | Z12: =IF(U12<>"",$P12,"") -> 112227.67 | AA12: =IF($F12&"/Día"=AC$9,SUM($G12:$H12),"") | AB12: =IF(AA12<>"",$O12,"") | AC12: =IF($F12&"/Día"=AC$9,ROUND(AA12/$W$1,1),"") | AD12: =IF(AA12=0,0,IF($F12&"/Día"=AC$9,ROUND(AB12/AA12,4),"")) | AE12: =IF(AA12=0,0,IF($F12&"/Día"=AC$9,ROUND(AF12/AA12,4),"")) | AF12: =IF(AA12<>"",$P12,"")
A13: - | B13: II-GAS | C13: Servicios | D13: Mes | E13: F1 | F13: MM BTU | G13: 40281.697 | H13: 44653.33 | I13: 2.55 | J13: 2.55 | N13: 1884.53 | O13: =ROUND(G13*I13,2)+ROUND(H13*J13,2)-K13-L13-M13-N13 -> 214699.79 | P13: =ROUND(18.75%*O13,2) -> 40256.21 | Q13: =ROUND($P13*R13/(R13+T13),2) -> 32204.97 | R13: 0.15 | S13: =P13-Q13 -> 8051.24 | T13: 0.0375 | U13: =IF($F13&"/Día"=W$9,SUM($G13:$H13),"") | V13: =IF(U13<>"",$O13,"") | W13: =IF($F13&"/Día"=W$9,ROUND(U13/$W$1,1),"") | X13: =IF(U13=0,0,IF($F13&"/Día"=W$9,ROUND(V13/U13,4),"")) | Y13: =IF(U13=0,0,IF($F13&"/Día"=W$9,ROUND(Z13/U13,4),"")) | Z13: =IF(U13<>"",$P13,"") | AA13: =IF($F13&"/Día"=AC$9,SUM($G13:$H13),"") -> 84935.027 | AB13: =IF(AA13<>"",$O13,"") -> 214699.79 | AC13: =IF($F13&"/Día"=AC$9,ROUND(AA13/$W$1,1),"") -> 2739.8 | AD13: =IF(AA13=0,0,IF($F13&"/Día"=AC$9,ROUND(AB13/AA13,4),"")) -> 2.5278 | AE13: =IF(AA13=0,0,IF($F13&"/Día"=AC$9,ROUND(AF13/AA13,4),"")) -> 0.474 | AF13: =IF(AA13<>"",$P13,"") -> 40256.21
A14: - | B14: III | C14: Licencia | D14: Quincena | E14: F2 | F14: Bls | G14: 11836 | H14: 12495 | I14: 66.7972 | J14: 67.3179 | N14: 1257.31 | O14: =ROUND(G14*I14,2)+ROUND(H14*J14,2)-K14-L14-M14-N14 -> 1630491.5 | P14: =ROUND(18.75%*O14,2) -> 305717.16 | Q14: =ROUND($O14*R14,2) -> 244573.73 | R14: 0.15 | S14: =ROUND($O14*T14,2) -> 61143.43 | T14: 0.0375 | U14: =IF($F14&"/Día"=W$9,SUM($G14:$H14),"") -> 24331 | V14: =IF(U14<>"",$O14,"") -> 1630491.5 | W14: =IF($F14&"/Día"=W$9,ROUND(U14/$W$1,1),"") -> 784.9 | X14: =IF(U14=0,0,IF($F14&"/Día"=W$9,ROUND(V14/U14,4),"")) -> 67.0129 | Y14: =IF(U14=0,0,IF($F14&"/Día"=W$9,ROUND(Z14/U14,4),"")) -> 12.5649 | Z14: =IF(U14<>"",$P14,"") -> 305717.16 | AA14: =IF($F14&"/Día"=AC$9,SUM($G14:$H14),"") | AB14: =IF(AA14<>"",$O14,"") | AC14: =IF($F14&"/Día"=AC$9,ROUND(AA14/$W$1,1),"") | AD14: =IF(AA14=0,0,IF($F14&"/Día"=AC$9,ROUND(AB14/AA14,4),"")) | AE14: =IF(AA14=0,0,IF($F14&"/Día"=AC$9,ROUND(AF14/AA14,4),"")) | AF14: =IF(AA14<>"",$P14,"")
A15: - | B15: IV | C15: Licencia | D15: Quincena | E15: F2 | F15: Bls | G15: 17378 | H15: 20845 | I15: 66.7972 | J15: 67.3179 | N15: 3247.24 | O15: =ROUND(G15*I15,2)+ROUND(H15*J15,2)-K15-L15-M15-N15 -> 2560796.1 | P15: =ROUND(18.75%*O15,2) -> 480149.27 | Q15: =ROUND($O15*R15,2) -> 384119.42 | R15: 0.15 | S15: =ROUND($O15*T15,2) -> 96029.85 | T15: 0.0375 | U15: =IF($F15&"/Día"=W$9,SUM($G15:$H15),"") -> 38223 | V15: =IF(U15<>"",$O15,"") -> 2560796.1 | W15: =IF($F15&"/Día"=W$9,ROUND(U15/$W$1,1),"") -> 1233 | X15: =IF(U15=0,0,IF($F15&"/Día"=W$9,ROUND(V15/U15,4),"")) -> 66.9962 | Y15: =IF(U15=0,0,IF($F15&"/Día"=W$9,ROUND(Z15/U15,4),"")) -> 12.5618 | Z15: =IF(U15<>"",$P15,"") -> 480149.27 | AA15: =IF($F15&"/Día"=AC$9,SUM($G15:$H15),"") | AB15: =IF(AA15<>"",$O15,"") | AC15: =IF($F15&"/Día"=AC$9,ROUND(AA15/$W$1,1),"") | AD15: =IF(AA15=0,0,IF($F15&"/Día"=AC$9,ROUND(AB15/AA15,4),"")) | AE15: =IF(AA15=0,0,IF($F15&"/Día"=AC$9,ROUND(AF15/AA15,4),"")) | AF15: =IF(AA15<>"",$P15,"")
A16: - | B16: V | C16: Servicios | D16: Mes | E16: F1 | F16: Bls | H16: 2532 | J16: 67.0812 | N16: 1487.58 | O16: =ROUND(G16*I16,2)+ROUND(H16*J16,2)-K16-L16-M16-N16 -> 168362.02 | P16: =ROUND(18.75%*O16,2) -> 31567.88 | Q16: =ROUND($O16*R16,2) -> 25254.3 | R16: 0.15 | S16: =ROUND($O16*T16,2) -> 6313.58 | T16: 0.0375 | U16: =IF($F16&"/Día"=W$9,SUM($G16:$H16),"") -> 2532 | V16: =IF(U16<>"",$O16,"") -> 168362.02 | W16: =IF($F16&"/Día"=W$9,ROUND(U16/$W$1,1),"") -> 81.7 | X16: =IF(U16=0,0,IF($F16&"/Día"=W$9,ROUND(V16/U16,4),"")) -> 66.4937 | Y16: =IF(U16=0,0,IF($F16&"/Día"=W$9,ROUND(Z16/U16,4),"")) -> 12.4676 | Z16: =IF(U16<>"",$P16,"") -> 31567.88 | AA16: =IF($F16&"/Día"=AC$9,SUM($G16:$H16),"") | AB16: =IF(AA16<>"",$O16,"") | AC16: =IF($F16&"/Día"=AC$9,ROUND(AA16/$W$1,1),"") | AD16: =IF(AA16=0,0,IF($F16&"/Día"=AC$9,ROUND(AB16/AA16,4),"")) | AE16: =IF(AA16=0,0,IF($F16&"/Día"=AC$9,ROUND(AF16/AA16,4),"")) | AF16: =IF(AA16<>"",$P16,"")
A17: - | B17: VII/VI | C17: Licencia | D17: Quincena | E17: F2 | F17: Bls | G17: 46815 | H17: 59830 | I17: 66.2472 | J17: 66.7679 | N17: 2221.88 | O17: =ROUND(G17*I17,2)+ROUND(H17*J17,2)-K17-L17-M17-N17 -> 7093864.2 | P17: =ROUND(18.75%*O17,2) -> 1330099.6 | Q17: =ROUND($O17*R17,2) -> 1064079.6 | R17: 0.15 | S17: =ROUND($O17*T17,2) -> 266019.91 | T17: 0.0375 | U17: =IF($F17&"/Día"=W$9,SUM($G17:$H17),"") -> 106645 | V17: =IF(U17<>"",$O17,"") -> 7093864.2 | W17: =IF($F17&"/Día"=W$9,ROUND(U17/$W$1,1),"") -> 3440.2 | X17: =IF(U17=0,0,IF($F17&"/Día"=W$9,ROUND(V17/U17,4),"")) -> 66.5185 | Y17: =IF(U17=0,0,IF($F17&"/Día"=W$9,ROUND(Z17/U17,4),"")) -> 12.4722 | Z17: =IF(U17<>"",$P17,"") -> 1330099.6 | AA17: =IF($F17&"/Día"=AC$9,SUM($G17:$H17),"") | AB17: =IF(AA17<>"",$O17,"") | AC17: =IF($F17&"/Día"=AC$9,ROUND(AA17/$W$1,1),"") | AD17: =IF(AA17=0,0,IF($F17&"/Día"=AC$9,ROUND(AB17/AA17,4),"")) | AE17: =IF(AA17=0,0,IF($F17&"/Día"=AC$9,ROUND(AF17/AA17,4),"")) | AF17: =IF(AA17<>"",$P17,"")
A18: - | B18: VII | C18: Servicios | D18: Mes | E18: F1 | F18: Bls | O18: =ROUND(G18*I18,2)+ROUND(H18*J18,2)-K18-L18-M18-N18 -> 0 | P18: =ROUND(18.75%*O18,2) -> 0 | Q18: =ROUND($O18*R18,2) -> 0 | R18: 0.15 | S18: =ROUND($O18*T18,2) -> 0 | T18: 0.0375 | U18: =IF($F18&"/Día"=W$9,SUM($G18:$H18),"") -> 0 | V18: =IF(U18<>"",$O18,"") -> 0 | W18: =IF($F18&"/Día"=W$9,ROUND(U18/$W$1,1),"") -> 0 | X18: =IF(U18=0,0,IF($F18&"/Día"=W$9,ROUND(V18/U18,4),"")) -> 0 | Y18: =IF(U18=0,0,IF($F18&"/Día"=W$9,ROUND(Z18/U18,4),"")) -> 0 | Z18: =IF(U18<>"",$P18,"") -> 0 | AA18: =IF($F18&"/Día"=AC$9,SUM($G18:$H18),"") | AB18: =IF(AA18<>"",$O18,"") | AC18: =IF($F18&"/Día"=AC$9,ROUND(AA18/$W$1,1),"") | AD18: =IF(AA18=0,0,IF($F18&"/Día"=AC$9,ROUND(AB18/AA18,4),"")) | AE18: =IF(AA18=0,0,IF($F18&"/Día"=AC$9,ROUND(AF18/AA18,4),"")) | AF18: =IF(AA18<>"",$P18,"")
A19: - | B19: VII/VI-GAS | C19: Licencia | D19: Quincena | E19: F2 | F19: MM BTU | G19: 58474.37 | H19: 64682.42 | I19: 2.1708 | J19: 2.1708 | N19: 2121.65 | O19: =ROUND(G19*I19,2)+ROUND(H19*J19,2)-K19-L19-M19-N19 -> 265227.11 | P19: =ROUND(18.75%*O19,2) -> 49730.08 | Q19: =ROUND($O19*R19,2) -> 39784.07 | R19: 0.15 | S19: =ROUND($O19*T19,2) -> 9946.02 | T19: 0.0375 | U19: =IF($F19&"/Día"=W$9,SUM($G19:$H19),"") | V19: =IF(U19<>"",$O19,"") | W19: =IF($F19&"/Día"=W$9,ROUND(U19/$W$1,1),"") | X19: =IF(U19=0,0,IF($F19&"/Día"=W$9,ROUND(V19/U19,4),"")) | Y19: =IF(U19=0,0,IF($F19&"/Día"=W$9,ROUND(Z19/U19,4),"")) | Z19: =IF(U19<>"",$P19,"") | AA19: =IF($F19&"/Día"=AC$9,SUM($G19:$H19),"") -> 123156.79 | AB19: =IF(AA19<>"",$O19,"") -> 265227.11 | AC19: =IF($F19&"/Día"=AC$9,ROUND(AA19/$W$1,1),"") -> 3972.8 | AD19: =IF(AA19=0,0,IF($F19&"/Día"=AC$9,ROUND(AB19/AA19,4),"")) -> 2.1536 | AE19: =IF(AA19=0,0,IF($F19&"/Día"=AC$9,ROUND(AF19/AA19,4),"")) -> 0.4038 | AF19: =IF(AA19<>"",$P19,"") -> 49730.08
A20: - | B20: IX | C20: Licencia | D20: Quincena | E20: F2 | F20: Bls | G20: 2083 | H20: 3260 | I20: 66.7972 | J20: 67.3179 | N20: 737.78 | O20: =ROUND(G20*I20,2)+ROUND(H20*J20,2)-K20-L20-M20-N20 -> 357857.14 | P20: =ROUND(18.75%*O20,2) -> 67098.21 | Q20: =ROUND($O20*R20,2) -> 53678.57 | R20: 0.15 | S20: =ROUND($O20*T20,2) -> 13419.64 | T20: 0.0375 | U20: =IF($F20&"/Día"=W$9,SUM($G20:$H20),"") -> 5343 | V20: =IF(U20<>"",$O20,"") -> 357857.14 | W20: =IF($F20&"/Día"=W$9,ROUND(U20/$W$1,1),"") -> 172.4 | X20: =IF(U20=0,0,IF($F20&"/Día"=W$9,ROUND(V20/U20,4),"")) -> 66.9768 | Y20: =IF(U20=0,0,IF($F20&"/Día"=W$9,ROUND(Z20/U20,4),"")) -> 12.5582 | Z20: =IF(U20<>"",$P20,"") -> 67098.21 | AA20: =IF($F20&"/Día"=AC$9,SUM($G20:$H20),"") | AB20: =IF(AA20<>"",$O20,"") | AC20: =IF($F20&"/Día"=AC$9,ROUND(AA20/$W$1,1),"") | AD20: =IF(AA20=0,0,IF($F20&"/Día"=AC$9,ROUND(AB20/AA20,4),"")) | AE20: =IF(AA20=0,0,IF($F20&"/Día"=AC$9,ROUND(AF20/AA20,4),"")) | AF20: =IF(AA20<>"",$P20,"")
A21: - | B21: X | C21: Licencia | D21: Quincena | E21: F2 | F21: Bls | G21: 195037 | H21: 205982 | I21: 66.7972 | J21: 67.3179 | N21: 4334.18 | O21: =ROUND(G21*I21,2)+ROUND(H21*J21,2)-K21-L21-M21-N21 -> 26889867 | P21: =ROUND(18.75%*O21,2) -> 5041850.1 | Q21: =ROUND($O21*R21,2) -> 4033480 | R21: 0.15 | S21: =ROUND($O21*T21,2) -> 1008370 | T21: 0.0375 | U21: =IF($F21&"/Día"=W$9,SUM($G21:$H21),"") -> 401019 | V21: =IF(U21<>"",$O21,"") -> 26889867 | W21: =IF($F21&"/Día"=W$9,ROUND(U21/$W$1,1),"") -> 12936.1 | X21: =IF(U21=0,0,IF($F21&"/Día"=W$9,ROUND(V21/U21,4),"")) -> 67.0538 | Y21: =IF(U21=0,0,IF($F21&"/Día"=W$9,ROUND(Z21/U21,4),"")) -> 12.5726 | Z21: =IF(U21<>"",$P21,"") -> 5041850.1 | AA21: =IF($F21&"/Día"=AC$9,SUM($G21:$H21),"") | AB21: =IF(AA21<>"",$O21,"") | AC21: =IF($F21&"/Día"=AC$9,ROUND(AA21/$W$1,1),"") | AD21: =IF(AA21=0,0,IF($F21&"/Día"=AC$9,ROUND(AB21/AA21,4),"")) | AE21: =IF(AA21=0,0,IF($F21&"/Día"=AC$9,ROUND(AF21/AA21,4),"")) | AF21: =IF(AA21<>"",$P21,"")
A22: - | B22: X-GAS | C22: Licencia | D22: Mes | E22: F2 | F22: MM BTU | G22: 251980.16 | H22: 254840.6 | I22: 1.8012 | J22: 1.8012 | N22: 2235.16 | O22: =ROUND(G22*I22,2)+ROUND(H22*J22,2)-K22-L22-M22-N22 -> 910650.39 | P22: =ROUND(18.75%*O22,2) -> 170746.95 | Q22: =ROUND($O22*R22,2) -> 136597.56 | R22: 0.15 | S22: =ROUND($O22*T22,2) -> 34149.39 | T22: 0.0375 | U22: =IF($F22&"/Día"=W$9,SUM($G22:$H22),"") | V22: =IF(U22<>"",$O22,"") | W22: =IF($F22&"/Día"=W$9,ROUND(U22/$W$1,1),"") | X22: =IF(U22=0,0,IF($F22&"/Día"=W$9,ROUND(V22/U22,4),"")) | Y22: =IF(U22=0,0,IF($F22&"/Día"=W$9,ROUND(Z22/U22,4),"")) | Z22: =IF(U22<>"",$P22,"") | AA22: =IF($F22&"/Día"=AC$9,SUM($G22:$H22),"") -> 506820.76 | AB22: =IF(AA22<>"",$O22,"") -> 910650.39 | AC22: =IF($F22&"/Día"=AC$9,ROUND(AA22/$W$1,1),"") -> 16349.1 | AD22: =IF(AA22=0,0,IF($F22&"/Día"=AC$9,ROUND(AB22/AA22,4),"")) -> 1.7968 | AE22: =IF(AA22=0,0,IF($F22&"/Día"=AC$9,ROUND(AF22/AA22,4),"")) -> 0.3369 | AF22: =IF(AA22<>"",$P22,"") -> 170746.95
A23: - | B23: XIV | C23: Licencia | D23: Mes | E23: F2 | F23: Bls | O23: =ROUND(G23*I23,2)+ROUND(H23*J23,2)-K23-L23-M23-N23 -> 0 | P23: =ROUND(18.75%*O23,2) -> 0 | Q23: =ROUND($O23*R23,2) -> 0 | R23: 0.15 | S23: =ROUND($O23*T23,2) -> 0 | T23: 0.0375 | U23: =IF($F23&"/Día"=W$9,SUM($G23:$H23),"") -> 0 | V23: =IF(U23<>"",$O23,"") -> 0 | W23: =IF($F23&"/Día"=W$9,ROUND(U23/$W$1,1),"") -> 0 | X23: =IF(U23=0,0,IF($F23&"/Día"=W$9,ROUND(V23/U23,4),"")) -> 0 | Y23: =IF(U23=0,0,IF($F23&"/Día"=W$9,ROUND(Z23/U23,4),"")) -> 0 | Z23: =IF(U23<>"",$P23,"") -> 0 | AA23: =IF($F23&"/Día"=AC$9,SUM($G23:$H23),"") | AB23: =IF(AA23<>"",$O23,"") | AC23: =IF($F23&"/Día"=AC$9,ROUND(AA23/$W$1,1),"") | AD23: =IF(AA23=0,0,IF($F23&"/Día"=AC$9,ROUND(AB23/AA23,4),"")) | AE23: =IF(AA23=0,0,IF($F23&"/Día"=AC$9,ROUND(AF23/AA23,4),"")) | AF23: =IF(AA23<>"",$P23,"")
A24: - | B24: XV | C24: Licencia | D24: Quincena | E24: F2 | F24: Bls | G24: 564 | H24: 535 | I24: 66.5365 | J24: 67.7014 | N24: 802.26 | O24: =ROUND(G24*I24,2)+ROUND(H24*J24,2)-K24-L24-M24-N24 -> 72944.58 | P24: =ROUND(18.75%*O24,2) -> 13677.11 | Q24: =ROUND($O24*R24,2) -> 10941.69 | R24: 0.15 | S24: =ROUND($O24*T24,2) -> 2735.42 | T24: 0.0375 | U24: =IF($F24&"/Día"=W$9,SUM($G24:$H24),"") -> 1099 | V24: =IF(U24<>"",$O24,"") -> 72944.58 | W24: =IF($F24&"/Día"=W$9,ROUND(U24/$W$1,1),"") -> 35.5 | X24: =IF(U24=0,0,IF($F24&"/Día"=W$9,ROUND(V24/U24,4),"")) -> 66.3736 | Y24: =IF(U24=0,0,IF($F24&"/Día"=W$9,ROUND(Z24/U24,4),"")) -> 12.4451 | Z24: =IF(U24<>"",$P24,"") -> 13677.11 | AA24: =IF($F24&"/Día"=AC$9,SUM($G24:$H24),"") | AB24: =IF(AA24<>"",$O24,"") | AC24: =IF($F24&"/Día"=AC$9,ROUND(AA24/$W$1,1),"") | AD24: =IF(AA24=0,0,IF($F24&"/Día"=AC$9,ROUND(AB24/AA24,4),"")) | AE24: =IF(AA24=0,0,IF($F24&"/Día"=AC$9,ROUND(AF24/AA24,4),"")) | AF24: =IF(AA24<>"",$P24,"")
A25: - | B25: XIII Crudo | C25: Licencia | D25: Quincena | E25: F2 | F25: Bls | G25: 28828 | H25: 36208 | I25: 66.7972 | J25: 67.3179 | N25: 1530.48 | O25: =ROUND(G25*I25,2)+ROUND(H25*J25,2)-K25-L25-M25-N25 -> 4361545.7 | P25: =ROUND(18.75%*O25,2) -> 817789.82 | Q25: =ROUND($O25*R25,2) -> 654231.86 | R25: 0.15 | S25: =ROUND($O25*T25,2) -> 163557.96 | T25: 0.0375 | U25: =IF($F25&"/Día"=W$9,SUM($G25:$H25),"") -> 65036 | V25: =IF(U25<>"",$O25,"") -> 4361545.7 | W25: =IF($F25&"/Día"=W$9,ROUND(U25/$W$1,1),"") -> 2097.9 | X25: =IF(U25=0,0,IF($F25&"/Día"=W$9,ROUND(V25/U25,4),"")) -> 67.0636 | Y25: =IF(U25=0,0,IF($F25&"/Día"=W$9,ROUND(Z25/U25,4),"")) -> 12.5744 | Z25: =IF(U25<>"",$P25,"") -> 817789.82 | AA25: =IF($F25&"/Día"=AC$9,SUM($G25:$H25),"") | AB25: =IF(AA25<>"",$O25,"") | AC25: =IF($F25&"/Día"=AC$9,ROUND(AA25/$W$1,1),"") | AD25: =IF(AA25=0,0,IF($F25&"/Día"=AC$9,ROUND(AB25/AA25,4),"")) | AE25: =IF(AA25=0,0,IF($F25&"/Día"=AC$9,ROUND(AF25/AA25,4),"")) | AF25: =IF(AA25<>"",$P25,"")
A26: - | B26: XIII COND | C26: Licencia | D26: Quincena | E26: F2 | F26: Bls | O26: =ROUND(G26*I26,2)+ROUND(H26*J26,2)-K26-L26-M26-N26 -> 0 | P26: =ROUND(18.75%*O26,2) -> 0 | Q26: =ROUND($O26*R26,2) -> 0 | R26: 0.15 | S26: =ROUND($O26*T26,2) -> 0 | T26: 0.0375 | U26: =IF($F26&"/Día"=W$9,SUM($G26:$H26),"") -> 0 | V26: =IF(U26<>"",$O26,"") -> 0 | W26: =IF($F26&"/Día"=W$9,ROUND(U26/$W$1,1),"") -> 0 | X26: =IF(U26=0,0,IF($F26&"/Día"=W$9,ROUND(V26/U26,4),"")) -> 0 | Y26: =IF(U26=0,0,IF($F26&"/Día"=W$9,ROUND(Z26/U26,4),"")) -> 0 | Z26: =IF(U26<>"",$P26,"") -> 0 | AA26: =IF($F26&"/Día"=AC$9,SUM($G26:$H26),"") | AB26: =IF(AA26<>"",$O26,"") | AC26: =IF($F26&"/Día"=AC$9,ROUND(AA26/$W$1,1),"") | AD26: =IF(AA26=0,0,IF($F26&"/Día"=AC$9,ROUND(AB26/AA26,4),"")) | AE26: =IF(AA26=0,0,IF($F26&"/Día"=AC$9,ROUND(AF26/AA26,4),"")) | AF26: =IF(AA26<>"",$P26,"")
A27: - | B27: XIII Gas | C27: Licencia | D27: Quincena | E27: F2 | F27: MM BTU | G27: =109679.9639+69454.7114 -> 179134.68 | H27: =115352.29+94462.85 -> 209815.14 | I27: 2.4759775 | J27: 2.6336074 | N27: 3163.29 | O27: =ROUND(G27*I27,2)+ROUND(H27*J27,2)-K27-L27-M27-N27 -> 992940.84 | P27: =ROUND(18.75%*O27,2) -> 186176.41 | Q27: =ROUND($O27*R27,2) -> 148941.13 | R27: 0.15 | S27: =ROUND($O27*T27,2) -> 37235.28 | T27: 0.0375 | U27: =IF($F27&"/Día"=W$9,SUM($G27:$H27),"") | V27: =IF(U27<>"",$O27,"") | W27: =IF($F27&"/Día"=W$9,ROUND(U27/$W$1,1),"") | X27: =IF(U27=0,0,IF($F27&"/Día"=W$9,ROUND(V27/U27,4),"")) | Y27: =IF(U27=0,0,IF($F27&"/Día"=W$9,ROUND(Z27/U27,4),"")) | Z27: =IF(U27<>"",$P27,"") | AA27: =IF($F27&"/Día"=AC$9,SUM($G27:$H27),"") -> 388949.82 | AB27: =IF(AA27<>"",$O27,"") -> 992940.84 | AC27: =IF($F27&"/Día"=AC$9,ROUND(AA27/$W$1,1),"") -> 12546.8 | AD27: =IF(AA27=0,0,IF($F27&"/Día"=AC$9,ROUND(AB27/AA27,4),"")) -> 2.5529 | AE27: =IF(AA27=0,0,IF($F27&"/Día"=AC$9,ROUND(AF27/AA27,4),"")) -> 0.4787 | AF27: =IF(AA27<>"",$P27,"") -> 186176.41
A28: - | B28: Z-2B | C28: Servicios | D28: Mes | E28: F1 | F28: Bls | H28: =39453+207131 -> 246584 | J28: 64.0398 | N28: 2445.75 | O28: =ROUND(G28*I28,2)+ROUND(H28*J28,2)-K28-L28-M28-N28 -> 15788744 | P28: =ROUND(18.75%*O28,2) -> 2960389.5 | Q28: =ROUND($O28*R28,2) -> 2368311.6 | R28: 0.15 | S28: =ROUND($O28*T28,2) -> 592077.91 | T28: 0.0375 | U28: =IF($F28&"/Día"=W$9,SUM($G28:$H28),"") -> 246584 | V28: =IF(U28<>"",$O28,"") -> 15788744 | W28: =IF($F28&"/Día"=W$9,ROUND(U28/$W$1,1),"") -> 7954.3 | X28: =IF(U28=0,0,IF($F28&"/Día"=W$9,ROUND(V28/U28,4),"")) -> 64.0299 | Y28: =IF(U28=0,0,IF($F28&"/Día"=W$9,ROUND(Z28/U28,4),"")) -> 12.0056 | Z28: =IF(U28<>"",$P28,"") -> 2960389.5 | AA28: =IF($F28&"/Día"=AC$9,SUM($G28:$H28),"") | AB28: =IF(AA28<>"",$O28,"") | AC28: =IF($F28&"/Día"=AC$9,ROUND(AA28/$W$1,1),"") | AD28: =IF(AA28=0,0,IF($F28&"/Día"=AC$9,ROUND(AB28/AA28,4),"")) | AE28: =IF(AA28=0,0,IF($F28&"/Día"=AC$9,ROUND(AF28/AA28,4),"")) | AF28: =IF(AA28<>"",$P28,"")
A29: - | B29: Z-2B GAS | C29: Servicios | D29: Mes | E29: F1 | F29: MM BTU | H29: =28128.11+153471.87+1104.62 -> 182704.6 | J29: 5.4650451 | N29: 2156.75 | O29: =ROUND(G29*I29,2)+ROUND(H29*J29,2)-K29-L29-M29-N29 -> 996332.12 | P29: =ROUND(18.75%*O29,2) -> 186812.27 | Q29: =ROUND($O29*R29,2) -> 149449.82 | R29: 0.15 | S29: =ROUND($O29*T29,2) -> 37362.45 | T29: 0.0375 | U29: =IF($F29&"/Día"=W$9,SUM($G29:$H29),"") | V29: =IF(U29<>"",$O29,"") | W29: =IF($F29&"/Día"=W$9,ROUND(U29/$W$1,1),"") | X29: =IF(U29=0,0,IF($F29&"/Día"=W$9,ROUND(V29/U29,4),"")) | Y29: =IF(U29=0,0,IF($F29&"/Día"=W$9,ROUND(Z29/U29,4),"")) | Z29: =IF(U29<>"",$P29,"") | AA29: =IF($F29&"/Día"=AC$9,SUM($G29:$H29),"") -> 182704.6 | AB29: =IF(AA29<>"",$O29,"") -> 996332.12 | AC29: =IF($F29&"/Día"=AC$9,ROUND(AA29/$W$1,1),"") -> 5893.7 | AD29: =IF(AA29=0,0,IF($F29&"/Día"=AC$9,ROUND(AB29/AA29,4),"")) -> 5.4532 | AE29: =IF(AA29=0,0,IF($F29&"/Día"=AC$9,ROUND(AF29/AA29,4),"")) -> 1.0225 | AF29: =IF(AA29<>"",$P29,"") -> 186812.27
A30: - | B30: XX | C30: Licencia | D30: Quincena | E30: F2 | F30: Bls | G30: 480 | H30: 368 | I30: 66.7972 | J30: 67.3179 | N30: 471.2 | O30: =ROUND(G30*I30,2)+ROUND(H30*J30,2)-K30-L30-M30-N30 -> 56364.45 | P30: =ROUND(18.75%*O30,2) -> 10568.33 | Q30: =ROUND($O30*R30,2) -> 2113.67 | R30: 0.0375 | S30: =ROUND($O30*T30,2) -> 8454.67 | T30: 0.15 | U30: =IF($F30&"/Día"=W$9,SUM($G30:$H30),"") -> 848 | V30: =IF(U30<>"",$O30,"") -> 56364.45 | W30: =IF($F30&"/Día"=W$9,ROUND(U30/$W$1,1),"") -> 27.4 | X30: =IF(U30=0,0,IF($F30&"/Día"=W$9,ROUND(V30/U30,4),"")) -> 66.4675 | Y30: =IF(U30=0,0,IF($F30&"/Día"=W$9,ROUND(Z30/U30,4),"")) -> 12.4627 | Z30: =IF(U30<>"",$P30,"") -> 10568.33 | AA30: =IF($F30&"/Día"=AC$9,SUM($G30:$H30),"") | AB30: =IF(AA30<>"",$O30,"") | AC30: =IF($F30&"/Día"=AC$9,ROUND(AA30/$W$1,1),"") | AD30: =IF(AA30=0,0,IF($F30&"/Día"=AC$9,ROUND(AB30/AA30,4),"")) | AE30: =IF(AA30=0,0,IF($F30&"/Día"=AC$9,ROUND(AF30/AA30,4),"")) | AF30: =IF(AA30<>"",$P30,"")
A31: - | B31: Z1 Crudo | C31: Licencia | D31: Quincena | E31: F2 | F31: Bls | N31: 1450.98 | O31: =ROUND(G31*I31,2)+ROUND(H31*J31,2)-K31-L31-M31-N31 -> -1450.98 | P31: =ROUND(18.75%*O31,2) -> -272.06 | Q31: =ROUND($O31*R31,2) -> -54.41 | R31: 0.0375 | S31: =ROUND($O31*T31,2) -> -217.65 | T31: 0.15 | U31: =IF($F31&"/Día"=W$9,SUM($G31:$H31),"") -> 0 | V31: =IF(U31<>"",$O31,"") -> -1450.98 | W31: =IF($F31&"/Día"=W$9,ROUND(U31/$W$1,1),"") -> 0 | X31: =IF(U31=0,0,IF($F31&"/Día"=W$9,ROUND(V31/U31,4),"")) -> 0 | Y31: =IF(U31=0,0,IF($F31&"/Día"=W$9,ROUND(Z31/U31,4),"")) -> 0 | Z31: =IF(U31<>"",$P31,"") -> -272.06 | AA31: =IF($F31&"/Día"=AC$9,SUM($G31:$H31),"") | AB31: =IF(AA31<>"",$O31,"") | AC31: =IF($F31&"/Día"=AC$9,ROUND(AA31/$W$1,1),"") | AD31: =IF(AA31=0,0,IF($F31&"/Día"=AC$9,ROUND(AB31/AA31,4),"")) | AE31: =IF(AA31=0,0,IF($F31&"/Día"=AC$9,ROUND(AF31/AA31,4),"")) | AF31: =IF(AA31<>"",$P31,"")
A32: - | B32: Z1 Gas | C32: Licencia | D32: Quincena | E32: F2 | F32: MM BTU | O32: =ROUND(G32*I32,2)+ROUND(H32*J32,2)-K32-L32-M32-N32 -> 0 | P32: =ROUND(18.75%*O32,2) -> 0 | Q32: =ROUND($O32*R32,2) -> 0 | R32: 0.0375 | S32: =ROUND($O32*T32,2) -> 0 | T32: 0.15 | U32: =IF($F32&"/Día"=W$9,SUM($G32:$H32),"") | V32: =IF(U32<>"",$O32,"") | W32: =IF($F32&"/Día"=W$9,ROUND(U32/$W$1,1),"") | X32: =IF(U32=0,0,IF($F32&"/Día"=W$9,ROUND(V32/U32,4),"")) | Y32: =IF(U32=0,0,IF($F32&"/Día"=W$9,ROUND(Z32/U32,4),"")) | Z32: =IF(U32<>"",$P32,"") | AA32: =IF($F32&"/Día"=AC$9,SUM($G32:$H32),"") -> 0 | AB32: =IF(AA32<>"",$O32,"") -> 0 | AC32: =IF($F32&"/Día"=AC$9,ROUND(AA32/$W$1,1),"") -> 0 | AD32: =IF(AA32=0,0,IF($F32&"/Día"=AC$9,ROUND(AB32/AA32,4),"")) -> 0 | AE32: =IF(AA32=0,0,IF($F32&"/Día"=AC$9,ROUND(AF32/AA32,4),"")) -> 0 | AF32: =IF(AA32<>"",$P32,"") -> 0
