Workbook
Name tc: Sep!$N$1
Name tc: Ago!$N$1

Sheet Recuperado_Hoja1
N6: Pagina : | P6: 1/1
A8: Gerencia de Supervisión de Contratos | N8: Fecha : | P8: 45238
A10: reporte_ajuste_regalia_quincenal.rpt | N10: Hora : | P10: 0.72101852
I13: AJUSTE DE REGALIA CORRESPONDIENTE A LA
I15: SEGUNDA QUINCENA DEL MES OCTUBRE DEL 2023
E20: VALOR PRODUCCION | F20: VALOR PRODUCCION | H20: CANASTA | I20: CANASTA | J20: MONTO REGALIA | K20: MONTO REGALIA
A21: LOTE | B21: PERIODO | C21: MES AFECTADO | D21: PERIODO | E21: ORIGINAL | F21: AJUSTADO | H21: ORIGINAL | I21: AJUSTADA | J21: ORIGINAL | K21: AJUSTADO | L21: MONTO AJUSTE | M21: FECHA PAGO | N21: OBSERVACION
J22: US$ | K22: US$ | L22: US$
A26: HIDROCARBURO : | C26: GAS
A28: 56 | B28: 2023 | C28: SETIEMBRE | D28: SEGUNDA QUINCENA | E28: 27963147 | F28: 25283022 | H28: 5.415 | I28: 4.896 | J28: 10625996 | K28: 9607548.5 | L28: -1018447.2 | M28: 45233 | N28: Ajuste que considera cambio de destino de los embarques # 737 de Francia a Holanda y # 738 de Japón a Francia.
A31: 56 | B31: 2023 | C31: OCTUBRE | D31: PRIMERA QUINCENA | E31: 24372651 | F31: 22855598 | H31: 4.884 | I31: 4.58 | J31: 9261607.4 | K31: 8685127.3 | L31: -576480.06 | M31: 45233 | N31: Ajuste que considera cambio de destino del embarque # 739 de España a Reino Unido.
J35: SUB TOTAL | L35: -1594927.3
A37: 57 | B37: 2023 | C37: SETIEMBRE | D37: PRIMERA QUINCENA | E37: 17874603 | F37: 16902455 | H37: 4.707 | I37: 4.451 | J37: 1942969.3 | K37: 1837296.9 | L37: -105672.43 | M37: 45233 | N37: AJUSTE QUE CONSIDERA EL PRECIO REALIZADO DEL MES DE SETIEMBRE 2023, SEGÚN FACTURA N°F057-00000839 EMITIDA EL 10.10.2023 Y LAS NOTAS ND 058, 059 Y NC 148
A40: 57 | B40: 2023 | C40: SETIEMBRE | D40: SEGUNDA QUINCENA | E40: 18534725 | F40: 17526676 | H40: 4.707 | I40: 4.451 | J40: 2061061.4 | K40: 1948966.3 | L40: -112095.12 | M40: 45233 | N40: AJUSTE QUE CONSIDERA EL PRECIO REALIZADO DEL MES DE SETIEMBRE 2023, SEGÚN FACTURA N°F057-00000839 EMITIDA EL 10.10.2023 Y LAS NOTAS ND 058, 059 Y NC 148.
A43: 57 | B43: 2023 | C43: OCTUBRE | D43: PRIMERA QUINCENA | E43: 18131148 | F43: 17145048 | H43: 4.707 | I43: 4.451 | J43: 1987173.9 | K43: 1879097.3 | L43: -108076.59 | M43: 45233 | N43: AJUSTE QUE CONSIDERA EL PRECIO REALIZADO DEL MES DE SETIEMBRE 2023, SEGÚN FACTURA N°F057-00000839 EMITIDA EL 10.10.2023 Y LAS NOTAS ND 058, 059 Y NC 148.
J47: SUB TOTAL | L47: -325844.14
A49: VII_VI | B49: 2023 | C49: OCTUBRE | D49: PRIMERA QUINCENA | E49: 158453.96 | F49: 160506.8 | H49: 3.0026 | I49: 3.0415 | J49: 31690.79 | K49: 32101.36 | L49: 410.57 | M49: 45223 | N49: CONSIDERA PRECIO REALIZADO DEL MES DE OCTUBRE DE 2023, DE ACUERDO A FACTURA Nº FS02- 00000112 REMITIDA POR SAPET A ENEL GENERACION PIURA S.A.
J53: SUB TOTAL | L53: 410.57
A55: X | B55: 2023 | C55: OCTUBRE | D55: PRIMERA QUINCENA | E55: 635801.16 | F55: 645979.21 | H55: 2.7236 | I55: 2.7672 | J55: 155771.28 | K55: 158264.91 | L55: 2493.63 | M55: 45233 | N55: CONSIDERA PRECIO REALIZADO DEL MES DE OCTUBRE DE 2023, DE ACUERDO A FACTURA Nº F001- 00000459 REMITIDA POR CNPC PERÚ S.A. A ENEL GENERACION PIURA S.A.
J59: SUB TOTAL | L59: 2493.63
A61: HIDROCARBURO : | C61: GAS PAITA 2
A63: XIII | B63: 2023 | C63: SETIEMBRE | D63: PRIMERA QUINCENA | E63: 75945.12 | F63: 80933.38 | H63: 3.59 | I63: 3.8258 | J63: 16707.93 | K63: 17805.34 | L63: 1097.41 | M63: 45233 | N63: CONSIDERA EL PRECIO REALIZADO SEGÚ FACTURA N°01-1562 A ENERGIGAS SAC. INCLUYE FACTURA N°1569 Y NC N°001-154
J67: SUB TOTAL | L67: 1097.41
A69: HIDROCARBURO : | C69: GAS PLT. MELCHORITA
A71: 88 | B71: 2023 | C71: SETIEMBRE | D71: SEGUNDA QUINCENA | E71: 5397558.3 | F71: 4880230 | H71: 5.415 | I71: 4.896 | J71: 2051072.1 | K71: 1854487.4 | L71: -196584.75 | M71: 45233 | N71: Ajuste que considera cambio de destino de los embarques # 737 de Francia a Holanda y # 738 de Japón a Francia.
A74: 88 | B74: 2023 | C74: OCTUBRE | D74: PRIMERA QUINCENA | E74: 4311923.1 | F74: 4043531.5 | H74: 4.884 | I74: 4.58 | J74: 1638530.8 | K74: 1536542 | L74: -101988.81 | M74: 45233 | N74: Ajuste que considera el cambio de destino del embarque # 739 de España a Reino Unido.
J78: SUB TOTAL | L78: -298573.56
A80: HIDROCARBURO : | C80: LIQUIDO GAS NATURAL
A82: 31-C | B82: 2021 | C82: JULIO | D82: PRIMERA QUINCENA | E82: 111201.63 | F82: 102573.26 | G82: =E82/H82 -> 2206.0007 | H82: 50.4087 | I82: 46.4974 | J82: 44814.26 | K82: 41337.02 | L82: -3477.24 | M82: 45233 | N82: APLICACIÓN DEL ACUERDO DE VALORIZACIÓN DE LOS LGN DEL LOTE 31-C SUSCRITO EL 12.10.2023
A83: 31-C | B83: 2021 | C83: JULIO | D83: SEGUNDA QUINCENA | E83: 104544.09 | F83: 95685.61 | G83: =E83/H83 -> 2145.9997 | H83: 48.7158 | I83: 44.5879 | J83: 41085.83 | K83: 37604.44 | L83: -3481.39 | M83: 45233 | N83: APLICACIÓN DEL ACUERDO DE VALORIZACIÓN DE LOS LGN DEL LOTE 31-C SUSCRITO EL 12.10.2023
A84: 31-C | B84: 2021 | C84: AGOSTO | D84: PRIMERA QUINCENA | E84: 94664.3 | F84: 86618.28 | G84: =E84/H84 -> 1979.0005 | H84: 47.8344 | I84: 43.7687 | J84: 36540.42 | K84: 33434.66 | L84: -3105.76 | M84: 45233 | N84: APLICACIÓN DEL ACUERDO DE VALORIZACIÓN DE LOS LGN DEL LOTE 31-C SUSCRITO EL 12.10.2023
A85: 31-C | B85: 2021 | C85: AGOSTO | D85: SEGUNDA QUINCENA | E85: 96722.09 | F85: 88418.38 | G85: =E85/H85 -> 2094.9983 | H85: 46.1681 | I85: 42.2045 | J85: 36657.67 | K85: 33510.57 | L85: -3147.1 | M85: 45233 | N85: APLICACIÓN DEL ACUERDO DE VALORIZACIÓN DE LOS LGN DEL LOTE 31-C SUSCRITO EL 12.10.2023
A86: 31-C | B86: 2021 | C86: SETIEMBRE | D86: PRIMERA QUINCENA | E86: 87956.11 | F86: 81133.94 | G86: =E86/H86 -> 1796.9994 | H86: 48.9461 | I86: 45.1497 | J86: 34390.84 | K86: 31723.37 | L86: -2667.47 | M86: 45233 | N86: APLICACIÓN DEL ACUERDO DE VALORIZACIÓN DE LOS LGN DEL LOTE 31-C SUSCRITO EL 12.10.2023
A87: 31-C | B87: 2021 | C87: SETIEMBRE | D87: SEGUNDA QUINCENA | E87: 102122.85 | F87: 94884.62 | G87: =E87/H87 -> 1841.9996 | H87: 55.4413 | I87: 51.5117 | J87: 41257.63 | K87: 38333.39 | L87: -2924.24 | M87: 45233 | N87: APLICACIÓN DEL ACUERDO DE VALORIZACIÓN DE LOS LGN DEL LOTE 31-C SUSCRITO EL 12.10.2023
A88: 31-C | B88: 2021 | C88: OCTUBRE | D88: PRIMERA QUINCENA | E88: 100169 | F88: 93212.41 | G88: =E88/H88 -> 1727.0011 | H88: 58.0017 | I88: 53.9736 | J88: 42772.16 | K88: 39801.7 | L88: -2970.46 | M88: 45233 | N88: APLICACIÓN DEL ACUERDO DE VALORIZACIÓN DE LOS LGN DEL LOTE 31-C SUSCRITO EL 12.10.2023
A89: 31-C | B89: 2021 | C89: OCTUBRE | D89: SEGUNDA QUINCENA | E89: 111006.61 | F89: 103461.81 | G89: =E89/H89 -> 1963.9992 | H89: 56.5207 | I89: 52.6791 | J89: 48398.88 | K89: 45109.35 | L89: -3289.53 | M89: 45233 | N89: APLICACIÓN DEL ACUERDO DE VALORIZACIÓN DE LOS LGN DEL LOTE 31-C SUSCRITO EL 12.10.2023
A90: 31-C | B90: 2021 | C90: DICIEMBRE | D90: PRIMERA QUINCENA | E90: 60324.24 | F90: 55620.24 | G90: =E90/H90 -> 1215.9988 | H90: 49.6088 | I90: 45.7403 | J90: 23767.75 | K90: 21914.37 | L90: -1853.38 | M90: 45233 | N90: APLICACIÓN DEL ACUERDO DE VALORIZACIÓN DE LOS LGN DEL LOTE 31-C SUSCRITO EL 12.10.2023
A91: 31-C | B91: 2021 | C91: DICIEMBRE | D91: SEGUNDA QUINCENA | E91: 59208.78 | F91: 52626.06 | G91: =E91/H91 -> 1304.0002 | H91: 45.4055 | I91: 40.3574 | J91: 23742.72 | K91: 21103.05 | L91: -2639.67 | M91: 45233 | N91: APLICACIÓN DEL ACUERDO DE VALORIZACIÓN DE LOS LGN DEL LOTE 31-C SUSCRITO EL 12.10.2023
A92: 31-C | B92: 2022 | C92: ENERO | D92: PRIMERA QUINCENA | E92: 79057.23 | F92: 70365.05 | G92: =E92/H92 -> 1640.9984 | H92: 48.1763 | I92: 42.8794 | J92: 34073.67 | K92: 30327.34 | L92: -3746.33 | M92: 45233 | N92: APLICACIÓN DEL ACUERDO DE VALORIZACIÓN DE LOS LGN DEL LOTE 31-C SUSCRITO EL 12.10.2023
A93: 31-C | B93: 2022 | C93: ENERO | D93: SEGUNDA QUINCENA | E93: 247402.75 | F93: 227016.2 | G93: =E93/H93 -> 4463.997 | H93: 55.4218 | I93: 50.8549 | J93: 112568.25 | K93: 103292.37 | L93: -9275.88 | M93: 45233 | N93: APLICACIÓN DEL ACUERDO DE VALORIZACIÓN DE LOS LGN DEL LOTE 31-C SUSCRITO EL 12.10.2023
...

Sheet Ene-2
A1: Período de Cálculo: | E1: 43101 | U1: Días en el mes | W1: =DATE(YEAR(E1),MONTH(E1)+1,1)-DATE(YEAR(E1),MONTH(E1),1) -> 31
A2: PERUPETRO S.A.
A3: DETERMINACION DEL CANON, SOBRECANON y PARTICIPACION (US$)
A4: ="Correspondiente a "&TEXT(E1,"MMMMMMM YYYY") -> Correspondiente a Enero 2018
A5: ="Tipo de Cambio= "&TEXT(F1,"0.000") -> Tipo de Cambio= 0.000
A7: Localidad | C7: Modalidad de Contrato | D7: Calculo del Canon | F7: Volumen Producción / Venta | I7: Canasta o Valor Venta (US$/Unidad) | K7: Deducción de Gastos para determinación de valor de producción en Punto de Fiscalización (US$) | O7: Valor de la Producción (US$) | P7: Canon y Sobrecanon / Participación (US$) | U7: Resumen por Petróleo y Condensados | AA7: Resumen por Gas Natural | AG7: Control
A8: - Lote | D8: Período | E8: Fórmula | F8: Unidades | G8: 1ra. Q | H8: 2da. Q / Mes | I8: 1ra. Q | J8: 2da. Q / Mes | K8: Flete Marítimo | L8: Comercialización | M8: Oleoducto | N8: Fiscalización | P8: Total | Q8: Localidad 1 | S8: Localidad 2 | U8: Producción / Venta | X8: Valor Prod | Y8: Valor Canon | AA8: Producción / Venta | AD8: Valor Prod | AE8: Valor Canon | AG8: Total
A9: Piura / Tumbes | Q9: Piura | S9: Tumbes | U9: Bls/Mes | V9: V P (US$) | W9: Bls/Día | X9: US$/Bl | Y9: US$/Bl | Z9: US$ | AA9: MM BTU/Mes | AB9: V P (US$) | AC9: MM BTU/Día | AD9: US$/MM BTU | AE9: US$/MM BTU | AF9: US$ | AG9: Canon
A10: - | B10: I | C10: Servicios | D10: Mes | E10: F1 | F10: Bls | H10: 24582 | J10: 67.0812 | N10: 683.58 | O10: =ROUND(G10*I10,2)+ROUND(H10*J10,2)-K10-L10-M10-N10 -> 1648306.5 | P10: =ROUND(18.75%*O10,2) -> 309057.47 | Q10: =ROUND($O10*R10,2) -> 247245.97 | R10: 0.15 | S10: =ROUND($O10*T10,2) -> 61811.49 | T10: 0.0375 | U10: =IF($F10&"/Día"=W$9,SUM($G10:$H10),"") -> 24582 | V10: =IF(U10<>"",$O10,"") -> 1648306.5 | W10: =IF($F10&"/Día"=W$9,ROUND(U10/$W$1,1),"") -> 793 | X10: =IF(U10=0,0,IF($F10&"/Día"=W$9,ROUND(V10/U10,4),"")) -> 67.0534 | Y10: =IF(U10=0,0,IF($F10&"/Día"=W$9,ROUND(Z10/U10,4),"")) -> 12.5725 | Z10: =IF(U10<>"",$P10,"") -> 309057.47 | AA10: =IF($F10&"/Día"=AC$9,SUM($G10:$H10),"") | AB10: =IF(AA10<>"",$O10,"") | AC10: =IF($F10&"/Día"=AC$9,ROUND(AA10/$W$1,1),"") | AD10: =IF(AA10=0,0,IF($F10&"/Día"=AC$9,ROUND(AB10/AA10,4),"")) | AE10: =IF(AA10=0,0,IF($F10&"/Día"=AC$9,ROUND(AF10/AA10,4),"")) | AF10: =IF(AA10<>"",$P10,"")
A11: - | B11: I GAS | C11: Servicios | D11: Mes | E11: F1 | F11: MM BTU | H11: 253218.78 | J11: 2.9822 | N11: 1914.05 | O11: =ROUND(G11*I11,2)+ROUND(H11*J11,2)-K11-L11-M11-N11 -> 753235 | P11: =ROUND(18.75%*O11,2) -> 141231.56 | Q11: =ROUND($O11*R11,2) -> 112985.25 | R11: 0.15 | S11: =ROUND($O11*T11,2) -> 28246.31 | T11: 0.0375 | U11: =IF($F11&"/Día"=W$9,SUM($G11:$H11),"") | V11: =IF(U11<>"",$O11,"") | W11: =IF($F11&"/Día"=W$9,ROUND(U11/$W$1,1),"") | X11: =IF(U11=0,0,IF($F11&"/Día"=W$9,ROUND(V11/U11,4),"")) | Y11: =IF(U11=0,0,IF($F11&"/Día"=W$9,ROUND(Z11/U11,4),"")) | Z11: =IF(U11<>"",$P11,"") | AA11: =IF($F11&"/Día"=AC$9,SUM($G11:$H11),"") -> 253218.78 | AB11: =IF(AA11<>"",$O11,"") -> 753235 | AC11: =IF($F11&"/Día"=AC$9,ROUND(AA11/$W$1,1),"") -> 8168.3 | AD11: =IF(AA11=0,0,IF($F11&"/Día"=AC$9,ROUND(AB11/AA11,4),"")) -> 2.9746 | AE11: =IF(AA11=0,0,IF($F11&"/Día"=AC$9,ROUND(AF11/AA11,4),"")) -> 0.5577 | AF11: =IF(AA11<>"",$P11,"") -> 141231.56
A12: - | B12: II | C12: Licencia | D12: Quincena | E12: F2 | F12: Bls | G12: 4562 | H12: 4721 | I12: 64.1613 | J12: 65.1575 | N12: 1764.83 | O12: =ROUND(G12*I12,2)+ROUND(H12*J12,2)-K12-L12-M12-N12 -> 598547.58 | P12: =ROUND(18.75%*O12,2) -> 112227.67 | Q12: =ROUND($O12*R12,2) -> 89782.14 | R12: 0.15 | S12: =ROUND($O12*T12,2) -> 22445.53 | T12: 0.0375 | U12: =IF($F12&"/Día"=W$9,SUM($G12:$H12),"") -> 9283 | V12: =IF(U12<>"",$O12,"") -> 598547.58 | W12: =IF($F12&"/Día"=W$9,ROUND(U12/$W$1,1),"") -> 299.5 | X12: =IF(U12=0,0,IF($F12&"/Día"=W$9,ROUND(V12/U12,4),"")) -> 64.4778 | Y12: =IF(U12=0,0,IF($F12&"/Día"=W$9,ROUND(Z12/U12,4),"")) -> 12.0896 | Z12: =IF(U12<>"",$P12,"") -> 112227.67 | AA12: =IF($F12&"/Día"=AC$9,SUM($G12:$H12),"") | AB12: =IF(AA12<>"",$O12,"") | AC12: =IF($F12&"/Día"=AC$9,ROUND(AA12/$W$1,1),"") | AD12: =IF(AA12=0,0,IF($F12&"/Día"=AC$9,ROUND(AB12/AA12,4),"")) | AE12: =IF(AA12=0,0,IF($F12&"/Día"=AC$9,ROUND(AF12/AA12,4),"")) | AF12: =IF(AA12<>"",$P12,"")
A13: - | B13: II-GAS | C13: Servicios | D13: Mes | E13: F1 | F13: MM BTU | G13: 40281.697 | H13: 44653.33 | I13: 2.55 | J13: 2.55 | N13: 1884.53 | O13: =ROUND(G13*I13,2)+ROUND(H13*J13,2)-K13-L13-M13-N13 -> 214699.79 | P13: =ROUND(18.75%*O13,2) -> 40256.21 | Q13: =ROUND($P13*R13/(R13+T13),2) -> 32204.97 | R13: 0.15 | S13: =P13-Q13 -> 8051.24 | T13: 0.0375 | U13: =IF($F13&"/Día"=W$9,SUM($G13:$H13),"") | V13: =IF(U13<>"",$O13,"") | W13: =IF($F13&"/Día"=W$9,ROUND(U13/$W$1,1),"") | X13: =IF(U13=0,0,IF($F13&"/Día"=W$9,ROUND(V13/U13,4),"")) | Y13: =IF(U13=0,0,IF($F13&"/Día"=W$9,ROUND(Z13/U13,4),"")) | Z13: =IF(U13<>"",$P13,"") | AA13: =IF($F13&"/Día"=AC$9,SUM($G13:$H13),"") -> 84935.027 | AB13: =IF(AA13<>"",$O13,"") -> 214699.79 | AC13: =IF($F13&"/Día"=AC$9,ROUND(AA13/$W$1,1),"") -> 2739.8 | AD13: =IF(AA13=0,0,IF($F13&"/Día"=AC$9,ROUND(AB13/AA13,4),"")) -> 2.5278 | AE13: =IF(AA13=0,0,IF($F13&"/Día"=AC$9,ROUND(AF13/AA13,4),"")) -> 0.474 | AF13: =IF(AA13<>"",$P13,"") -> 40256.21
A14: - | B14: III | C14: Licencia | D14: Quincena | E14: F2 | F14: Bls | G14: 11836 | H14: 12495 | I14: 66.7972 | J14: 67.3179 | N14: 1257.31 | O14: =ROUND(G14*I14,2)+ROUND(H14*J14,2)-K14-L14-M14-N14 -> 1630491.5 | P14: =ROUND(18.75%*O14,2) -> 305717.16 | Q14: =ROUND($O14*R14,2) -> 244573.73 | R14: 0.15 | S14: =ROUND($O14*T14,2) -> 61143.43 | T14: 0.0375 | U14: =IF($F14&"/Día"=W$9,SUM($G14:$H14),"") -> 24331 | V14: =IF(U14<>"",$O14,"") -> 1630491.5 | W14: =IF($F14&"/Día"=W$9,ROUND(U14/$W$1,1),"") -> 784.9 | X14: =IF(U14=0,0,IF($F14&"/Día"=W$9,ROUND(V14/U14,4),"")) -> 67.0129 | Y14: =IF(U14=0,0,IF($F14&"/Día"=W$9,ROUND(Z14/U14,4),"")) -> 12.5649 | Z14: =IF(U14<>"",$P14,"") -> 305717.16 | AA14: =IF($F14&"/Día"=AC$9,SUM($G14:$H14),"") | AB14: =IF(AA14<>"",$O14,"") | AC14: =IF($F14&"/Día"=AC$9,ROUND(AA14/$W$1,1),"") | AD14: =IF(AA14=0,0,IF($F14&"/Día"=AC$9,ROUND(AB14/AA14,4),"")) | AE14: =IF(AA14=0,0,IF($F14&"/Día"=AC$9,ROUND(AF14/AA14,4),"")) | AF14: =IF(AA14<>"",$P14,"")
A15: - | B15: IV | C15: Licencia | D15: Quincena | E15: F2 | F15: Bls | G15: 17378 | H15: 20845 | I15: 66.7972 | J15: 67.3179 | N15: 3247.24 | O15: =ROUND(G15*I15,2)+ROUND(H15*J15,2)-K15-L15-M15-N15 -> 2560796.1 | P15: =ROUND(18.75%*O15,2) -> 480149.27 | Q15: =ROUND($O15*R15,2) -> 384119.42 | R15: 0.15 | S15: =ROUND($O15*T15,2) -> 96029.85 | T15: 0.0375 | U15: =IF($F15&"/Día"=W$9,SUM($G15:$H15),"") -> 38223 | V15: =IF(U15<>"",$O15,"") -> 2560796.1 | W15: =IF($F15&"/Día"=W$9,ROUND(U15/$W$1,1),"") -> 1233 | X15: =IF(U15=0,0,IF($F15&"/Día"=W$9,ROUND(V15/U15,4),"")) -> 66.9962 | Y15: =IF(U15=0,0,IF($F15&"/Día"=W$9,ROUND(Z15/U15,4),"")) -> 12.5618 | Z15: =IF(U15<>"",$P15,"") -> 480149.27 | AA15: =IF($F15&"/Día"=AC$9,SUM($G15:$H15),"") | AB15: =IF(AA15<>"",$O15,"") | AC15: =IF($F15&"/Día"=AC$9,ROUND(AA15/$W$1,1),"") | AD15: =IF(AA15=0,0,IF($F15&"/Día"=AC$9,ROUND(AB15/AA15,4),"")) | AE15: =IF(AA15=0,0,IF($F15&"/Día"=AC$9,ROUND(AF15/AA15,4),"")) | AF15: =IF(AA15<>"",$P15,"")
A16: - | B16: V | C16: Servicios | D16: Mes | E16: F1 | F16: Bls | H16: 2532 | J16: 67.0812 | N16: 1487.58 | O16: =ROUND(G16*I16,2)+ROUND(H16*J16,2)-K16-L16-M16-N16 -> 168362.02 | P16: =ROUND(18.75%*O16,2) -> 31567.88 | Q16: =ROUND($O16*R16,2) -> 25254.3 | R16: 0.15 | S16: =ROUND($O16*T16,2) -> 6313.58 | T16: 0.0375 | U16: =IF($F16&"/Día"=W$9,SUM($G16:$H16),"") -> 2532 | V16: =IF(U16<>"",$O16,"") -> 168362.02 | W16: =IF($F16&"/Día"=W$9,ROUND(U16/$W$1,1),"") -> 81.7 | X16: =IF(U16=0,0,IF($F16&"/Día"=W$9,ROUND(V16/U16,4),"")) -> 66.4937 | Y16: =IF(U16=0,0,IF($F16&"/Día"=W$9,ROUND(Z16/U16,4),"")) -> 12.4676 | Z16: =IF(U16<>"",$P16,"") -> 31567.88 | AA16: =IF($F16&"/Día"=AC$9,SUM($G16:$H16),"") | AB16: =IF(AA16<>"",$O16,"") | AC16: =IF($F16&"/Día"=AC$9,ROUND(AA16/$W$1,1),"") | AD16: =IF(AA16=0,0,IF($F16&"/Día"=AC$9,ROUND(AB16/AA16,4),"")) | AE16: =IF(AA16=0,0,IF($F16&"/Día"=AC$9,ROUND(AF16/AA16,4),"")) | AF16: =IF(AA16<>"",$P16,"")
A17: - | B17: VII/VI | C17: Licencia | D17: Quincena | E17: F2 | F17: Bls | G17: 46815 | H17: 59830 | I17: 66.2472 | J17: 66.7679 | N17: 2221.88 | O17: =ROUND(G17*I17,2)+ROUND(H17*J17,2)-K17-L17-M17-N17 -> 7093864.2 | P17: =ROUND(18.75%*O17,2) -> 1330099.6 | Q17: =ROUND($O17*R17,2) -> 1064079.6 | R17: 0.15 | S17: =ROUND($O17*T17,2) -> 266019.91 | T17: 0.0375 | U17: =IF($F17&"/Día"=W$9,SUM($G17:$H17),"") -> 106645 | V17: =IF(U17<>"",$O17,"") -> 7093864.2 | W17: =IF($F17&"/Día"=W$9,ROUND(U17/$W$1,1),"") -> 3440.2 | X17: =IF(U17=0,0,IF($F17&"/Día"=W$9,ROUND(V17/U17,4),"")) -> 66.5185 | Y17: =IF(U17=0,0,IF($F17&"/Día"=W$9,ROUND(Z17/U17,4),"")) -> 12.4722 | Z17: =IF(U17<>"",$P17,"") -> 1330099.6 | AA17: =IF($F17&"/Día"=AC$9,SUM($G17:$H17),"") | AB17: =IF(AA17<>"",$O17,"") | AC17: =IF($F17&"/Día"=AC$9,ROUND(AA17/$W$1,1),"") | AD17: =IF(AA17=0,0,IF($F17&"/Día"=AC$9,ROUND(AB17/AA17,4),"")) | AE17: =IF(AA17=0,0,IF($F17&"/Día"=AC$9,ROUND(AF17/AA17,4),"")) | AF17: =IF(AA17<>"",$P17,"")
A18: - | B18: VII | C18: Servicios | D18: Mes | E18: F1 | F18: Bls | O18: =ROUND(G18*I18,2)+ROUND(H18*J18,2)-K18-L18-M18-N18 -> 0 | P18: =ROUND(18.75%*O18,2) -> 0 | Q18: =ROUND($O18*R18,2) -> 0 | R18: 0.15 | S18: =ROUND($O18*T18,2) -> 0 | T18: 0.0375 | U18: =IF($F18&"/Día"=W$9,SUM($G18:$H18),"") -> 0 | V18: =IF(U18<>"",$O18,"") -> 0 | W18: =IF($F18&"/Día"=W$9,ROUND(U18/$W$1,1),"") -> 0 | X18: =IF(U18=0,0,IF($F18&"/Día"=W$9,ROUND(V18/U18,4),"")) -> 0 | Y18: =IF(U18=0,0,IF($F18&"/Día"=W$9,ROUND(Z18/U18,4),"")) -> 0 | Z18: =IF(U18<>"",$P18,"") -> 0 | AA18: =IF($F18&"/Día"=AC$9,SUM($G18:$H18),"") | AB18: =IF(AA18<>"",$O18,"") | AC18: =IF($F18&"/Día"=AC$9,ROUND(AA18/$W$1,1),"") | AD18: =IF(AA18=0,0,IF($F18&"/Día"=AC$9,ROUND(AB18/AA18,4),"")) | AE18: =IF(AA18=0,0,IF($F18&"/Día"=AC$9,ROUND(AF18/AA18,4),"")) | AF18: =IF(AA18<>"",$P18,"")
A19: - | B19: VII/VI-GAS | C19: Licencia | D19: Quincena | E19: F2 | F19: MM BTU | G19: 58474.37 | H19: 64682.42 | I19: 2.1708 | J19: 2.1708 | N19: 2121.65 | O19: =ROUND(G19*I19,2)+ROUND(H19*J19,2)-K19-L19-M19-N19 -> 265227.11 | P19: =ROUND(18.75%*O19,2) -> 49730.08 | Q19: =ROUND($O19*R19,2) -> 39784.07 | R19: 0.15 | S19: =ROUND($O19*T19,2) -> 9946.02 | T19: 0.0375 | U19: =IF($F19&"/Día"=W$9,SUM($G19:$H19),"") | V19: =IF(U19<>"",$O19,"") | W19: =IF($F19&"/Día"=W$9,ROUND(U19/$W$1,1),"") | X19: =IF(U19=0,0,IF($F19&"/Día"=W$9,ROUND(V19/U19,4),"")) | Y19: =IF(U19=0,0,IF($F19&"/Día"=W$9,ROUND(Z19/U19,4),"")) | Z19: =IF(U19<>"",$P19,"") | AA19: =IF($F19&"/Día"=AC$9,SUM($G19:$H19),"") -> 123156.79 | AB19: =IF(AA19<>"",$O19,"") -> 265227.11 | AC19: =IF($F19&"/Día"=AC$9,ROUND(AA19/$W$1,1),"") -> 3972.8 | AD19: =IF(AA19=0,0,IF($F19&"/Día"=AC$9,ROUND(AB19/AA19,4),"")) -> 2.1536 | AE19: =IF(AA19=0,0,IF($F19&"/Día"=AC$9,ROUND(AF19/AA19,4),"")) -> 0.4038 | AF19: =IF(AA19<>"",$P19,"") -> 49730.08
A20: - | B20: IX | C20: Licencia | D20: Quincena | E20: F2 | F20: Bls | G20: 2083 | H20: 3260 | I20: 66.7972 | J20: 67.3179 | N20: 737.78 | O20: =ROUND(G20*I20,2)+ROUND(H20*J20,2)-K20-L20-M20-N20 -> 357857.14 | P20: =ROUND(18.75%*O20,2) -> 67098.21 | Q20: =ROUND($O20*R20,2) -> 53678.57 | R20: 0.15 | S20: =ROUND($O20*T20,2) -> 13419.64 | T20: 0.0375 | U20: =IF($F20&"/Día"=W$9,SUM($G20:$H20),"") -> 5343 | V20: =IF(U20<>"",$O20,"") -> 357857.14 | W20: =IF($F20&"/Día"=W$9,ROUND(U20/$W$1,1),"") -> 172.4 | X20: =IF(U20=0,0,IF($F20&"/Día"=W$9,ROUND(V20/U20,4),"")) -> 66.9768 | Y20: =IF(U20=0,0,IF($F20&"/Día"=W$9,ROUND(Z20/U20,4),"")) -> 12.5582 | Z20: =IF(U20<>"",$P20,"") -> 67098.21 | AA20: =IF($F20&"/Día"=AC$9,SUM($G20:$H20),"") | AB20: =IF(AA20<>"",$O20,"") | AC20: =IF($F20&"/Día"=AC$9,ROUND(AA20/$W$1,1),"") | AD20: =IF(AA20=0,0,IF($F20&"/Día"=AC$9,ROUND(AB20/AA20,4),"")) | AE20: =IF(AA20=0,0,IF($F20&"/Día"=AC$9,ROUND(AF20/AA20,4),"")) | AF20: =IF(AA20<>"",$P20,"")
A21: - | B21: X | C21: Licencia | D21: Quincena | E21: F2 | F21: Bls | G21: 195037 | H21: 205982 | I21: 66.7972 | J21: 67.3179 | N21: 4334.18 | O21: =ROUND(G21*I21,2)+ROUND(H21*J21,2)-K21-L21-M21-N21 -> 26889867 | P21: =ROUND(18.75%*O21,2) -> 5041850.1 | Q21: =ROUND($O21*R21,2) -> 4033480 | R21: 0.15 | S21: =ROUND($O21*T21,2) -> 1008370 | T21: 0.0375 | U21: =IF($F21&"/Día"=W$9,SUM($G21:$H21),"") -> 401019 | V21: =IF(U21<>"",$O21,"") -> 26889867 | W21: =IF($F21&"/Día"=W$9,ROUND(U21/$W$1,1),"") -> 12936.1 | X21: =IF(U21=0,0,IF($F21&"/Día"=W$9,ROUND(V21/U21,4),"")) -> 67.0538 | Y21: =IF(U21=0,0,IF($F21&"/Día"=W$9,ROUND(Z21/U21,4),"")) -> 12.5726 | Z21: =IF(U21<>"",$P21,"") -> 5041850.1 | AA21: =IF($F21&"/Día"=AC$9,SUM($G21:$H21),"") | AB21: =IF(AA21<>"",$O21,"") | AC21: =IF($F21&"/Día"=AC$9,ROUND(AA21/$W$1,1),"") | AD21: =IF(AA21=0,0,IF($F21&"/Día"=AC$9,ROUND(AB21/AA21,4),"")) | AE21: =IF(AA21=0,0,IF($F21&"/Día"=AC$9,ROUND(AF21/AA21,4),"")) | AF21: =IF(AA21<>"",$P21,"")
A22: - | B22: X-GAS | C22: Licencia | D22: Mes | E22: F2 | F22: MM BTU | G22: 251980.16 | H22: 254840.6 | I22: 1.8012 | J22: 1.8012 | N22: 2235.16 | O22: =ROUND(G22*I22,2)+ROUND(H22*J22,2)-K22-L22-M22-N22 -> 910650.39 | P22: =ROUND(18.75%*O22,2) -> 170746.95 | Q22: =ROUND($O22*R22,2) -> 136597.56 | R22: 0.15 | S22: =ROUND($O22*T22,2) -> 34149.39 | T22: 0.0375 | U22: =IF($F22&"/Día"=W$9,SUM($G22:$H22),"") | V22: =IF(U22<>"",$O22,"") | W22: =IF($F22&"/Día"=W$9,ROUND(U22/$W$1,1),"") | X22: =IF(U22=0,0,IF($F22&"/Día"=W$9,ROUND(V22/U22,4),"")) | Y22: =IF(U22=0,0,IF($F22&"/Día"=W$9,ROUND(Z22/U22,4),"")) | Z22: =IF(U22<>"",$P22,"") | AA22: =IF($F22&"/Día"=AC$9,SUM($G22:$H22),"") -> 506820.76 | AB22: =IF(AA22<>"",$O22,"") -> 910650.39 | AC22: =IF($F22&"/Día"=AC$9,ROUND(AA22/$W$1,1),"") -> 16349.1 | AD22: =IF(AA22=0,0,IF($F22&"/Día"=AC$9,ROUND(AB22/AA22,4),"")) -> 1.7968 | AE22: =IF(AA22=0,0,IF($F22&"/Día"=AC$9,ROUND(AF22/AA22,4),"")) -> 0.3369 | AF22: =IF(AA22<>"",$P22,"") -> 170746.95
A23: - | B23: XIV | C23: Licencia | D23: Mes | E23: F2 | F23: Bls | O23: =ROUND(G23*I23,2)+ROUND(H23*J23,2)-K23-L23-M23-N23 -> 0 | P23: =ROUND(18.75%*O23,2) -> 0 | Q23: =ROUND($O23*R23,2) -> 0 | R23: 0.15 | S23: =ROUND($O23*T23,2) -> 0 | T23: 0.0375 | U23: =IF($F23&"/Día"=W$9,SUM($G23:$H23),"") -> 0 | V23: =IF(U23<>"",$O23,"") -> 0 | W23: =IF($F23&"/Día"=W$9,ROUND(U23/$W$1,1),"") -> 0 | X23: =IF(U23=0,0,IF($F23&"/Día"=W$9,ROUND(V23/U23,4),"")) -> 0 | Y23: =IF(U23=0,0,IF($F23&"/Día"=W$9,ROUND(Z23/U23,4),"")) -> 0 | Z23: =IF(U23<>"",$P23,"") -> 0 | AA23: =IF($F23&"/Día"=AC$9,SUM($G23:$H23),"") | AB23: =IF(AA23<>"",$O23,"") | AC23: =IF($F23&"/Día"=AC$9,ROUND(AA23/$W$1,1),"") | AD23: =IF(AA23=0,0,IF($F23&"/Día"=AC$9,ROUND(AB23/AA23,4),"")) | AE23: =IF(AA23=0,0,IF($F23&"/Día"=AC$9,ROUND(AF23/AA23,4),"")) | AF23: =IF(AA23<>"",$P23,"")
A24: - | B24: XV | C24: Licencia | D24: Quincena | E24: F2 | F24: Bls | G24: 564 | H24: 535 | I24: 66.5365 | J24: 67.7014 | N24: 802.26 | O24: =ROUND(G24*I24,2)+ROUND(H24*J24,2)-K24-L24-M24-N24 -> 72944.58 | P24: =ROUND(18.75%*O24,2) -> 13677.11 | Q24: =ROUND($O24*R24,2) -> 10941.69 | R24: 0.15 | S24: =ROUND($O24*T24,2) -> 2735.42 | T24: 0.0375 | U24: =IF($F24&"/Día"=W$9,SUM($G24:$H24),"") -> 1099 | V24: =IF(U24<>"",$O24,"") -> 72944.58 | W24: =IF($F24&"/Día"=W$9,ROUND(U24/$W$1,1),"") -> 35.5 | X24: =IF(U24=0,0,IF($F24&"/Día"=W$9,ROUND(V24/U24,4),"")) -> 66.3736 | Y24: =IF(U24=0,0,IF($F24&"/Día"=W$9,ROUND(Z24/U24,4),"")) -> 12.4451 | Z24: =IF(U24<>"",$P24,"") -> 13677.11 | AA24: =IF($F24&"/Día"=AC$9,SUM($G24:$H24),"") | AB24: =IF(AA24<>"",$O24,"") | AC24: =IF($F24&"/Día"=AC$9,ROUND(AA24/$W$1,1),"") | AD24: =IF(AA24=0,0,IF($F24&"/Día"=AC$9,ROUND(AB24/AA24,4),"")) | AE24: =IF(AA24=0,0,IF($F24&"/Día"=AC$9,ROUND(AF24/AA24,4),"")) | AF24: =IF(AA24<>"",$P24,"")
A25: - | B25: XIII Crudo | C25: Licencia | D25: Quincena | E25: F2 | F25: Bls | G25: 28828 | H25: 36208 | I25: 66.7972 | J25: 67.3179 | N25: 1530.48 | O25: =ROUND(G25*I25,2)+ROUND(H25*J25,2)-K25-L25-M25-N25 -> 4361545.7 | P25: =ROUND(18.75%*O25,2) -> 817789.82 | Q25: =ROUND($O25*R25,2) -> 654231.86 | R25: 0.15 | S25: =ROUND($O25*T25,2) -> 163557.96 | T25: 0.0375 | U25: =IF($F25&"/Día"=W$9,SUM($G25:$H25),"") -> 65036 | V25: =IF(U25<>"",$O25,"") -> 4361545.7 | W25: =IF($F25&"/Día"=W$9,ROUND(U25/$W$1,1),"") -> 2097.9 | X25: =IF(U25=0,0,IF($F25&"/Día"=W$9,ROUND(V25/U25,4),"")) -> 67.0636 | Y25: =IF(U25=0,0,IF($F25&"/Día"=W$9,ROUND(Z25/U25,4),"")) -> 12.5744 | Z25: =IF(U25<>"",$P25,"") -> 817789.82 | AA25: =IF($F25&"/Día"=AC$9,SUM($G25:$H25),"") | AB25: =IF(AA25<>"",$O25,"") | AC25: =IF($F25&"/Día"=AC$9,ROUND(AA25/$W$1,1),"") | AD25: =IF(AA25=0,0,IF($F25&"/Día"=AC$9,ROUND(AB25/AA25,4),"")) | AE25: =IF(AA25=0,0,IF($F25&"/Día"=AC$9,ROUND(AF25/AA25,4),"")) | AF25: =IF(AA25<>"",$P25,"")
A26: - | B26: XIII COND | C26: Licencia | D26: Quincena | E26: F2 | F26: Bls | O26: =ROUND(G26*I26,2)+ROUND(H26*J26,2)-K26-L26-M26-N26 -> 0 | P26: =ROUND(18.75%*O26,2) -> 0 | Q26: =ROUND($O26*R26,2) -> 0 | R26: 0.15 | S26: =ROUND($O26*T26,2) -> 0 | T26: 0.0375 | U26: =IF($F26&"/Día"=W$9,SUM($G26:$H26),"") -> 0 | V26: =IF(U26<>"",$O26,"") -> 0 | W26: =IF($F26&"/Día"=W$9,ROUND(U26/$W$1,1),"") -> 0 | X26: =IF(U26=0,0,IF($F26&"/Día"=W$9,ROUND(V26/U26,4),"")) -> 0 | Y26: =IF(U26=0,0,IF($F26&"/Día"=W$9,ROUND(Z26/U26,4),"")) -> 0 | Z26: =IF(U26<>"",$P26,"") -> 0 | AA26: =IF($F26&"/Día"=AC$9,SUM($G26:$H26),"") | AB26: =IF(AA26<>"",$O26,"") | AC26: =IF($F26&"/Día"=AC$9,ROUND(AA26/$W$1,1),"") | AD26: =IF(AA26=0,0,IF($F26&"/Día"=AC$9,ROUND(AB26/AA26,4),"")) | AE26: =IF(AA26=0,0,IF($F26&"/Día"=AC$9,ROUND(AF26/AA26,4),"")) | AF26: =IF(AA26<>"",$P26,"")
A27: - | B27: XIII Gas | C27: Licencia | D27: Quincena | E27: F2 | F27: MM BTU | G27: =109679.9639+69454.7114 -> 179134.68 | H27: =115352.29+94462.85 -> 209815.14 | I27: 2.4759775 | J27: 2.6336074 | N27: 3163.29 | O27: =ROUND(G27*I27,2)+ROUND(H27*J27,2)-K27-L27-M27-N27 -> 992940.84 | P27: =ROUND(18.75%*O27,2) -> 186176.41 | Q27: =ROUND($O27*R27,2) -> 148941.13 | R27: 0.15 | S27: =ROUND($O27*T27,2) -> 37235.28 | T27: 0.0375 | U27: =IF($F27&"/Día"=W$9,SUM($G27:$H27),"") | V27: =IF(U27<>"",$O27,"") | W27: =IF($F27&"/Día"=W$9,ROUND(U27/$W$1,1),"") | X27: =IF(U27=0,0,IF($F27&"/Día"=W$9,ROUND(V27/U27,4),"")) | Y27: =IF(U27=0,0,IF($F27&"/Día"=W$9,ROUND(Z27/U27,4),"")) | Z27: =IF(U27<>"",$P27,"") | AA27: =IF($F27&"/Día"=AC$9,SUM($G27:$H27),"") -> 388949.82 | AB27: =IF(AA27<>"",$O27,"") -> 992940.84 | AC27: =IF($F27&"/Día"=AC$9,ROUND(AA27/$W$1,1),"") -> 12546.8 | AD27: =IF(AA27=0,0,IF($F27&"/Día"=AC$9,ROUND(AB27/AA27,4),"")) -> 2.5529 | AE27: =IF(AA27=0,0,IF($F27&"/Día"=AC$9,ROUND(AF27/AA27,4),"")) -> 0.4787 | AF27: =IF(AA27<>"",$P27,"") -> 186176.41
A28: - | B28: Z-2B | C28: Servicios | D28: Mes | E28: F1 | F28: Bls | H28: =39453+207131 -> 246584 | J28: 64.0398 | N28: 2445.75 | O28: =ROUND(G28*I28,2)+ROUND(H28*J28,2)-K28-L28-M28-N28 -> 15788744 | P28: =ROUND(18.75%*O28,2) -> 2960389.5 | Q28: =ROUND($O28*R28,2) -> 2368311.6 | R28: 0.15 | S28: =ROUND($O28*T28,2) -> 592077.91 | T28: 0.0375 | U28: =IF($F28&"/Día"=W$9,SUM($G28:$H28),"") -> 246584 | V28: =IF(U28<>"",$O28,"") -> 15788744 | W28: =IF($F28&"/Día"=W$9,ROUND(U28/$W$1,1),"") -> 7954.3 | X28: =IF(U28=0,0,IF($F28&"/Día"=W$9,ROUND(V28/U28,4),"")) -> 64.0299 | Y28: =IF(U28=0,0,IF($F28&"/Día"=W$9,ROUND(Z28/U28,4),"")) -> 12.0056 | Z28: =IF(U28<>"",$P28,"") -> 2960389.5 | AA28: =IF($F28&"/Día"=AC$9,SUM($G28:$H28),"") | AB28: =IF(AA28<>"",$O28,"") | AC28: =IF($F28&"/Día"=AC$9,ROUND(AA28/$W$1,1),"") | AD28: =IF(AA28=0,0,IF($F28&"/Día"=AC$9,ROUND(AB28/AA28,4),"")) | AE28: =IF(AA28=0,0,IF($F28&"/Día"=AC$9,ROUND(AF28/AA28,4),"")) | AF28: =IF(AA28<>"",$P28,"")
A29: - | B29: Z-2B GAS | C29: Servicios | D29: Mes | E29: F1 | F29: MM BTU | H29: =28128.11+153471.87+1104.62 -> 182704.6 | J29: 5.4650451 | N29: 2156.75 | O29: =ROUND(G29*I29,2)+ROUND(H29*J29,2)-K29-L29-M29-N29 -> 996332.12 | P29: =ROUND(18.75%*O29,2) -> 186812.27 | Q29: =ROUND($O29*R29,2) -> 149449.82 | R29: 0.15 | S29: =ROUND($O29*T29,2) -> 37362.45 | T29: 0.0375 | U29: =IF($F29&"/Día"=W$9,SUM($G29:$H29),"") | V29: =IF(U29<>"",$O29,"") | W29: =IF($F29&"/Día"=W$9,ROUND(U29/$W$1,1),"") | X29: =IF(U29=0,0,IF($F29&"/Día"=W$9,ROUND(V29/U29,4),"")) | Y29: =IF(U29=0,0,IF($F29&"/Día"=W$9,ROUND(Z29/U29,4),"")) | Z29: =IF(U29<>"",$P29,"") | AA29: =IF($F29&"/Día"=AC$9,SUM($G29:$H29),"") -> 182704.6 | AB29: =IF(AA29<>"",$O29,"") -> 996332.12 | AC29: =IF($F29&"/Día"=AC$9,ROUND(AA29/$W$1,1),"") -> 5893.7 | AD29: =IF(AA29=0,0,IF($F29&"/Día"=AC$9,ROUND(AB29/AA29,4),"")) -> 5.4532 | AE29: =IF(AA29=0,0,IF($F29&"/Día"=AC$9,ROUND(AF29/AA29,4),"")) -> 1.0225 | AF29: =IF(AA29<>"",$P29,"") -> 186812.27
A30: - | B30: XX | C30: Licencia | D30: Quincena | E30: F2 | F30: Bls | G30: 480 | H30: 368 | I30: 66.7972 | J30: 67.3179 | N30: 471.2 | O30: =ROUND(G30*I30,2)+ROUND(H30*J30,2)-K30-L30-M30-N30 -> 56364.45 | P30: =ROUND(18.75%*O30,2) -> 10568.33 | Q30: =ROUND($O30*R30,2) -> 2113.67 | R30: 0.0375 | S30: =ROUND($O30*T30,2) -> 8454.67 | T30: 0.15 | U30: =IF($F30&"/Día"=W$9,SUM($G30:$H30),"") -> 848 | V30: =IF(U30<>"",$O30,"") -> 56364.45 | W30: =IF($F30&"/Día"=W$9,ROUND(U30/$W$1,1),"") -> 27.4 | X30: =IF(U30=0,0,IF($F30&"/Día"=W$9,ROUND(V30/U30,4),"")) -> 66.4675 | Y30: =IF(U30=0,0,IF($F30&"/Día"=W$9,ROUND(Z30/U30,4),"")) -> 12.4627 | Z30: =IF(U30<>"",$P30,"") -> 10568.33 | AA30: =IF($F30&"/Día"=AC$9,SUM($G30:$H30),"") | AB30: =IF(AA30<>"",$O30,"") | AC30: =IF($F30&"/Día"=AC$9,ROUND(AA30/$W$1,1),"") | AD30: =IF(AA30=0,0,IF($F30&"/Día"=AC$9,ROUND(AB30/AA30,4),"")) | AE30: =IF(AA30=0,0,IF($F30&"/Día"=AC$9,ROUND(AF30/AA30,4),"")) | AF30: =IF(AA30<>"",$P30,"")
A31: - | B31: Z1 Crudo | C31: Licencia | D31: Quincena | E31: F2 | F31: Bls | N31: 1450.98 | O31: =ROUND(G31*I31,2)+ROUND(H31*J31,2)-K31-L31-M31-N31 -> -1450.98 | P31: =ROUND(18.75%*O31,2) -> -272.06 | Q31: =ROUND($O31*R31,2) -> -54.41 | R31: 0.0375 | S31: =ROUND($O31*T31,2) -> -217.65 | T31: 0.15 | U31: =IF($F31&"/Día"=W$9,SUM($G31:$H31),"") -> 0 | V31: =IF(U31<>"",$O31,"") -> -1450.98 | W31: =IF($F31&"/Día"=W$9,ROUND(U31/$W$1,1),"") -> 0 | X31: =IF(U31=0,0,IF($F31&"/Día"=W$9,ROUND(V31/U31,4),"")) -> 0 | Y31: =IF(U31=0,0,IF($F31&"/Día"=W$9,ROUND(Z31/U31,4),"")) -> 0 | Z31: =IF(U31<>"",$P31,"") -> -272.06 | AA31: =IF($F31&"/Día"=AC$9,SUM($G31:$H31),"") | AB31: =IF(AA31<>"",$O31,"") | AC31: =IF($F31&"/Día"=AC$9,ROUND(AA31/$W$1,1),"") | AD31: =IF(AA31=0,0,IF($F31&"/Día"=AC$9,ROUND(AB31/AA31,4),"")) | AE31: =IF(AA31=0,0,IF($F31&"/Día"=AC$9,ROUND(AF31/AA31,4),"")) | AF31: =IF(AA31<>"",$P31,"")
A32: - | B32: Z1 Gas | C32: Licencia | D32: Quincena | E32: F2 | F32: MM BTU | O32: =ROUND(G32*I32,2)+ROUND(H32*J32,2)-K32-L32-M32-N32 -> 0 | P32: =ROUND(18.75%*O32,2) -> 0 | Q32: =ROUND($O32*R32,2) -> 0 | R32: 0.0375 | S32: =ROUND($O32*T32,2) -> 0 | T32: 0.15 | U32: =IF($F32&"/Día"=W$9,SUM($G32:$H32),"") | V32: =IF(U32<>"",$O32,"") | W32: =IF($F32&"/Día"=W$9,ROUND(U32/$W$1,1),"") | X32: =IF(U32=0,0,IF($F32&"/Día"=W$9,ROUND(V32/U32,4),"")) | Y32: =IF(U32=0,0,IF($F32&"/Día"=W$9,ROUND(Z32/U32,4),"")) | Z32: =IF(U32<>"",$P32,"") | AA32: =IF($F32&"/Día"=AC$9,SUM($G32:$H32),"") -> 0 | AB32: =IF(AA32<>"",$O32,"") -> 0 | AC32: =IF($F32&"/Día"=AC$9,ROUND(AA32/$W$1,1),"") -> 0 | AD32: =IF(AA32=0,0,IF($F32&"/Día"=AC$9,ROUND(AB32/AA32,4),"")) -> 0 | AE32: =IF(AA32=0,0,IF($F32&"/Día"=AC$9,ROUND(AF32/AA32,4),"")) -> 0 | AF32: =IF(AA32<>"",$P32,"") -> 0
A33: - | B33: Z-2B - LGN | C33: Servicios | D33: Mes | E33: F1 | F33: Bls | H33: =5522+28988 -> 34510 | J33: 59.0561 | N33: 2349.32 | O33: =ROUND(G33*I33,2)+ROUND(H33*J33,2)-K33-L33-M33-N33 -> 2035676.7 | P33: =ROUND(18.75%*O33,2) -> 381689.38 | Q33: =ROUND($O33*R33,2) -> 305351.5 | R33: 0.15 | S33: =ROUND($O33*T33,2) -> 76337.88 | T33: 0.0375 | U33: =IF($F33&"/Día"=W$9,SUM($G33:$H33),"") -> 34510 | V33: =IF(U33<>"",$O33,"") -> 2035676.7 | W33: =IF($F33&"/Día"=W$9,ROUND(U33/$W$1,1),"") -> 1113.2 | X33: =IF(U33=0,0,IF($F33&"/Día"=W$9,ROUND(V33/U33,4),"")) -> 58.988 | Y33: =IF(U33=0,0,IF($F33&"/Día"=W$9,ROUND(Z33/U33,4),"")) -> 11.0603 | Z33: =IF(U33<>"",$P33,"") -> 381689.38 | AA33: =IF($F33&"/Día"=AC$9,SUM($G33:$H33),"") | AB33: =IF(AA33<>"",$O33,"") | AC33: =IF($F33&"/Día"=AC$9,ROUND(AA33/$W$1,1),"") | AD33: =IF(AA33=0,0,IF($F33&"/Día"=AC$9,ROUND(AB33/AA33,4),"")) | AE33: =IF(AA33=0,0,IF($F33&"/Día"=AC$9,ROUND(AF33/AA33,4),"")) | AF33: =IF(AA33<>"",$P33,"")
A34: - | B34: Z-6 | C34: Licencia | D34: Quincena | E34: F2 | F34: MM BTU | O34: =ROUND(G34*I34,2)+ROUND(H34*J34,2)-K34-L34-M34-N34 -> 0 | P34: =ROUND(18.75%*O34,2) -> 0 | Q34: =ROUND($O34*R34,2) -> 0 | R34: 0.15 | S34: =ROUND($O34*T34,2) -> 0 | T34: 0.0375
A35: - | B35: Ajustes meses anteriores (1) | O35: =+O149 -> -23595.17 | P35: =ROUND(18.75%*O35,2) -> -4424.09 | Q35: =+Q149 -> -3539.28 | S35: =+S149 -> -884.82 | U35: =IF($F35&"/Día"=W$9,SUM($G35:$H35),"") | V35: =IF(U35<>"",$O35,"") | W35: =IF($F35&"/Día"=W$9,ROUND(U35/$W$1,1),"") | X35: =IF(U35=0,0,IF($F35&"/Día"=W$9,ROUND(V35/U35,4),"")) | Y35: =IF(U35=0,0,IF($F35&"/Día"=W$9,ROUND(Z35/U35,4),"")) | Z35: =IF(U35<>"",$P35,"") | AA35: =IF($F35&"/Día"=AC$9,SUM($G35:$H35),"") | AB35: =IF(AA35<>"",$O35,"") | AC35: =IF($F35&"/Día"=AC$9,ROUND(AA35/$W$1,1),"") | AD35: =IF(AA35=0,0,IF($F35&"/Día"=AC$9,ROUND(AB35/AA35,4),"")) | AE35: =IF(AA35=0,0,IF($F35&"/Día"=AC$9,ROUND(AF35/AA35,4),"")) | AF35: =IF(AA35<>"",$P35,"")
B36: Subtotal | C36: =TEXT(A$9,)&" US$" -> Piura / Tumbes US$ | O36: =SUM(O10:O35) -> 67371407 | P36: =SUM(P10:P35) -> 12632139 | Q36: =SUM(Q10:Q35) -> 10099533 | S36: =SUM(S10:S35) -> 2532605.5 | U36: =SUM(U10:U35) -> 960035 | V36: =SUM(V10:V35) -> 63261917 | W36: =SUM(W10:W35) -> 30969.1 | X36: =ROUND(V36/U36,4) -> 65.8954 | Y36: =ROUND(Z36/U36,4) -> 12.3554 | Z36: =SUM(Z10:Z35) -> 11861609 | AA36: =SUM(AA10:AA35) -> 1539785.8 | AB36: =SUM(AB10:AB35) -> 4133085.2 | AC36: =SUM(AC10:AC35) -> 49670.5 | AD36: =ROUND(AB36/AA36,4) -> 2.6842 | AE36: =ROUND(AF36/AA36,4) -> 0.5033 | AF36: =SUM(AF10:AF35) -> 774953.48 | AG36: =P36-Z36-AF36 -> -4424.09
C37: =TEXT(A$9,)&" S/." -> Piura / Tumbes S/. | P37: =ROUND($F$1*P36,2) -> 0 | Q37: =ROUND($F$1*Q36,2) -> 0 | S37: =ROUND($F$1*S36,2) -> 0
A38: Provincia Puerto Inca Huanuco | Q38: Puerto Inca
A39: - | B39: 31-D | C39: Licencia | D39: Quincena | E39: F2 | F39: Bls | H39: 2156 | J39: 68.2014 | N39: 1112.44 | O39: =ROUND(G39*I39,2)+ROUND(H39*J39,2)-K39-L39-M39-N39 -> 145929.78 | P39: =ROUND(15%*O39,2) -> 21889.47 | Q39: =ROUND($O39*R39,2) -> 21889.47 | R39: 0.15 | U39: =IF($F39&"/Día"=W$9,SUM($G39:$H39),"") -> 2156 | V39: =IF(U39<>"",$O39,"") -> 145929.78 | W39: =IF($F39&"/Día"=W$9,ROUND(U39/$W$1,1),"") -> 69.5 | X39: =IF(U39=0,0,IF($F39&"/Día"=W$9,ROUND(V39/U39,4),"")) -> 67.6854 | Y39: =IF(U39=0,0,IF($F39&"/Día"=W$9,ROUND(Z39/U39,4),"")) -> 10.1528 | Z39: =IF(U39<>"",$P39,"") -> 21889.47 | AA39: =IF($F39&"/Día"=AC$9,SUM($G39:$H39),"") | AB39: =IF(AA39<>"",$O39,"") | AC39: =IF($F39&"/Día"=AC$9,ROUND(AA39/$W$1,1),"") | AD39: =IF(AA39=0,0,IF($F39&"/Día"=AC$9,ROUND(AB39/AA39,4),"")) | AE39: =IF(AA39=0,0,IF($F39&"/Día"=AC$9,ROUND(AF39/AA39,4),"")) | AF39: =IF(AA39<>"",$P39,"")
A40: - | B40: 131 | C40: Licencia | D40: Quincena | E40: F2 | F40: Bls | G40: 41943 | H40: 45761 | I40: 64.135 | J40: 64.8264 | N40: 9444.89 | O40: =ROUND(G40*I40,2)+ROUND(H40*J40,2)-K40-L40-M40-N40 -> 5647090.3 | P40: =ROUND(15%*O40,2) -> 847063.55 | Q40: =ROUND($O40*R40,2) -> 847063.55 | R40: 0.15 | U40: =IF($F40&"/Día"=W$9,SUM($G40:$H40),"") -> 87704 | V40: =IF(U40<>"",$O40,"") -> 5647090.3 | W40: =IF($F40&"/Día"=W$9,ROUND(U40/$W$1,1),"") -> 2829.2 | X40: =IF(U40=0,0,IF($F40&"/Día"=W$9,ROUND(V40/U40,4),"")) -> 64.3881 | Y40: =IF(U40=0,0,IF($F40&"/Día"=W$9,ROUND(Z40/U40,4),"")) -> 9.6582 | Z40: =IF(U40<>"",$P40,"") -> 847063.55 | AA40: =IF($F40&"/Día"=AC$9,SUM($G40:$H40),"") | AB40: =IF(AA40<>"",$O40,"") | AC40: =IF($F40&"/Día"=AC$9,ROUND(AA40/$W$1,1),"") | AD40: =IF(AA40=0,0,IF($F40&"/Día"=AC$9,ROUND(AB40/AA40,4),"")) | AE40: =IF(AA40=0,0,IF($F40&"/Día"=AC$9,ROUND(AF40/AA40,4),"")) | AF40: =IF(AA40<>"",$P40,"")
A41: - | B41: Ajustes meses anteriores (2) | U41: =IF($F41&"/Día"=W$9,SUM($G41:$H41),"") | V41: =IF(U41<>"",$O41,"") | W41: =IF($F41&"/Día"=W$9,ROUND(U41/$W$1,1),"") | X41: =IF(U41=0,0,IF($F41&"/Día"=W$9,ROUND(V41/U41,4),"")) | Y41: =IF(U41=0,0,IF($F41&"/Día"=W$9,ROUND(Z41/U41,4),"")) | Z41: =IF(U41<>"",$P41,"") | AA41: =IF($F41&"/Día"=AC$9,SUM($G41:$H41),"") | AB41: =IF(AA41<>"",$O41,"") | AC41: =IF($F41&"/Día"=AC$9,ROUND(AA41/$W$1,1),"") | AD41: =IF(AA41=0,0,IF($F41&"/Día"=AC$9,ROUND(AB41/AA41,4),"")) | AE41: =IF(AA41=0,0,IF($F41&"/Día"=AC$9,ROUND(AF41/AA41,4),"")) | AF41: =IF(AA41<>"",$P41,"")
...

Sheet cuadre
E1: 45597 | S1: , | U1: Días en el mes | W1: =DATE(YEAR(E1),MONTH(E1)+1,1)-DATE(YEAR(E1),MONTH(E1),1) -> 30
A2: PERUPETRO S.A.
A3: DETERMINACION DEL CANON, SOBRECANON y PARTICIPACION (US$)
A4: ="Correspondiente a "&TEXT(E1,"MMMMMMM YYYY") -> Correspondiente a Noviembre 2024
A5: ="Tipo de Cambio= "&TEXT(F1,"0.000") -> Tipo de Cambio= 0.000
A7: Localidad | C7: Modalidad de Contrato | D7: Calculo del Canon | F7: Volumen Producción / Venta | I7: Canasta o Valor Venta (US$/Unidad) | K7: Deducción de Gastos para determinación de valor de producción en Punto de Fiscalización (US$) | O7: Valor de la Producción (US$) | P7: Canon y Sobrecanon / Participación (US$) | U7: RESUMEN POR PETROLERO Y CONDENSADOS | AA7: RESUMEN POR GAS NATURAL | AG7: Control
A8: - Lote | D8: Período | E8: Fórmula | F8: Unidades | G8: 1ra. Q | H8: 2da. Q / Mes | I8: 1ra. Q | J8: 2da. Q / Mes | K8: Flete Marítimo | L8: Comercialización | M8: Oleoducto | N8: Fiscalización | P8: Total | Q8: Localidad 1 | S8: Localidad 2 | U8: Producción / Venta | X8: Valor Prod | Y8: Valor Canon | AA8: Producción / Venta | AD8: Valor Prod | AE8: Valor Canon | AG8: Total
A9: Piura / Tumbes | Q9: Piura | S9: Tumbes | U9: Bls/Mes | V9: V P (US$) | W9: Bls/Día | X9: US$/Bl | Y9: US$/Bl | Z9: US$ | AA9: MM BTU/Mes | AB9: V P (US$) | AC9: MM BTU/Día | AD9: US$/MM BTU | AE9: US$/MM BTU | AF9: US$ | AG9: Canon
A10: - | B10: I | C10: Servicios | D10: Mes | E10: F1 | F10: Bls | G10: 4624 | H10: 9359 | J10: 73.2977 | N10: 93.41 | O10: =ROUND(G10*I10,2)+ROUND(H10*J10,2)-K10-L10-M10-N10 -> 685899.76 | P10: =ROUND(18.75%*O10,2) -> 128606.21 | Q10: =ROUND($O10*R10,2) -> 102884.96 | R10: 0.15 | S10: =ROUND($O10*T10,2) -> 25721.24 | T10: 0.0375 | U10: =IF($F10&"/Día"=W$9,SUM($G10:$H10),"") -> 13983 | V10: =IF(U10<>"",$O10,"") -> 685899.76 | W10: =IF($F10&"/Día"=W$9,ROUND(U10/$W$1,1),"") -> 466.1 | X10: =IF(U10=0,0,IF($F10&"/Día"=W$9,ROUND(V10/U10,4),"")) -> 49.0524 | Y10: =IF(U10=0,0,IF($F10&"/Día"=W$9,ROUND(Z10/U10,4),"")) -> 9.1973 | Z10: =IF(U10<>"",$P10,"") -> 128606.21 | AA10: =IF($F10&"/Día"=AC$9,SUM($G10:$H10),"") | AB10: =IF(AA10<>"",$O10,"") | AC10: =IF($F10&"/Día"=AC$9,ROUND(AA10/$W$1,1),"") | AD10: =IF(AA10=0,0,IF($F10&"/Día"=AC$9,ROUND(AB10/AA10,4),"")) | AE10: =IF(AA10=0,0,IF($F10&"/Día"=AC$9,ROUND(AF10/AA10,4),"")) | AF10: =IF(AA10<>"",$P10,"")
A11: - | B11: I GAS | C11: Servicios | D11: Mes | E11: F1 | F11: MM BTU | G11: 43341.48 | H11: 44253.289 | J11: 3.932 | N11: 264.11 | O11: =ROUND(G11*I11,2)+ROUND(H11*J11,2)-K11-L11-M11-N11 -> 173739.82 | P11: =ROUND(18.75%*O11,2) -> 32576.22 | Q11: =ROUND($O11*R11,2) -> 26060.97 | R11: 0.15 | S11: =ROUND($O11*T11,2) -> 6515.24 | T11: 0.0375 | U11: =IF($F11&"/Día"=W$9,SUM($G11:$H11),"") | V11: =IF(U11<>"",$O11,"") | W11: =IF($F11&"/Día"=W$9,ROUND(U11/$W$1,1),"") | X11: =IF(U11=0,0,IF($F11&"/Día"=W$9,ROUND(V11/U11,4),"")) | Y11: =IF(U11=0,0,IF($F11&"/Día"=W$9,ROUND(Z11/U11,4),"")) | Z11: =IF(U11<>"",$P11,"") | AA11: =IF($F11&"/Día"=AC$9,SUM($G11:$H11),"") -> 87594.769 | AB11: =IF(AA11<>"",$O11,"") -> 173739.82 | AC11: =IF($F11&"/Día"=AC$9,ROUND(AA11/$W$1,1),"") -> 2919.8 | AD11: =IF(AA11=0,0,IF($F11&"/Día"=AC$9,ROUND(AB11/AA11,4),"")) -> 1.9834 | AE11: =IF(AA11=0,0,IF($F11&"/Día"=AC$9,ROUND(AF11/AA11,4),"")) -> 0.3719 | AF11: =IF(AA11<>"",$P11,"") -> 32576.22 | AJ11: =AK11-P11 -> -0.01 | AK11: 32576.21
A12: - | B12: II | C12: Licencia | D12: Quincena | E12: F2 | F12: Bls | G12: 5026 | H12: 5243 | J12: 73.0332 | N12: 756.92 | O12: =ROUND(G12*I12,2)+ROUND(H12*J12,2)-K12-L12-M12-N12 -> 382156.15 | P12: =ROUND(18.75%*O12,2) -> 71654.28 | Q12: =ROUND($O12*R12,2) -> 57323.42 | R12: 0.15 | S12: =ROUND($O12*T12,2) -> 14330.86 | T12: 0.0375 | U12: =IF($F12&"/Día"=W$9,SUM($G12:$I12),"") -> 10269 | V12: =IF(U12<>"",$O12,"") -> 382156.15 | W12: =IF($F12&"/Día"=W$9,ROUND(U12/$W$1,1),"") -> 342.3 | X12: =IF(U12=0,0,IF($F12&"/Día"=W$9,ROUND(V12/U12,4),"")) -> 37.2145 | Y12: =IF(U12=0,0,IF($F12&"/Día"=W$9,ROUND(Z12/U12,4),"")) -> 6.9777 | Z12: =IF(U12<>"",$P12,"") -> 71654.28 | AA12: =IF($F12&"/Día"=AC$9,SUM($G12:$I12),"") | AB12: =IF(AA12<>"",$O12,"") | AC12: =IF($F12&"/Día"=AC$9,ROUND(AA12/$W$1,1),"") | AD12: =IF(AA12=0,0,IF($F12&"/Día"=AC$9,ROUND(AB12/AA12,4),"")) | AE12: =IF(AA12=0,0,IF($F12&"/Día"=AC$9,ROUND(AF12/AA12,4),"")) | AF12: =IF(AA12<>"",$P12,"")
A13: - | B13: II-GAS | C13: Servicios | D13: Mes | E13: F1 | F13: MM BTU | G13: 18137.092 | H13: 9380.4372 | J13: 2.8114 | N13: 808.45 | O13: =ROUND(G13*I13,2)+ROUND(H13*J13,2)-K13-L13-M13-N13 -> 25563.71 | P13: =ROUND(18.75%*O13,2) -> 4793.2 | Q13: =ROUND($O13*R13,2) -> 3834.56 | R13: 0.15 | S13: =ROUND($O13*T13,2) -> 958.64 | T13: 0.0375 | U13: =IF($F13&"/Día"=W$9,SUM($G13:$H13),"") | V13: =IF(U13<>"",$O13,"") | W13: =IF($F13&"/Día"=W$9,ROUND(U13/$W$1,1),"") | X13: =IF(U13=0,0,IF($F13&"/Día"=W$9,ROUND(V13/U13,4),"")) | Y13: =IF(U13=0,0,IF($F13&"/Día"=W$9,ROUND(Z13/U13,4),"")) | Z13: =IF(U13<>"",$P13,"") | AA13: =IF($F13&"/Día"=AC$9,SUM($G13:$H13),"") -> 27517.529 | AB13: =IF(AA13<>"",$O13,"") -> 25563.71 | AC13: =IF($F13&"/Día"=AC$9,ROUND(AA13/$W$1,1),"") -> 917.3 | AD13: =IF(AA13=0,0,IF($F13&"/Día"=AC$9,ROUND(AB13/AA13,4),"")) -> 0.929 | AE13: =IF(AA13=0,0,IF($F13&"/Día"=AC$9,ROUND(AF13/AA13,4),"")) -> 0.1742 | AF13: =IF(AA13<>"",$P13,"") -> 4793.2
A14: - | B14: III | C14: Licencia | D14: Quincena | E14: F2 | F14: Bls | G14: 28111 | H14: 27624 | J14: 73.2977 | N14: 1139.59 | O14: =ROUND(G14*I14,2)+ROUND(H14*J14,2)-K14-L14-M14-N14 -> 2023636.1 | P14: =ROUND(18.75%*O14,2) -> 379431.76 | Q14: =ROUND($O14*R14,2) -> 303545.41 | R14: 0.15 | S14: =ROUND($O14*T14,2) -> 75886.35 | T14: 0.0375 | U14: =IF($F14&"/Día"=W$9,SUM($G14:$H14),"") -> 55735 | V14: =IF(U14<>"",$O14,"") -> 2023636.1 | W14: =IF($F14&"/Día"=W$9,ROUND(U14/$W$1,1),"") -> 1857.8 | X14: =IF(U14=0,0,IF($F14&"/Día"=W$9,ROUND(V14/U14,4),"")) -> 36.3082 | Y14: =IF(U14=0,0,IF($F14&"/Día"=W$9,ROUND(Z14/U14,4),"")) -> 6.8078 | Z14: =IF(U14<>"",$P14,"") -> 379431.76 | AA14: =IF($F14&"/Día"=AC$9,SUM($G14:$H14),"") | AB14: =IF(AA14<>"",$O14,"") | AC14: =IF($F14&"/Día"=AC$9,ROUND(AA14/$W$1,1),"") | AD14: =IF(AA14=0,0,IF($F14&"/Día"=AC$9,ROUND(AB14/AA14,4),"")) | AE14: =IF(AA14=0,0,IF($F14&"/Día"=AC$9,ROUND(AF14/AA14,4),"")) | AF14: =IF(AA14<>"",$P14,"")
A15: - | B15: III-GAS | C15: Servicios | D15: Mes | E15: F1 | F15: MM BTU | G15: 13798.961 | H15: 8492.0515 | J15: 3.2 | O15: =ROUND(G15*I15,2)+ROUND(H15*J15,2)-K15-L15-M15-N15 -> 27174.56 | P15: =ROUND(18.75%*O15,2) -> 5095.23 | Q15: =ROUND($O15*R15,2) -> 4076.18 | R15: 0.15 | S15: =ROUND($O15*T15,2) -> 1019.05 | T15: 0.0375 | U15: =IF($F15&"/Día"=W$9,SUM($G15:$H15),"") | V15: =IF(U15<>"",$O15,"") | W15: =IF($F15&"/Día"=W$9,ROUND(U15/$W$1,1),"") | X15: =IF(U15=0,0,IF($F15&"/Día"=W$9,ROUND(V15/U15,4),"")) | Y15: =IF(U15=0,0,IF($F15&"/Día"=W$9,ROUND(Z15/U15,4),"")) | Z15: =IF(U15<>"",$P15,"") | AA15: =IF($F15&"/Día"=AC$9,SUM($G15:$H15),"") -> 22291.013 | AB15: =IF(AA15<>"",$O15,"") -> 27174.56 | AC15: =IF($F15&"/Día"=AC$9,ROUND(AA15/$W$1,1),"") -> 743 | AD15: =IF(AA15=0,0,IF($F15&"/Día"=AC$9,ROUND(AB15/AA15,4),"")) -> 1.2191 | AE15: =IF(AA15=0,0,IF($F15&"/Día"=AC$9,ROUND(AF15/AA15,4),"")) -> 0.2286 | AF15: =IF(AA15<>"",$P15,"") -> 5095.23
A16: - | B16: IV | C16: Licencia | D16: Quincena | E16: F2 | F16: Bls | G16: 43248 | H16: 43588 | J16: 73.2977 | N16: 1993.13 | O16: =ROUND(G16*I16,2)+ROUND(H16*J16,2)-K16-L16-M16-N16 -> 3192907 | P16: =ROUND(18.75%*O16,2) -> 598670.07 | Q16: =ROUND($O16*R16,2) -> 478936.05 | R16: 0.15 | S16: =ROUND($O16*T16,2) -> 119734.01 | T16: 0.0375 | U16: =IF($F16&"/Día"=W$9,SUM($G16:$H16),"") -> 86836 | V16: =IF(U16<>"",$O16,"") -> 3192907 | W16: =IF($F16&"/Día"=W$9,ROUND(U16/$W$1,1),"") -> 2894.5 | X16: =IF(U16=0,0,IF($F16&"/Día"=W$9,ROUND(V16/U16,4),"")) -> 36.7694 | Y16: =IF(U16=0,0,IF($F16&"/Día"=W$9,ROUND(Z16/U16,4),"")) -> 6.8943 | Z16: =IF(U16<>"",$P16,"") -> 598670.07 | AA16: =IF($F16&"/Día"=AC$9,SUM($G16:$H16),"") | AB16: =IF(AA16<>"",$O16,"") | AC16: =IF($F16&"/Día"=AC$9,ROUND(AA16/$W$1,1),"") | AD16: =IF(AA16=0,0,IF($F16&"/Día"=AC$9,ROUND(AB16/AA16,4),"")) | AE16: =IF(AA16=0,0,IF($F16&"/Día"=AC$9,ROUND(AF16/AA16,4),"")) | AF16: =IF(AA16<>"",$P16,"")
A17: - | B17: IV-GAS | C17: Licencia | D17: Quincena | E17: F2 | F17: Bls | G17: 71572.007 | H17: 44180.073 | J17: 3.1332 | N17: 601.69 | O17: =ROUND(G17*I17,2)+ROUND(H17*J17,2)-K17-L17-M17-N17 -> 137823.32 | P17: =ROUND(18.75%*O17,2) -> 25841.87 | Q17: =ROUND($O17*R17,2) -> 20673.5 | R17: 0.15 | S17: =ROUND($O17*T17,2) -> 5168.37 | T17: 0.0375 | U17: =IF($F17&"/Día"=W$9,SUM($G17:$H17),"") -> 115752.08 | V17: =IF(U17<>"",$O17,"") -> 137823.32 | W17: =IF($F17&"/Día"=W$9,ROUND(U17/$W$1,1),"") -> 3858.4 | X17: =IF(U17=0,0,IF($F17&"/Día"=W$9,ROUND(V17/U17,4),"")) -> 1.1907 | Y17: =IF(U17=0,0,IF($F17&"/Día"=W$9,ROUND(Z17/U17,4),"")) -> 0.2233 | Z17: =IF(U17<>"",$P17,"") -> 25841.87 | AA17: =IF($F17&"/Día"=AC$9,SUM($G17:$H17),"") | AB17: =IF(AA17<>"",$O17,"") | AC17: =IF($F17&"/Día"=AC$9,ROUND(AA17/$W$1,1),"") | AD17: =IF(AA17=0,0,IF($F17&"/Día"=AC$9,ROUND(AB17/AA17,4),"")) | AE17: =IF(AA17=0,0,IF($F17&"/Día"=AC$9,ROUND(AF17/AA17,4),"")) | AF17: =IF(AA17<>"",$P17,"")
A18: - | B18: V | C18: Servicios | D18: Mes | E18: F1 | F18: Bls | G18: 3037 | H18: 5045 | J18: 73.0596 | N18: 492.8 | O18: =ROUND(G18*I18,2)+ROUND(H18*J18,2)-K18-L18-M18-N18 -> 368092.88 | P18: =ROUND(18.75%*O18,2) -> 69017.42 | Q18: =ROUND($O18*R18,2) -> 55213.93 | R18: 0.15 | S18: =ROUND($O18*T18,2) -> 13803.48 | T18: 0.0375 | U18: =IF($F18&"/Día"=W$9,SUM($G18:$H18),"") -> 8082 | V18: =IF(U18<>"",$O18,"") -> 368092.88 | W18: =IF($F18&"/Día"=W$9,ROUND(U18/$W$1,1),"") -> 269.4 | X18: =IF(U18=0,0,IF($F18&"/Día"=W$9,ROUND(V18/U18,4),"")) -> 45.5448 | Y18: =IF(U18=0,0,IF($F18&"/Día"=W$9,ROUND(Z18/U18,4),"")) -> 8.5396 | Z18: =IF(U18<>"",$P18,"") -> 69017.42 | AA18: =IF($F18&"/Día"=AC$9,SUM($G18:$H18),"") | AB18: =IF(AA18<>"",$O18,"") | AC18: =IF($F18&"/Día"=AC$9,ROUND(AA18/$W$1,1),"") | AD18: =IF(AA18=0,0,IF($F18&"/Día"=AC$9,ROUND(AB18/AA18,4),"")) | AE18: =IF(AA18=0,0,IF($F18&"/Día"=AC$9,ROUND(AF18/AA18,4),"")) | AF18: =IF(AA18<>"",$P18,"")
A19: - | B19: VI (T) | C19: Licencia | D19: Quincena | E19: F1 | F19: Bls | G19: 23227 | H19: 25415 | J19: 73.2977 | N19: 592.65 | O19: =ROUND(G19*I19,2)+ROUND(H19*J19,2)-K19-L19-M19-N19 -> 1862268.4 | P19: =ROUND(18.75%*O19,2) -> 349175.33 | Q19: =ROUND($O19*R19,2) -> 279340.26 | R19: 0.15 | S19: =ROUND($O19*T19,2) -> 69835.07 | T19: 0.0375 | U19: =IF($F19&"/Día"=W$9,SUM($G19:$H19),"") -> 48642 | V19: =IF(U19<>"",$O19,"") -> 1862268.4 | W19: =IF($F19&"/Día"=W$9,ROUND(U19/$W$1,1),"") -> 1621.4 | X19: =IF(U19=0,0,IF($F19&"/Día"=W$9,ROUND(V19/U19,4),"")) -> 38.2852 | Y19: =IF(U19=0,0,IF($F19&"/Día"=W$9,ROUND(Z19/U19,4),"")) -> 7.1785 | Z19: =IF(U19<>"",$P19,"") -> 349175.33 | AA19: =IF($F19&"/Día"=AC$9,SUM($G19:$H19),"") | AB19: =IF(AA19<>"",$O19,"") | AC19: =IF($F19&"/Día"=AC$9,ROUND(AA19/$W$1,1),"") | AD19: =IF(AA19=0,0,IF($F19&"/Día"=AC$9,ROUND(AB19/AA19,4),"")) | AE19: =IF(AA19=0,0,IF($F19&"/Día"=AC$9,ROUND(AF19/AA19,4),"")) | AF19: =IF(AA19<>"",$P19,"")
A20: - | B20: VI - GAS | C20: Licencia | D20: Quincena | E20: F1 | F20: MM BTU | G20: 59288.898 | H20: 62901.239 | J20: 3.8211 | N20: 254.45 | O20: =ROUND(G20*I20,2)+ROUND(H20*J20,2)-K20-L20-M20-N20 -> 240097.48 | P20: =ROUND(18.75%*O20,2) -> 45018.28 | Q20: =ROUND($O20*R20,2) -> 36014.62 | R20: 0.15 | S20: =ROUND($O20*T20,2) -> 9003.66 | T20: 0.0375 | U20: =IF($F20&"/Día"=W$9,SUM($G20:$H20),"") | V20: =IF(U20<>"",$O20,"") | W20: =IF($F20&"/Día"=W$9,ROUND(U20/$W$1,1),"") | X20: =IF(U20=0,0,IF($F20&"/Día"=W$9,ROUND(V20/U20,4),"")) | Y20: =IF(U20=0,0,IF($F20&"/Día"=W$9,ROUND(Z20/U20,4),"")) | Z20: =IF(U20<>"",$P20,"") | AA20: =IF($F20&"/Día"=AC$9,SUM($G20:$H20),"") -> 122190.14 | AB20: =IF(AA20<>"",$O20,"") -> 240097.48 | AC20: =IF($F20&"/Día"=AC$9,ROUND(AA20/$W$1,1),"") -> 4073 | AD20: =IF(AA20=0,0,IF($F20&"/Día"=AC$9,ROUND(AB20/AA20,4),"")) -> 1.9649 | AE20: =IF(AA20=0,0,IF($F20&"/Día"=AC$9,ROUND(AF20/AA20,4),"")) -> 0.3684 | AF20: =IF(AA20<>"",$P20,"") -> 45018.28
A21: - | B21: VII (T) | C21: Licencia | D21: Quincena | E21: F1 | F21: Bls | G21: 15639 | H21: 16938 | J21: 73.0596 | N21: 293.11 | O21: =ROUND(G21*I21,2)+ROUND(H21*J21,2)-K21-L21-M21-N21 -> 1237190.4 | P21: =ROUND(18.75%*O21,2) -> 231973.2 | Q21: =ROUND($O21*R21,2) -> 185578.56 | R21: 0.15 | S21: =ROUND($O21*T21,2) -> 46394.64 | T21: 0.0375 | U21: =IF($F21&"/Día"=W$9,SUM($G21:$H21),"") -> 32577 | V21: =IF(U21<>"",$O21,"") -> 1237190.4 | W21: =IF($F21&"/Día"=W$9,ROUND(U21/$W$1,1),"") -> 1085.9 | X21: =IF(U21=0,0,IF($F21&"/Día"=W$9,ROUND(V21/U21,4),"")) -> 37.9774 | Y21: =IF(U21=0,0,IF($F21&"/Día"=W$9,ROUND(Z21/U21,4),"")) -> 7.1208 | Z21: =IF(U21<>"",$P21,"") -> 231973.2 | AA21: =IF($F21&"/Día"=AC$9,SUM($G21:$H21),"") | AB21: =IF(AA21<>"",$O21,"") | AC21: =IF($F21&"/Día"=AC$9,ROUND(AA21/$W$1,1),"") | AD21: =IF(AA21=0,0,IF($F21&"/Día"=AC$9,ROUND(AB21/AA21,4),"")) | AE21: =IF(AA21=0,0,IF($F21&"/Día"=AC$9,ROUND(AF21/AA21,4),"")) | AF21: =IF(AA21<>"",$P21,"")
A22: - | B22: VII/VI | C22: Licencia | D22: Quincena | E22: F2 | F22: Bls | O22: =ROUND(G22*I22,2)+ROUND(H22*J22,2)-K22-L22-M22-N22 -> 0 | P22: =ROUND(18.75%*O22,2) -> 0 | Q22: =ROUND($O22*R22,2) -> 0 | R22: 0.15 | S22: =ROUND($O22*T22,2) -> 0 | T22: 0.0375
A23: - | B23: IX | C23: Licencia | D23: Quincena | E23: F2 | F23: Bls | G23: 1870 | H23: 2633 | J23: 73.2977 | N23: 315.65 | O23: =ROUND(G23*I23,2)+ROUND(H23*J23,2)-K23-L23-M23-N23 -> 192677.19 | P23: =ROUND(18.75%*O23,2) -> 36126.97 | Q23: =ROUND($O23*R23,2) -> 28901.58 | R23: 0.15 | S23: =ROUND($O23*T23,2) -> 7225.39 | T23: 0.0375 | U23: =IF($F23&"/Día"=W$9,SUM($G23:$H23),"") -> 4503 | V23: =IF(U23<>"",$O23,"") -> 192677.19 | W23: =IF($F23&"/Día"=W$9,ROUND(U23/$W$1,1),"") -> 150.1 | X23: =IF(U23=0,0,IF($F23&"/Día"=W$9,ROUND(V23/U23,4),"")) -> 42.7886 | Y23: =IF(U23=0,0,IF($F23&"/Día"=W$9,ROUND(Z23/U23,4),"")) -> 8.0229 | Z23: =IF(U23<>"",$P23,"") -> 36126.97 | AA23: =IF($F23&"/Día"=AC$9,SUM($G23:$H23),"") | AB23: =IF(AA23<>"",$O23,"") | AC23: =IF($F23&"/Día"=AC$9,ROUND(AA23/$W$1,1),"") | AD23: =IF(AA23=0,0,IF($F23&"/Día"=AC$9,ROUND(AB23/AA23,4),"")) | AE23: =IF(AA23=0,0,IF($F23&"/Día"=AC$9,ROUND(AF23/AA23,4),"")) | AF23: =IF(AA23<>"",$P23,"")
A24: - | B24: X | C24: Licencia | D24: Quincena | E24: F2 | F24: Bls | G24: 118972 | H24: 117901 | J24: 74.8523 | N24: 1318.19 | O24: =ROUND(G24*I24,2)+ROUND(H24*J24,2)-K24-L24-M24-N24 -> 8823842.8 | P24: =ROUND(18.75%*O24,2) -> 1654470.5 | Q24: =ROUND($O24*R24,2) -> 1323576.4 | R24: 0.15 | S24: =ROUND($O24*T24,2) -> 330894.11 | T24: 0.0375 | U24: =IF($F24&"/Día"=W$9,SUM($G24:$H24),"") -> 236873 | V24: =IF(U24<>"",$O24,"") -> 8823842.8 | W24: =IF($F24&"/Día"=W$9,ROUND(U24/$W$1,1),"") -> 7895.8 | X24: =IF(U24=0,0,IF($F24&"/Día"=W$9,ROUND(V24/U24,4),"")) -> 37.2514 | Y24: =IF(U24=0,0,IF($F24&"/Día"=W$9,ROUND(Z24/U24,4),"")) -> 6.9846 | Z24: =IF(U24<>"",$P24,"") -> 1654470.5 | AA24: =IF($F24&"/Día"=AC$9,SUM($G24:$H24),"") | AB24: =IF(AA24<>"",$O24,"") | AC24: =IF($F24&"/Día"=AC$9,ROUND(AA24/$W$1,1),"") | AD24: =IF(AA24=0,0,IF($F24&"/Día"=AC$9,ROUND(AB24/AA24,4),"")) | AE24: =IF(AA24=0,0,IF($F24&"/Día"=AC$9,ROUND(AF24/AA24,4),"")) | AF24: =IF(AA24<>"",$P24,"")
A25: - | B25: X-GAS | C25: Licencia | D25: Mes | E25: F2 | F25: MM BTU | G25: 193471.59 | H25: 195754.86 | J25: 2.8097 | N25: 970.33 | O25: =ROUND(G25*I25,2)+ROUND(H25*J25,2)-K25-L25-M25-N25 -> 549042.1 | P25: =ROUND(18.75%*O25,2) -> 102945.39 | Q25: =ROUND($O25*R25,2) -> 82356.32 | R25: 0.15 | S25: =ROUND($O25*T25,2) -> 20589.08 | T25: 0.0375 | U25: =IF($F25&"/Día"=W$9,SUM($G25:$H25),"") | V25: =IF(U25<>"",$O25,"") | W25: =IF($F25&"/Día"=W$9,ROUND(U25/$W$1,1),"") | X25: =IF(U25=0,0,IF($F25&"/Día"=W$9,ROUND(V25/U25,4),"")) | Y25: =IF(U25=0,0,IF($F25&"/Día"=W$9,ROUND(Z25/U25,4),"")) | Z25: =IF(U25<>"",$P25,"") | AA25: =IF($F25&"/Día"=AC$9,SUM($G25:$H25),"") -> 389226.45 | AB25: =IF(AA25<>"",$O25,"") -> 549042.1 | AC25: =IF($F25&"/Día"=AC$9,ROUND(AA25/$W$1,1),"") -> 12974.2 | AD25: =IF(AA25=0,0,IF($F25&"/Día"=AC$9,ROUND(AB25/AA25,4),"")) -> 1.4106 | AE25: =IF(AA25=0,0,IF($F25&"/Día"=AC$9,ROUND(AF25/AA25,4),"")) -> 0.2645 | AF25: =IF(AA25<>"",$P25,"") -> 102945.39
A26: - | B26: XV | C26: Licencia | D26: Quincena | E26: F2 | F26: Bls | G26: 284 | H26: 270 | J26: 73.0596 | N26: 344.64 | O26: =ROUND(G26*I26,2)+ROUND(H26*J26,2)-K26-L26-M26-N26 -> 19381.45 | P26: =ROUND(18.75%*O26,2) -> 3634.02 | Q26: =ROUND($O26*R26,2) -> 2907.22 | R26: 0.15 | S26: =ROUND($O26*T26,2) -> 726.8 | T26: 0.0375 | U26: =IF($F26&"/Día"=W$9,SUM($G26:$H26),"") -> 554 | V26: =IF(U26<>"",$O26,"") -> 19381.45 | W26: =IF($F26&"/Día"=W$9,ROUND(U26/$W$1,1),"") -> 18.5 | X26: =IF(U26=0,0,IF($F26&"/Día"=W$9,ROUND(V26/U26,4),"")) -> 34.9846 | Y26: =IF(U26=0,0,IF($F26&"/Día"=W$9,ROUND(Z26/U26,4),"")) -> 6.5596 | Z26: =IF(U26<>"",$P26,"") -> 3634.02 | AA26: =IF($F26&"/Día"=AC$9,SUM($G26:$H26),"") | AB26: =IF(AA26<>"",$O26,"") | AC26: =IF($F26&"/Día"=AC$9,ROUND(AA26/$W$1,1),"") | AD26: =IF(AA26=0,0,IF($F26&"/Día"=AC$9,ROUND(AB26/AA26,4),"")) | AE26: =IF(AA26=0,0,IF($F26&"/Día"=AC$9,ROUND(AF26/AA26,4),"")) | AF26: =IF(AA26<>"",$P26,"")
A27: - | B27: XIII Crudo | C27: Licencia | D27: Quincena | E27: F2 | F27: Bls | G27: 14931 | H27: 14937 | J27: 73.2377 | N27: 3262.8 | O27: =ROUND(G27*I27,2)+ROUND(H27*J27,2)-K27-L27-M27-N27 -> 1090688.7 | P27: =ROUND(18.75%*O27,2) -> 204504.14 | Q27: =ROUND($O27*R27,2) -> 163603.31 | R27: 0.15 | S27: =ROUND($O27*T27,2) -> 40900.83 | T27: 0.0375 | U27: =IF($F27&"/Día"=W$9,SUM($G27:$H27),"") -> 29868 | V27: =IF(U27<>"",$O27,"") -> 1090688.7 | W27: =IF($F27&"/Día"=W$9,ROUND(U27/$W$1,1),"") -> 995.6 | X27: =IF(U27=0,0,IF($F27&"/Día"=W$9,ROUND(V27/U27,4),"")) -> 36.517 | Y27: =IF(U27=0,0,IF($F27&"/Día"=W$9,ROUND(Z27/U27,4),"")) -> 6.8469 | Z27: =IF(U27<>"",$P27,"") -> 204504.14 | AA27: =IF($F27&"/Día"=AC$9,SUM($G27:$H27),"") | AB27: =IF(AA27<>"",$O27,"") | AC27: =IF($F27&"/Día"=AC$9,ROUND(AA27/$W$1,1),"") | AD27: =IF(AA27=0,0,IF($F27&"/Día"=AC$9,ROUND(AB27/AA27,4),"")) | AE27: =IF(AA27=0,0,IF($F27&"/Día"=AC$9,ROUND(AF27/AA27,4),"")) | AF27: =IF(AA27<>"",$P27,"")
A28: - | B28: XIII Gas | C28: Licencia | D28: Quincena | E28: F2 | F28: MM BTU | G28: =G448 -> 391300.81 | H28: =H459 -> 396292.73 | J28: =J459 -> 3.3340609 | N28: =N438 -> 1356.01 | O28: =O438 -> 2589083.2 | P28: =P438 -> 485453.1 | Q28: =Q438 -> 388362.48 | R28: 0.15 | S28: =S438 -> 97090.61 | T28: 0.0375 | U28: =IF($F28&"/Día"=W$9,SUM($G28:$H28),"") | V28: =IF(U28<>"",$O28,"") | W28: =IF($F28&"/Día"=W$9,ROUND(U28/$W$1,1),"") | X28: =IF(U28=0,0,IF($F28&"/Día"=W$9,ROUND(V28/U28,4),"")) | Y28: =IF(U28=0,0,IF($F28&"/Día"=W$9,ROUND(Z28/U28,4),"")) | Z28: =IF(U28<>"",$P28,"") | AA28: =IF($F28&"/Día"=AC$9,SUM($G28:$H28),"") -> 787593.54 | AB28: =IF(AA28<>"",$O28,"") -> 2589083.2 | AC28: =IF($F28&"/Día"=AC$9,ROUND(AA28/$W$1,1),"") -> 26253.1 | AD28: =IF(AA28=0,0,IF($F28&"/Día"=AC$9,ROUND(AB28/AA28,4),"")) -> 3.2873 | AE28: =IF(AA28=0,0,IF($F28&"/Día"=AC$9,ROUND(AF28/AA28,4),"")) -> 0.6164 | AF28: =IF(AA28<>"",$P28,"") -> 485453.1
A29: - | B29: XX | C29: Licencia | D29: Quincena | E29: F2 | F29: Bls | G29: 161 | H29: 180 | J29: 73.2977 | N29: 202.92 | O29: =ROUND(G29*I29,2)+ROUND(H29*J29,2)-K29-L29-M29-N29 -> 12990.67 | P29: =ROUND(18.75%*O29,2) -> 2435.75 | Q29: =ROUND($O29*R29,2) -> 487.15 | R29: 0.0375 | S29: =ROUND($O29*T29,2) -> 1948.6 | T29: 0.15 | U29: =IF($F29&"/Día"=W$9,SUM($G29:$H29),"") -> 341 | V29: =IF(U29<>"",$O29,"") -> 12990.67 | W29: =IF($F29&"/Día"=W$9,ROUND(U29/$W$1,1),"") -> 11.4 | X29: =IF(U29=0,0,IF($F29&"/Día"=W$9,ROUND(V29/U29,4),"")) -> 38.0958 | Y29: =IF(U29=0,0,IF($F29&"/Día"=W$9,ROUND(Z29/U29,4),"")) -> 7.143 | Z29: =IF(U29<>"",$P29,"") -> 2435.75 | AA29: =IF($F29&"/Día"=AC$9,SUM($G29:$H29),"") | AB29: =IF(AA29<>"",$O29,"") | AC29: =IF($F29&"/Día"=AC$9,ROUND(AA29/$W$1,1),"") | AD29: =IF(AA29=0,0,IF($F29&"/Día"=AC$9,ROUND(AB29/AA29,4),"")) | AE29: =IF(AA29=0,0,IF($F29&"/Día"=AC$9,ROUND(AF29/AA29,4),"")) | AF29: =IF(AA29<>"",$P29,"")
A30: - | B30: Z1 Crudo | C30: Licencia | D30: Quincena | E30: F2 | F30: Bls | G30: 59744 | N30: 1027.48 | O30: =ROUND(G30*I30,2)+ROUND(H30*J30,2)-K30-L30-M30-N30 -> -1027.48 | P30: =ROUND(18.75%*O30,2) -> -192.65 | Q30: =ROUND($O30*R30,2) -> -38.53 | R30: 0.0375 | S30: =ROUND($O30*T30,2) -> -154.12 | T30: 0.15
A31: - | B31: Z-69 Crudo | C31: Licencia | D31: Quincena | E31: F2 | F31: Bls | G31: 50058 | H31: 74952 | J31: 73.369 | N31: 525.01 | O31: =ROUND(G31*I31,2)+ROUND(H31*J31,2)-K31-L31-M31-N31 -> 5498628.3 | P31: =ROUND(18.75%*O31,2) -> 1030992.8 | Q31: =ROUND($O31*R31,2) -> 824794.24 | R31: 0.15 | S31: =ROUND($O31*T31,2) -> 206198.56 | T31: 0.0375
A32: - | B32: Z-69 Gas | C32: Licencia | D32: Quincena | E32: F2 | F32: MM BTU | G32: =G504 -> 146872.7 | H32: =H513 -> 140602.21 | J32: =J513 -> 2.8168665 | N32: 463.82 | O32: =ROUND(G32*I32,2)+ROUND(H32*J32,2)-K32-L32-M32-N32 -> 395593.84 | P32: =ROUND(18.75%*O32,2) -> 74173.85 | Q32: =ROUND($O32*R32,2) -> 59339.08 | R32: 0.15 | S32: =ROUND($O32*T32,2) -> 14834.77 | T32: 0.0375
A33: - | B33: Z-69 Lgn | C33: Licencia | D33: Quincena | E33: F2 | F33: Bls | G33: 9427 | H33: 9336 | J33: 61.4049 | N33: 502.46 | O33: =ROUND(G33*I33,2)+ROUND(H33*J33,2)-K33-L33-M33-N33 -> 572773.69 | P33: =ROUND(18.75%*O33,2) -> 107395.07 | Q33: =ROUND($O33*R33,2) -> 85916.05 | R33: 0.15 | S33: =ROUND($O33*T33,2) -> 21479.01 | T33: 0.0375
A34: - | B34: Ajustes meses anteriores (1) | O34: =O304 -> -2401688 | P34: =P304 -> -450316.52 | Q34: =Q304 -> -360253.19 | S34: =S304 -> -90063.27 | U34: =IF($F34&"/Día"=W$9,SUM($G34:$H34),"") | V34: =IF(U34<>"",$O34,"") | W34: =IF($F34&"/Día"=W$9,ROUND(U34/$W$1,1),"") | X34: =IF(U34=0,0,IF($F34&"/Día"=W$9,ROUND(V34/U34,4),"")) | Y34: =IF(U34=0,0,IF($F34&"/Día"=W$9,ROUND(Z34/U34,4),"")) | Z34: =IF(U34<>"",$P34,"") | AA34: =IF($F34&"/Día"=AC$9,SUM($G34:$H34),"") | AB34: =IF(AA34<>"",$O34,"") | AC34: =IF($F34&"/Día"=AC$9,ROUND(AA34/$W$1,1),"") | AD34: =IF(AA34=0,0,IF($F34&"/Día"=AC$9,ROUND(AB34/AA34,4),"")) | AE34: =IF(AA34=0,0,IF($F34&"/Día"=AC$9,ROUND(AF34/AA34,4),"")) | AF34: =IF(AA34<>"",$P34,"")
B35: Subtotal | C35: =TEXT(A$9,)&" US$" -> Piura / Tumbes US$ | O35: =SUM(O10:O34) -> 27698536 | P35: =SUM(P10:P34) -> 5193475.5 | Q35: =SUM(Q10:Q34) -> 4153434.6 | S35: =SUM(S10:S34) -> 1040041 | T35: 0 | U35: =SUM(U10:U34) -> 644015.08 | V35: =SUM(V10:V34) -> 20029555 | W35: =SUM(W10:W34) -> 21467.2 | X35: =ROUND(V35/U35,4) -> 31.1011 | Y35: =ROUND(Z35/U35,4) -> 5.8314 | Z35: =SUM(Z10:Z34) -> 3755541.5 | AA35: =SUM(AA10:AA34) -> 1436413.4 | AB35: =SUM(AB10:AB34) -> 3604700.8 | AC35: =SUM(AC10:AC34) -> 47880.4 | AD35: =ROUND(AB35/AA35,4) -> 2.5095 | AE35: =ROUND(AF35/AA35,4) -> 0.4705 | AF35: =SUM(AF10:AF34) -> 675881.42 | AG35: =P35-Z35-AF35 -> 762052.55
C36: =TEXT(A$9,)&" S/." -> Piura / Tumbes S/. | P36: =ROUND($F$1*P35,2) -> 0 | Q36: =ROUND($F$1*Q35,2) -> 0 | S36: =ROUND($F$1*S35,2) -> 0
A37: Provincia Puerto Inca Huanuco | Q37: Puerto Inca
