Workbook
Name UCA.AGRO.DATE: '01.XLS'!$B$5:$FA$5
Name UCA.AGRO.NAME: '01.XLS'!$A$7:$A$55
Name UCA.AGRO.VAL: '01.XLS'!$B$7:$FA$55
Name UCA.AGROOTROS.DATE: '02.XLS'!$B$5:$FA$5
Name UCA.AGROOTROS.NAME: '02.XLS'!$A$7:$A$51
Name UCA.AGROOTROS.VAL: '02.XLS'!$B$7:$FA$51
Name UCA.ASERRADA.DATE: '09.XLS'!$B$5:$FA$5
Name UCA.ASERRADA.NAME: '09.XLS'!$A$7:$A$41
Name UCA.ASERRADA.VAL: '09.XLS'!$B$7:$FA$41
Name UCA.COSECHAS.DATE: '05.XLS'!$B$5:$FA$5
Name UCA.COSECHAS.NAME: '05.XLS'!$A$7:$A$34
Name UCA.COSECHAS.VAL: '05.XLS'!$B$7:$FA$34
Name UCA.COSECHASOTROS.DATE: '06.XLS'!$B$5:$FA$5
Name UCA.COSECHASOTROS.NAME: '06.XLS'!$A$7:$A$49
Name UCA.COSECHASOTROS.VAL: '06.XLS'!$B$7:$FA$49
Name UCA.GGL.DATE: 'GASTOS G.L.'!$B$5:$FA$5
Name UCA.GGL.NAME: 'GASTOS G.L.'!$A$7:$A$30
Name UCA.GGL.VAL: 'GASTOS G.L.'!$B$7:$FA$30
Name UCA.GGN.DATE: 'GASTOS G.N.'!$B$5:$FA$5
Name UCA.GGN.NAME: 'GASTOS G.N.'!$A$7:$A$30
Name UCA.GGN.VAL: 'GASTOS G.N.'!$B$7:$FA$30
Name UCA.GGR.DATE: 'GASTOS G.R.'!$B$5:$FA$5
Name UCA.GGR.NAME: 'GASTOS G.R.'!$A$7:$A$31
Name UCA.GGR.VAL: 'GASTOS G.R.'!$B$7:$FA$31
Name UCA.HIDROCARBURO.DATE: '10.XLS'!$B$5:$FA$5
Name UCA.HIDROCARBURO.NAME: '10.XLS'!$A$7:$A$14
Name UCA.HIDROCARBURO.VAL: '10.XLS'!$B$7:$FA$14
Name UCA.IGL.DATE: 'INVERSIÓN G.L.'!$B$5:$FA$5
Name UCA.IGL.NAME: 'INVERSIÓN G.L.'!$A$7:$A$32
Name UCA.IGL.VAL: 'INVERSIÓN G.L.'!$B$7:$FA$32
Name UCA.IGN.DATE: 'INVERSIÓN G.N.'!$B$5:$FA$5
Name UCA.IGN.NAME: 'INVERSIÓN G.N.'!$A$7:$A$34
Name UCA.IGN.VAL: 'INVERSIÓN G.N.'!$B$7:$FA$34
Name UCA.IGR.DATE: 'INVERSIÓN G.R.'!$B$5:$FA$5
Name UCA.IGR.NAME: 'INVERSIÓN G.R.'!$A$7:$A$34
Name UCA.IGR.VAL: 'INVERSIÓN G.R.'!$B$7:$FA$34
Name UCA.MANUFACTURA.DATE: '11.XLS-BASE 2007'!$B$5:$FA$5
Name UCA.MANUFACTURA.NAME: '11.XLS-BASE 2007'!$A$7:$A$17
Name UCA.MANUFACTURA.VAL: '11.XLS-BASE 2007'!$B$7:$FA$17
Name UCA.MANUFACTURAVAR.NAME: '11.XLS-BASE 2007'!$A$23:$A$33
Name UCA.MANUFACTURAVAR.VAL: '11.XLS-BASE 2007'!$B$23:$FA$33
Name UCA.PESCA.DATE: '07.XLS'!$B$5:$FA$5
Name UCA.PESCA.NAME: '07.XLS'!$A$7:$A$54
Name UCA.PESCA.VAL: '07.XLS'!$B$7:$FA$54
Name UCA.ROLLIZA.DATE: '08.XLS'!$B$5:$FA$5
Name UCA.ROLLIZA.NAME: '08.XLS'!$A$7:$A$41
Name UCA.ROLLIZA.VAL: '08.XLS'!$B$7:$FA$41
Name UCA.SIEMBRAS.DATE: '03.XLS'!$B$5:$FN$5
Name UCA.SIEMBRAS.NAME: '03.XLS'!$A$7:$A$34
Name UCA.SIEMBRAS.VAL: '03.XLS'!$B$7:$FN$34
Name UCA.SIEMBRASOTROS.DATE: '04.XLS'!$B$5:$FN$5
Name UCA.SIEMBRASOTROS.NAME: '04.XLS'!$A$7:$A$49
Name UCA.SIEMBRASOTROS.VAL: '04.XLS'!$B$7:$FN$49
Name UCA.X.DATE: '15.XLS'!$B$5:$FA$5
Name UCA.X.NAME: '15.XLS'!$A$7:$A$34
Name UCA.X.VAL: '15.XLS'!$B$7:$FA$34

Sheet 01.XLS
A1: Cuadro N° 01
A2: UCAYALI: PRODUCCIÓN DE PRINCIPALES PRODUCTOS AGROPECUARIOS 1/
A3: (VBP y toneladas métricas)
B4: 2015 | N4: Total | O4: 2016 | AA4: Total | AB4: 2017 | AN4: Total | AO4: 2018 | BA4: Total | BB4: 2019 | BN4: Total | BO4: 2020 | CA4: Total | CB4: 2021 | CN4: Total | CO4: 2022 | DA4: Total | DB4: 2023 | DN4: Total | DO4: 2024 | EA4: Total | EB4: 2025 | EN4: Total | EO4: 2026 | FA4: Total | FC4: =CONCATENATE("Var.% ",FF4,"/",FF4-1) -> Var.% 2025/2024 | FE4: =FF4-1 -> 2024 | FF4: =YEAR(FC5) -> 2025 | FH4: PARA COMPROBAR
B5: 42005 | C5: 42036 | D5: 42064 | E5: 42095 | F5: 42125 | G5: 42156 | H5: 42186 | I5: 42217 | J5: 42248 | K5: 42278 | L5: 42309 | M5: 42339 | N5: =YEAR(M5) -> 2015 | O5: 42370 | P5: 42401 | Q5: 42430 | R5: 42461 | S5: 42491 | T5: 42522 | U5: 42552 | V5: 42583 | W5: 42614 | X5: 42644 | Y5: 42675 | Z5: 42705 | AA5: =YEAR(Z5) -> 2016 | AB5: 42736 | AC5: 42767 | AD5: 42795 | AE5: 42826 | AF5: 42856 | AG5: 42887 | AH5: 42917 | AI5: 42948 | AJ5: 42979 | AK5: 43009 | AL5: 43040 | AM5: 43070 | AN5: =YEAR(AM5) -> 2017 | AO5: 43101 | AP5: 43132 | AQ5: 43160 | AR5: 43191 | AS5: 43221 | AT5: 43252 | AU5: 43282 | AV5: 43313 | AW5: 43344 | AX5: 43374 | AY5: 43405 | AZ5: 43435 | BA5: =YEAR(AZ5) -> 2018 | BB5: 43466 | BC5: 43497 | BD5: 43525 | BE5: 43556 | BF5: 43586 | BG5: 43617 | BH5: 43647 | BI5: 43678 | BJ5: 43709 | BK5: 43739 | BL5: 43770 | BM5: 43800 | BN5: =YEAR(BM5) -> 2019 | BO5: 43831 | BP5: 43862 | BQ5: 43891 | BR5: 43922 | BS5: 43952 | BT5: 43983 | BU5: 44013 | BV5: 44044 | BW5: 44075 | BX5: 44105 | BY5: 44136 | BZ5: 44166 | CA5: =YEAR(BZ5) -> 2020 | CB5: 44197 | CC5: 44228 | CD5: 44256 | CE5: 44287 | CF5: 44317 | CG5: 44348 | CH5: 44378 | CI5: 44409 | CJ5: 44440 | CK5: 44470 | CL5: 44501 | CM5: 44531 | CN5: =YEAR(CM5) -> 2021 | CO5: 44562 | CP5: 44593 | CQ5: 44621 | CR5: 44652 | CS5: 44682 | CT5: 44713 | CU5: 44743 | CV5: 44774 | CW5: 44805 | CX5: 44835 | CY5: 44866 | CZ5: 44896 | DA5: =YEAR(CZ5) -> 2022 | DB5: 44927 | DC5: 44958 | DD5: 44986 | DE5: 45017 | DF5: 45047 | DG5: 45078 | DH5: 45108 | DI5: 45139 | DJ5: 45170 | DK5: 45200 | DL5: 45231 | DM5: 45261 | DN5: =YEAR(DM5) -> 2023 | DO5: 45292 | DP5: 45323 | DQ5: 45352 | DR5: 45383 | DS5: 45413 | DT5: 45444 | DU5: 45474 | DV5: 45505 | DW5: 45536 | DX5: 45566 | DY5: 45597 | DZ5: 45627 | EA5: =YEAR(DZ5) -> 2024 | EB5: 45658 | EC5: 45689 | ED5: 45717 | EE5: 45748 | EF5: 45778 | EG5: 45809 | EH5: 45839 | EI5: 45870 | EJ5: 45901 | EK5: 45931 | EL5: 45962 | EM5: 45992 | EN5: =YEAR(EM5) -> 2025 | EO5: 46023 | EP5: 46054 | EQ5: 46082 | ER5: 46113 | ES5: 46143 | ET5: 46174 | EU5: 46204 | EV5: 46235 | EW5: 46266 | EX5: 46296 | EY5: 46327 | EZ5: 46357 | FA5: =YEAR(EZ5) -> 2026 | FC5: =EL5 -> 45962 | FD5: =CONCATENATE("Ene.-",TEXT(FC5,"MMM.")) -> Ene.-Nov. | FE5: =FD5 -> Ene.-Nov. | FF5: =FD5 -> Ene.-Nov. | FH5: NO BORRRAR
A7: AGROPECUARIO 2/ | B7: =SUM(B8,B9) -> 38760.828 | C7: =SUM(C8,C9) -> 38938.516 | D7: =SUM(D8,D9) -> 41960.989 | E7: =SUM(E8,E9) -> 42033.767 | F7: =SUM(F8,F9) -> 38668.799 | G7: =SUM(G8,G9) -> 38459.462 | H7: =SUM(H8,H9) -> 34407.461 | I7: =SUM(I8,I9) -> 34410.185 | ... M7: =SUM(M8,M9) -> 36358.656 | N7: =SUM(B7:M7) -> 461014.28 | O7: =SUM(O8,O9) -> 33536.73 | P7: =SUM(P8,P9) -> 34432.231 | Q7: =SUM(Q8,Q9) -> 36968.369 | R7: =SUM(R8,R9) -> 39065.915 | S7: =SUM(S8,S9) -> 38904.029 | T7: =SUM(T8,T9) -> 39241.798 | U7: =SUM(U8,U9) -> 33273.882 | V7: =SUM(V8,V9) -> 30653.481 | ... Z7: =SUM(Z8,Z9) -> 37771.783 | AA7: =SUM(O7:Z7) -> 432418.43 | AB7: =SUM(AB8,AB9) -> 32281.672 | AC7: =SUM(AC8,AC9) -> 36554.884 | AD7: =SUM(AD8,AD9) -> 43293.764 | AE7: =SUM(AE8,AE9) -> 39582.055 | AF7: =SUM(AF8,AF9) -> 43831.377 | AG7: =SUM(AG8,AG9) -> 44243.127 | AH7: =SUM(AH8,AH9) -> 42058.807 | AI7: =SUM(AI8,AI9) -> 36723.214 | ... AM7: =SUM(AM8,AM9) -> 43880.2 | AN7: =SUM(AB7:AM7) -> 511748.59 | AO7: =SUM(AO8,AO9) -> 38091.032 | AP7: =SUM(AP8,AP9) -> 37823.768 | AQ7: =SUM(AQ8,AQ9) -> 43249.204 | AR7: =SUM(AR8,AR9) -> 45238.725 | AS7: =SUM(AS8,AS9) -> 51642.304 | AT7: =SUM(AT8,AT9) -> 54312.281 | AU7: =SUM(AU8,AU9) -> 48791.589 | AV7: =SUM(AV8,AV9) -> 46436.351 | ... AZ7: =SUM(AZ8,AZ9) -> 47359.36 | BA7: =SUM(AO7:AZ7) -> 565980.89 | BB7: =SUM(BB8,BB9) -> 43439.109 | BC7: =SUM(BC8,BC9) -> 43156.495 | BD7: =SUM(BD8,BD9) -> 45637.677 | BE7: =SUM(BE8,BE9) -> 55712.548 | BF7: =SUM(BF8,BF9) -> 65538.257 | BG7: =SUM(BG8,BG9) -> 62316.623 | BH7: =SUM(BH8,BH9) -> 56605.858 | BI7: =SUM(BI8,BI9) -> 55149.705 | ... BM7: =SUM(BM8,BM9) -> 51605.006 | BN7: =SUM(BB7:BM7) -> 644679.63 | BO7: =SUM(BO8,BO9) -> 48895.218 | BP7: =SUM(BP8,BP9) -> 47475.876 | BQ7: =SUM(BQ8,BQ9) -> 50609.84 | BR7: =SUM(BR8,BR9) -> 57032.063 | BS7: =SUM(BS8,BS9) -> 61502.711 | BT7: =SUM(BT8,BT9) -> 63105.677 | BU7: =SUM(BU8,BU9) -> 57527.477 | BV7: =SUM(BV8,BV9) -> 64387.702 | ... BZ7: =SUM(BZ8,BZ9) -> 46990.257 | CA7: =SUM(BO7:BZ7) -> 649348.67 | CB7: =SUM(CB8,CB9) -> 47170.727 | CC7: =SUM(CC8,CC9) -> 50765.463 | CD7: =SUM(CD8,CD9) -> 57482.06 | CE7: =SUM(CE8,CE9) -> 65995.589 | CF7: =SUM(CF8,CF9) -> 75124.649 | CG7: =SUM(CG8,CG9) -> 72449.193 | CH7: =SUM(CH8,CH9) -> 70014.362 | CI7: =SUM(CI8,CI9) -> 64187.284 | ... CM7: =SUM(CM8,CM9) -> 59446.82 | CN7: =SUM(CB7:CM7) -> 748934.56 | CO7: =SUM(CO8,CO9) -> 59216.068 | CP7: =SUM(CP8,CP9) -> 53423.636 | CQ7: =SUM(CQ8,CQ9) -> 62239.816 | CR7: =SUM(CR8,CR9) -> 59727.853 | CS7: =SUM(CS8,CS9) -> 80912.127 | CT7: =SUM(CT8,CT9) -> 80897.88 | CU7: =SUM(CU8,CU9) -> 72996.447 | CV7: =SUM(CV8,CV9) -> 76511.922 | ... CZ7: =SUM(CZ8,CZ9) -> 63971.965 | DA7: =SUM(CO7:CZ7) -> 807608.06 | DB7: =SUM(DB8,DB9) -> 56178.83 | DC7: =SUM(DC8,DC9) -> 54121.879 | DD7: =SUM(DD8,DD9) -> 50776.446 | DE7: =SUM(DE8,DE9) -> 56283.124 | DF7: =SUM(DF8,DF9) -> 69655.139 | DG7: =SUM(DG8,DG9) -> 70236.774 | DH7: =SUM(DH8,DH9) -> 79554.611 | DI7: =SUM(DI8,DI9) -> 80042.525 | ... DM7: =SUM(DM8,DM9) -> 48723.482 | DN7: =SUM(DB7:DM7) -> 796977.84 | DO7: =SUM(DO8,DO9) -> 44596.747 | DP7: =SUM(DP8,DP9) -> 46193.9 | DQ7: =SUM(DQ8,DQ9) -> 53305.25 | DR7: =SUM(DR8,DR9) -> 47609.912 | DS7: =SUM(DS8,DS9) -> 43783.763 | DT7: =SUM(DT8,DT9) -> 43510.157 | DU7: =SUM(DU8,DU9) -> 52737.955 | DV7: =SUM(DV8,DV9) -> 76607.234 | ... DZ7: =SUM(DZ8,DZ9) -> 67738.083 | EA7: =SUM(DO7:DZ7) -> 712139.7 | EB7: =SUM(EB8,EB9) -> 59241.238 | EC7: =SUM(EC8,EC9) -> 57605.097 | ED7: =SUM(ED8,ED9) -> 53960.501 | EE7: =SUM(EE8,EE9) -> 39898.6 | EF7: =SUM(EF8,EF9) -> 59990.763 | EG7: =SUM(EG8,EG9) -> 75931.111 | EH7: =SUM(EH8,EH9) -> 64887.604 | EI7: =SUM(EI8,EI9) -> 64464.929 | ... EM7: =SUM(EM8,EM9) -> 65431.101 | EN7: =SUM(EB7:EM7) -> 768387.78 | EO7: =SUM(EO8,EO9) -> 64958.487 | EP7: =SUM(EP8,EP9) -> 60686.13 | EQ7: =SUM(EQ8,EQ9) -> 0 | ER7: =SUM(ER8,ER9) -> 0 | ES7: =SUM(ES8,ES9) -> 0 | ET7: =SUM(ET8,ET9) -> 0 | EU7: =SUM(EU8,EU9) -> 0 | EV7: =SUM(EV8,EV9) -> 0 | ... EZ7: =SUM(EZ8,EZ9) -> 0 | FA7: =SUM(EO7:EZ7) -> 125644.62 | FC7: =IFERROR((( _xlfn.XLOOKUP((DATE(YEAR($FC$5),MONTH($FC$5),1)),UCA.AGRO.DATE,$B7:$FA7) / _xlfn.XLOOKUP((DATE(YEAR($FC$5)-1,MONTH($FC$5),1)),UCA.AGRO.DATE,$B7:$FA7) )-1)*100,"") -> 7.5468804 | FD7: =IFERROR(((FF7/FE7)-1)*100,"") -> 9.0867344 | FE7: =SUMIFS($B7:$FA7,UCA.AGRO.DATE,">="&DATE(YEAR($FC$5)-1,1,1),UCA.AGRO.DATE,"<="&DATE(YEAR($FC$5)-1,MONTH($FC$5),1)) -> 644401.61 | FF7: =SUMIFS($B7:$FA7,UCA.AGRO.DATE,">="&DATE(YEAR($FC$5),1,1),UCA.AGRO.DATE,"<="&$FC$5) -> 702956.68
A8: A. AGRÍCOLA 2/ | B8: 29883.172 | C8: 28378.571 | D8: 31623.204 | E8: 31329.006 | F8: 30331.084 | G8: 30625.279 | H8: 26376.675 | I8: 27475.514 | J8: 34586.142 | K8: 33169.498 | L8: 29859.273 | M8: 29115.883 | N8: =SUM(B8:M8) -> 362753.3 | O8: 27924.724 | P8: 28974.418 | Q8: 32196.367 | R8: 33639.588 | S8: 32050.662 | T8: 32443.696 | U8: 27415.798 | V8: 24619.563 | W8: 28490.211 | X8: 35911.237 | Y8: 27759.485 | Z8: 31367.218 | AA8: =SUM(O8:Z8) -> 362792.97 | AB8: 28290.733 | AC8: 30780.946 | AD8: 36289.579 | AE8: 33061.038 | AF8: 35830.23 | AG8: 36596.366 | AH8: 35268.263 | AI8: 30574.373 | AJ8: 46503.493 | AK8: 50361.462 | AL8: 34738.759 | AM8: 37874.335 | AN8: =SUM(AB8:AM8) -> 436169.58 | AO8: 32923.047 | AP8: 33370.469 | AQ8: 37145.36 | AR8: 38405.828 | AS8: 45242.167 | AT8: 47323.275 | AU8: 42083.49 | AV8: 38094.056 | AW8: 42095.935 | AX8: 45544.921 | AY8: 42738.977 | AZ8: 38000.907 | BA8: =SUM(AO8:AZ8) -> 482968.43 | BB8: 36608.144 | BC8: 37535.891 | BD8: 37835.754 | BE8: 46557.349 | BF8: 56807.001 | BG8: 52978.063 | BH8: 47373.887 | BI8: 44112.879 | BJ8: 43031.247 | BK8: 46755.905 | BL8: 45275.854 | BM8: 39750.015 | BN8: =SUM(BB8:BM8) -> 534621.99 | BO8: 41944.238 | BP8: 41880.075 | BQ8: 42989.731 | BR8: 48147.788 | BS8: 53117.592 | BT8: 53793.559 | BU8: 48341.548 | BV8: 53906.186 | BW8: 48590.393 | BX8: 40383.35 | BY8: 33612.492 | BZ8: 35345.505 | CA8: 542052.46 | CB8: 40216.33 | CC8: 45181.169 | CD8: 50034.979 | CE8: 57152.685 | CF8: 66703.059 | CG8: 63023.896 | CH8: 60826.282 | CI8: 53471.99 | CJ8: 57925.838 | CK8: 51268.725 | CL8: 47203.876 | CM8: 47734.963 | CN8: 640743.79 | CO8: 51955.324 | CP8: 47721.453 | CQ8: 54653.092 | CR8: 50696.902 | CS8: 72398.17 | CT8: 71418.332 | CU8: 63795.708 | CV8: 66017.988 | CW8: 60014.725 | CX8: 57180.356 | CY8: 51685.986 | CZ8: 53133.422 | DA8: 700671.46 | DB8: 48748.373 | DC8: 48302.882 | DD8: 42877.327 | DE8: 47364.358 | DF8: 61117.641 | DG8: 61246.209 | DH8: 70473.413 | DI8: 69272.558 | DJ8: 74834.524 | DK8: 72704.227 | DL8: 53891.175 | DM8: 37433.82 | DN8: 688266.51 | DO8: 37356.337 | DP8: 40520.426 | DQ8: 45389.013 | DR8: 38740.559 | DS8: 35285.942 | DT8: 34541.443 | DU8: 43625.287 | DV8: 65978.968 | DW8: 77187.895 | DX8: 74765.488 | DY8: 53500.297 | DZ8: 56414.372 | EA8: 603306.03 | EB8: 51275.185 | EC8: 51631.624 | ED8: 46044.369 | EE8: 30983.069 | EF8: 51039.16 | EG8: 66133.595 | EH8: 55097.877 | EI8: 53984.891 | EJ8: 74090.531 | EK8: 64085.971 | EL8: 58045.967 | EM8: 54068.817 | EN8: 656481.06 | EO8: 57076.084 | EP8: 54772.647 | FA8: =SUM(EO8:EZ8) -> 111848.73 | FC8: =IFERROR((( _xlfn.XLOOKUP((DATE(YEAR($FC$5),MONTH($FC$5),1)),UCA.AGRO.DATE,$B8:$FA8) / _xlfn.XLOOKUP((DATE(YEAR($FC$5)-1,MONTH($FC$5),1)),UCA.AGRO.DATE,$B8:$FA8) )-1)*100,"") -> 8.4965333 | FD8: =IFERROR(((FF8/FE8)-1)*100,"") -> 10.152026 | FE8: =SUMIFS($B8:$FA8,UCA.AGRO.DATE,">="&DATE(YEAR($FC$5)-1,1,1),UCA.AGRO.DATE,"<="&DATE(YEAR($FC$5)-1,MONTH($FC$5),1)) -> 546891.66 | FF8: =SUMIFS($B8:$FA8,UCA.AGRO.DATE,">="&DATE(YEAR($FC$5),1,1),UCA.AGRO.DATE,"<="&$FC$5) -> 602412.24
A9: B. PECUARIO 2/ | B9: 8877.6564 | C9: 10559.944 | D9: 10337.785 | E9: 10704.762 | F9: 8337.7146 | G9: 7834.1825 | H9: 8030.7867 | I9: 6934.6704 | J9: 6184.3169 | K9: 6465.951 | L9: 6750.4362 | M9: 7242.7736 | N9: =SUM(B9:M9) -> 98260.98 | O9: 5612.0052 | P9: 5457.8123 | Q9: 4772.002 | R9: 5426.3275 | S9: 6853.3666 | T9: 6798.102 | U9: 5858.0832 | V9: 6033.9178 | W9: 5841.6866 | X9: 4971.7449 | Y9: 5595.844 | Z9: 6404.5654 | AA9: =SUM(O9:Z9) -> 69625.458 | AB9: 3990.9389 | AC9: 5773.9382 | AD9: 7004.1844 | AE9: 6521.0175 | AF9: 8001.1465 | AG9: 7646.7612 | AH9: 6790.5446 | AI9: 6148.8409 | AJ9: 6198.1402 | AK9: 5731.3665 | AL9: 5766.2716 | AM9: 6005.8655 | AN9: =SUM(AB9:AM9) -> 75579.016 | AO9: 5167.9856 | AP9: 4453.2985 | AQ9: 6103.8436 | AR9: 6832.8976 | AS9: 6400.1366 | AT9: 6989.0053 | AU9: 6708.0992 | AV9: 8342.2953 | AW9: 6695.9522 | AX9: 8923.3743 | AY9: 7037.1121 | AZ9: 9358.4535 | BA9: =SUM(AO9:AZ9) -> 83012.454 | BB9: 6830.9646 | BC9: 5620.6039 | BD9: 7801.9234 | BE9: 9155.199 | BF9: 8731.2561 | BG9: 9338.5603 | BH9: 9231.9709 | BI9: 11036.826 | BJ9: 9201.457 | BK9: 12157.196 | BL9: 9096.696 | BM9: 11854.991 | BN9: =SUM(BB9:BM9) -> 110057.64 | BO9: 6950.98 | BP9: 5595.8015 | BQ9: 7620.1095 | BR9: 8884.2748 | BS9: 8385.119 | BT9: 9312.1185 | BU9: 9185.9289 | BV9: 10481.515 | BW9: 8831.6796 | BX9: 11688.608 | BY9: 8715.3211 | BZ9: 11644.752 | CA9: 107296.21 | CB9: 6954.3974 | CC9: 5584.2946 | CD9: 7447.0815 | CE9: 8842.9046 | CF9: 8421.5902 | CG9: 9425.2962 | CH9: 9188.0806 | CI9: 10715.294 | CJ9: 9261.9786 | CK9: 11890.964 | CL9: 8747.0284 | CM9: 11711.858 | CN9: 108190.77 | CO9: 7260.7433 | CP9: 5702.1824 | CQ9: 7586.7238 | CR9: 9030.9511 | CS9: 8513.9572 | CT9: 9479.5473 | CU9: 9200.7392 | CV9: 10493.934 | CW9: 8950.958 | CX9: 11596.605 | CY9: 8281.7126 | CZ9: 10838.542 | DA9: 106936.6 | DB9: 7430.4569 | DC9: 5818.9961 | DD9: 7899.1191 | DE9: 8918.7654 | DF9: 8537.4979 | DG9: 8990.5659 | DH9: 9081.1985 | DI9: 10769.966 | DJ9: 9416.3988 | DK9: 11818.476 | DL9: 8740.2313 | DM9: 11289.662 | DN9: 108711.33 | DO9: 7240.4102 | DP9: 5673.4733 | DQ9: 7916.2369 | DR9: 8869.3528 | DS9: 8497.821 | DT9: 8968.7135 | DU9: 9112.6688 | DV9: 10628.267 | DW9: 9516.7815 | DX9: 12271.567 | DY9: 8814.6684 | DZ9: 11323.711 | EA9: 108833.67 | EB9: 7966.0536 | EC9: 5973.4739 | ED9: 7916.1321 | EE9: 8915.5308 | EF9: 8951.6026 | EG9: 9797.5165 | EH9: 9789.7266 | EI9: 10480.039 | EJ9: 9483.5309 | EK9: 12299 | EL9: 8971.8337 | EM9: 11362.285 | EN9: 111906.72 | EO9: 7882.4032 | EP9: 5913.4839 | FA9: =SUM(EO9:EZ9) -> 13795.887 | FC9: =IFERROR((( _xlfn.XLOOKUP((DATE(YEAR($FC$5),MONTH($FC$5),1)),UCA.AGRO.DATE,$B9:$FA9) / _xlfn.XLOOKUP((DATE(YEAR($FC$5)-1,MONTH($FC$5),1)),UCA.AGRO.DATE,$B9:$FA9) )-1)*100,"") -> 1.7829978 | FD9: =IFERROR(((FF9/FE9)-1)*100,"") -> 3.1119692 | FE9: =SUMIFS($B9:$FA9,UCA.AGRO.DATE,">="&DATE(YEAR($FC$5)-1,1,1),UCA.AGRO.DATE,"<="&DATE(YEAR($FC$5)-1,MONTH($FC$5),1)) -> 97509.96 | FF9: =SUMIFS($B9:$FA9,UCA.AGRO.DATE,">="&DATE(YEAR($FC$5),1,1),UCA.AGRO.DATE,"<="&$FC$5) -> 100544.44
A11: TOTAL AGRÍCOLA | B11: =SUM(B13:B37,B39) -> 80334 | C11: =SUM(C13:C37,C39) -> 76800 | D11: =SUM(D13:D37,D39) -> 72549 | E11: =SUM(E13:E37,E39) -> 69152 | F11: =SUM(F13:F37,F39) -> 65836 | G11: =SUM(G13:G37,G39) -> 64809 | H11: =SUM(H13:H37,H39) -> 56715 | I11: =SUM(I13:I37,I39) -> 65295 | ... M11: =SUM(M13:M37,M39) -> 77153 | N11: =SUM(B11:M11) -> 859583 | O11: =SUM(O13:O37,O39) -> 75698 | P11: =SUM(P13:P37,P39) -> 81263 | Q11: =SUM(Q13:Q37,Q39) -> 78146 | R11: =SUM(R13:R37,R39) -> 73764 | S11: =SUM(S13:S37,S39) -> 67317 | T11: =SUM(T13:T37,T39) -> 64535 | U11: =SUM(U13:U37,U39) -> 52501 | V11: =SUM(V13:V37,V39) -> 58615 | ... Z11: =SUM(Z13:Z37,Z39) -> 80276 | AA11: =SUM(O11:Z11) -> 849920 | AB11: =SUM(AB13:AB37,AB39) -> 76851 | AC11: =SUM(AC13:AC37,AC39) -> 83617 | AD11: =SUM(AD13:AD37,AD39) -> 88568 | AE11: =SUM(AE13:AE37,AE39) -> 73209 | AF11: =SUM(AF13:AF37,AF39) -> 73805 | AG11: =SUM(AG13:AG37,AG39) -> 68430 | AH11: =SUM(AH13:AH37,AH39) -> 63946 | AI11: =SUM(AI13:AI37,AI39) -> 69059 | ... AM11: =SUM(AM13:AM37,AM39) -> 82897 | AN11: =SUM(AB11:AM11) -> 947850 | AO11: =SUM(AO13:AO37,AO39) -> 82918 | AP11: =SUM(AP13:AP37,AP39) -> 85528 | AQ11: =SUM(AQ13:AQ37,AQ39) -> 89223 | AR11: =SUM(AR13:AR37,AR39) -> 85194 | AS11: =SUM(AS13:AS37,AS39) -> 76662 | AT11: =SUM(AT13:AT37,AT39) -> 71934 | AU11: =SUM(AU13:AU37,AU39) -> 72244 | AV11: =SUM(AV13:AV37,AV39) -> 82500 | ... AZ11: =SUM(AZ13:AZ37,AZ39) -> 86391 | BA11: =SUM(AO11:AZ11) -> 1005868 | BB11: =SUM(BB13:BB37,BB39) -> 87135 | BC11: =SUM(BC13:BC37,BC39) -> 90291 | BD11: =SUM(BD13:BD37,BD39) -> 90617 | BE11: =SUM(BE13:BE37,BE39) -> 87889 | BF11: =SUM(BF13:BF37,BF39) -> 89557 | BG11: =SUM(BG13:BG37,BG39) -> 78136 | BH11: =SUM(BH13:BH37,BH39) -> 74137 | BI11: =SUM(BI13:BI37,BI39) -> 76128 | ... BM11: =SUM(BM13:BM37,BM39) -> 88968 | BN11: =SUM(BB11:BM11) -> 1045646 | BO11: =SUM(BO13:BO37,BO39) -> 97164.962 | BP11: =SUM(BP13:BP37,BP39) -> 100093.17 | BQ11: =SUM(BQ13:BQ37,BQ39) -> 100404.42 | BR11: =SUM(BR13:BR37,BR39) -> 88074.423 | BS11: =SUM(BS13:BS37,BS39) -> 81644.33 | BT11: =SUM(BT13:BT37,BT39) -> 76574.021 | BU11: =SUM(BU13:BU37,BU39) -> 76409.869 | BV11: =SUM(BV13:BV37,BV39) -> 89392.072 | ... BZ11: =SUM(BZ13:BZ37,BZ39) -> 86754.404 | CA11: =SUM(BO11:BZ11) -> 1066289 | CB11: =SUM(CB13:CB37,CB39) -> 102106.48 | CC11: =SUM(CC13:CC37,CC39) -> 115151.82 | CD11: =SUM(CD13:CD37,CD39) -> 124556.01 | CE11: =SUM(CE13:CE37,CE39) -> 120500.24 | CF11: =SUM(CF13:CF37,CF39) -> 115840.37 | CG11: =SUM(CG13:CG37,CG39) -> 102427.78 | CH11: =SUM(CH13:CH37,CH39) -> 101129.93 | CI11: =SUM(CI13:CI37,CI39) -> 104405.33 | ... CM11: =SUM(CM13:CM37,CM39) -> 116348.22 | CN11: =SUM(CB11:CM11) -> 1380257.1 | CO11: =SUM(CO13:CO37,CO39) -> 122169.11 | CP11: =SUM(CP13:CP37,CP39) -> 119559.94 | CQ11: =SUM(CQ13:CQ37,CQ39) -> 133497.38 | CR11: =SUM(CR13:CR37,CR39) -> 116109.34 | CS11: =SUM(CS13:CS37,CS39) -> 125411.45 | CT11: =SUM(CT13:CT37,CT39) -> 113309.27 | CU11: =SUM(CU13:CU37,CU39) -> 100469.12 | CV11: =SUM(CV13:CV37,CV39) -> 128022.17 | ... CZ11: =SUM(CZ13:CZ37,CZ39) -> 138250.07 | DA11: =SUM(CO11:CZ11) -> 1489137.7 | DB11: =SUM(DB13:DB37,DB39) -> 125194.14 | DC11: =SUM(DC13:DC37,DC39) -> 125669.53 | DD11: =SUM(DD13:DD37,DD39) -> 112251.98 | DE11: =SUM(DE13:DE37,DE39) -> 108900.89 | DF11: =SUM(DF13:DF37,DF39) -> 117667.26 | DG11: =SUM(DG13:DG37,DG39) -> 109719.62 | DH11: =SUM(DH13:DH37,DH39) -> 115109.51 | DI11: =SUM(DI13:DI37,DI39) -> 120214.1 | ... DM11: =SUM(DM13:DM37,DM39) -> 105488.58 | DN11: =SUM(DB11:DM11) -> 1491728.1 | DO11: =SUM(DO13:DO37,DO39) -> 100343.56 | DP11: =SUM(DP13:DP37,DP39) -> 103578.87 | DQ11: =SUM(DQ13:DQ37,DQ39) -> 111402.71 | DR11: =SUM(DR13:DR37,DR39) -> 100322.95 | DS11: =SUM(DS13:DS37,DS39) -> 88667.193 | DT11: =SUM(DT13:DT37,DT39) -> 80964.668 | DU11: =SUM(DU13:DU37,DU39) -> 103704.46 | DV11: =SUM(DV13:DV37,DV39) -> 141854.63 | ... DZ11: =SUM(DZ13:DZ37,DZ39) -> 128679.6 | EA11: =SUM(DO11:DZ11) -> 1429919.8 | EB11: =SUM(EB13:EB37,EB39) -> 115155.7 | EC11: =SUM(EC13:EC37,EC39) -> 119135.65 | ED11: =SUM(ED13:ED37,ED39) -> 109168.43 | EE11: =SUM(EE13:EE37,EE39) -> 81000.748 | EF11: =SUM(EF13:EF37,EF39) -> 105208.94 | EG11: =SUM(EG13:EG37,EG39) -> 114925.36 | EH11: =SUM(EH13:EH37,EH39) -> 96222.423 | EI11: =SUM(EI13:EI37,EI39) -> 111212.84 | ... EM11: =SUM(EM13:EM37,EM39) -> 142342.11 | EN11: =SUM(EB11:EM11) -> 1444988.2 | EO11: =SUM(EO13:EO37,EO39) -> 136460.79 | EP11: =SUM(EP13:EP37,EP39) -> 137830.45 | EQ11: =SUM(EQ13:EQ37,EQ39) -> 0 | ER11: =SUM(ER13:ER37,ER39) -> 0 | ES11: =SUM(ES13:ES37,ES39) -> 0 | ET11: =SUM(ET13:ET37,ET39) -> 0 | EU11: =SUM(EU13:EU37,EU39) -> 0 | EV11: =SUM(EV13:EV37,EV39) -> 0 | ... EZ11: =SUM(EZ13:EZ37,EZ39) -> 0 | FA11: =SUM(EO11:EZ11) -> 274291.24 | FC11: =IFERROR((( _xlfn.XLOOKUP((DATE(YEAR($FC$5),MONTH($FC$5),1)),UCA.AGRO.DATE,$B11:$FA11) / _xlfn.XLOOKUP((DATE(YEAR($FC$5)-1,MONTH($FC$5),1)),UCA.AGRO.DATE,$B11:$FA11) )-1)*100,"") -> 9.0909624 | FD11: =IFERROR(((FF11/FE11)-1)*100,"") -> 0.10804592 | FE11: =SUMIFS($B11:$FA11,UCA.AGRO.DATE,">="&DATE(YEAR($FC$5)-1,1,1),UCA.AGRO.DATE,"<="&DATE(YEAR($FC$5)-1,MONTH($FC$5),1)) -> 1301240.2 | FF11: =SUMIFS($B11:$FA11,UCA.AGRO.DATE,">="&DATE(YEAR($FC$5),1,1),UCA.AGRO.DATE,"<="&$FC$5) -> 1302646.1
A13: Arroz Cáscara | B13: 1841 | C13: 1820 | D13: 1274 | E13: 1885 | F13: 1253 | G13: 2126 | H13: 658 | I13: 2994 | J13: 4141 | K13: 4247 | L13: 1767 | M13: 2723 | N13: =SUM(B13:M13) -> 26729 | O13: 2352 | P13: 1985 | Q13: 1895 | R13: 1590 | S13: 660 | T13: 1466 | U13: 1026 | V13: 2688 | W13: 3657 | X13: 4873 | Y13: 2403 | Z13: 2339 | AA13: =SUM(O13:Z13) -> 26934 | AB13: 2184 | AC13: 3217 | AD13: 2898 | AE13: 2489 | AF13: 2776 | AG13: 3713 | AH13: 5586 | AI13: 3797 | AJ13: 16239 | AK13: 14475 | AL13: 5286 | AM13: 3538 | AN13: =SUM(AB13:AM13) -> 66198 | AO13: 2324 | AP13: 2720 | AQ13: 2972 | AR13: 3544 | AS13: 4972 | AT13: 3660 | AU13: 4083 | AV13: 4839 | AW13: 9903 | AX13: 8252 | AY13: 8440 | AZ13: 3887 | BA13: =SUM(AO13:AZ13) -> 59596 | BB13: 3645 | BC13: 4868 | BD13: 2081 | BE13: 4076 | BF13: 11337 | BG13: 7788 | BH13: 9707 | BI13: 10133 | BJ13: 10945 | BK13: 7831 | BL13: 12098 | BM13: 4945 | BN13: =SUM(BB13:BM13) -> 89454 | BO13: 6286.438 | BP13: 4747.04 | BQ13: 5497.84 | BR13: 9327.969 | BS13: 4191.779 | BT13: 5715.925 | BU13: 2767.75 | BV13: 5303.86 | BW13: 7985.358 | BX13: 5190.058 | BY13: 4574.94 | BZ13: 4651.689 | CA13: 66240.646 | CB13: 6179.609 | CC13: 6740.98 | CD13: 9133.519 | CE13: 9075.02 | CF13: 2596.18 | CG13: 2351.12 | CH13: 5026.34 | CI13: 4626.689 | CJ13: 6958.6 | CK13: 4962.62 | CL13: 2954.47 | CM13: 6522.909 | CN13: 67128.056 | CO13: 15084.36 | CP13: 10863.09 | CQ13: 15999.81 | CR13: 2769.288 | CS13: 5591.67 | CT13: 3736.74 | CU13: 4141.94 | CV13: 7316.6 | CW13: 9645.13 | CX13: 11757.82 | CY13: 10080.44 | CZ13: 7555.42 | DA13: 104542.31 | DB13: 7154.52 | DC13: 10297.78 | DD13: 8796.61 | DE13: 10941.62 | DF13: 7708.53 | DG13: 2624.32 | DH13: 8922.98 | DI13: 7237.039 | DJ13: 13351.195 | DK13: 18811.938 | DL13: 11534.86 | DM13: 4503.759 | DN13: 111885.15 | DO13: 6373.139 | DP13: 9957.99 | DQ13: 16534.459 | DR13: 8751.649 | DS13: 7995.54 | DT13: 5028.879 | DU13: 5939.62 | DV13: 12793.679 | DW13: 21474.989 | DX13: 16753.479 | DY13: 9413.05 | DZ13: 18757.409 | EA13: 139773.88 | EB13: 17796.938 | EC13: 20937.582 | ED13: 18390.61 | EE13: 3016.85 | EF13: 1704.266 | EG13: 4875.639 | EH13: 3603.53 | EI13: 2651.054 | EJ13: 14715.625 | EK13: 11233.379 | EL13: 7978.438 | EM13: 6788.77 | EN13: 113692.68 | EO13: 10933.929 | EP13: 11590.195 | FA13: =SUM(EO13:EZ13) -> 22524.124 | FC13: =IFERROR((( _xlfn.XLOOKUP((DATE(YEAR($FC$5),MONTH($FC$5),1)),UCA.AGRO.DATE,$B13:$FA13) / _xlfn.XLOOKUP((DATE(YEAR($FC$5)-1,MONTH($FC$5),1)),UCA.AGRO.DATE,$B13:$FA13) )-1)*100,"") -> -15.240671 | FD13: =IFERROR(((FF13/FE13)-1)*100,"") -> -11.661687 | FE13: =SUMIFS($B13:$FA13,UCA.AGRO.DATE,">="&DATE(YEAR($FC$5)-1,1,1),UCA.AGRO.DATE,"<="&DATE(YEAR($FC$5)-1,MONTH($FC$5),1)) -> 121016.47 | FF13: =SUMIFS($B13:$FA13,UCA.AGRO.DATE,">="&DATE(YEAR($FC$5),1,1),UCA.AGRO.DATE,"<="&$FC$5) -> 106903.91 | FH13: =SUM(B13:FA13) -> 1789395.7 | FI13: Arroz Cáscara | FJ13: =IF(EXACT(A13,FI13)=TRUE,"OK","VER") -> OK
A14: Cacao | B14: 411 | C14: 491 | D14: 519 | E14: 539 | F14: 581 | G14: 633 | H14: 687 | I14: 736 | J14: 773 | K14: 588 | L14: 415 | M14: 332 | N14: =SUM(B14:M14) -> 6705 | O14: 214 | P14: 250 | Q14: 534 | R14: 1198 | S14: 1174 | T14: 1257 | U14: 966 | V14: 638 | W14: 587 | X14: 653 | Y14: 550 | Z14: 602 | AA14: =SUM(O14:Z14) -> 8623 | AB14: 286 | AC14: 320 | AD14: 891 | AE14: 1218 | AF14: 1366 | AG14: 1751 | AH14: 1365 | AI14: 1026 | AJ14: 1149 | AK14: 1042 | AL14: 1140 | AM14: 1690 | AN14: =SUM(AB14:AM14) -> 13244 | AO14: 828 | AP14: 800 | AQ14: 897 | AR14: 1250 | AS14: 1661 | AT14: 1752 | AU14: 1650 | AV14: 1676 | AW14: 1591 | AX14: 1658 | AY14: 1446 | AZ14: 1377 | BA14: =SUM(AO14:AZ14) -> 16586 | BB14: 1217 | BC14: 1193 | BD14: 1327 | BE14: 1383 | BF14: 1634 | BG14: 1785 | BH14: 1426 | BI14: 1306 | BJ14: 1518 | BK14: 1578 | BL14: 1211 | BM14: 1453 | BN14: =SUM(BB14:BM14) -> 17031 | BO14: 1283.544 | BP14: 1357.009 | BQ14: 1391.53 | BR14: 2395.879 | BS14: 3055.638 | BT14: 3058.83 | BU14: 2373.86 | BV14: 1997.128 | BW14: 1973.789 | BX14: 1374.058 | BY14: 648.049 | BZ14: 795.975 | CA14: 21705.289 | CB14: 552.937 | CC14: 787.479 | CD14: 818.099 | CE14: 1944.898 | CF14: 3101.21 | CG14: 3132.847 | CH14: 2643 | CI14: 1742.243 | CJ14: 1704.8 | CK14: 1389.239 | CL14: 1219.79 | CM14: 1009.889 | CN14: 20046.431 | CO14: 648.04 | CP14: 564.789 | CQ14: 433.919 | CR14: 1971.18 | CS14: 4015.63 | CT14: 4480.25 | CU14: 4125.838 | CV14: 2622.708 | CW14: 1784.84 | CX14: 1047.989 | CY14: 639.679 | CZ14: 389.159 | DA14: 22724.021 | DB14: 325.85 | DC14: 228.143 | DD14: 180.686 | DE14: 899.543 | DF14: 2864.789 | DG14: 3273.029 | DH14: 3776.82 | DI14: 3103.518 | DJ14: 2333.805 | DK14: 1291.666 | DL14: 450.78 | DM14: 157.99 | DN14: 18886.619 | DO14: 102.887 | DP14: 70.424 | DQ14: 39.182 | DR14: 26.613 | DS14: 128.487 | DT14: 545.629 | DU14: 944.228 | DV14: 2017.467 | DW14: 2079.959 | DX14: 1288.754 | DY14: 532.659 | DZ14: 275.19 | EA14: 8051.479 | EB14: 134.3 | EC14: 90.36 | ED14: 55.283 | EE14: 30.898 | EF14: 2420.294 | EG14: 3875.167 | EH14: 3298.529 | EI14: 2347.738 | EJ14: 1726.515 | EK14: 1379.355 | EL14: 974.475 | EM14: 714.816 | EN14: 17047.73 | EO14: 160.22 | EP14: 103.486 | FA14: =SUM(EO14:EZ14) -> 263.706 | FC14: =IFERROR((( _xlfn.XLOOKUP((DATE(YEAR($FC$5),MONTH($FC$5),1)),UCA.AGRO.DATE,$B14:$FA14) / _xlfn.XLOOKUP((DATE(YEAR($FC$5)-1,MONTH($FC$5),1)),UCA.AGRO.DATE,$B14:$FA14) )-1)*100,"") -> 82.945374 | FD14: =IFERROR(((FF14/FE14)-1)*100,"") -> 110.03481 | FE14: =SUMIFS($B14:$FA14,UCA.AGRO.DATE,">="&DATE(YEAR($FC$5)-1,1,1),UCA.AGRO.DATE,"<="&DATE(YEAR($FC$5)-1,MONTH($FC$5),1)) -> 7776.289 | FF14: =SUMIFS($B14:$FA14,UCA.AGRO.DATE,">="&DATE(YEAR($FC$5),1,1),UCA.AGRO.DATE,"<="&$FC$5) -> 16332.914 | FH14: =SUM(B14:FA14) -> 341828.55 | FI14: Cacao | FJ14: =IF(EXACT(A14,FI14)=TRUE,"OK","VER") -> OK
A15: Café | D15: 1054 | E15: 1150 | F15: 1205 | G15: 1155 | H15: 878 | N15: =SUM(B15:M15) -> 5442 | Q15: 713 | R15: 709 | S15: 932 | T15: 1017 | U15: 1158 | AA15: =SUM(O15:Z15) -> 4529 | AD15: 430 | AE15: 551 | AF15: 929 | AG15: 925 | AH15: 1169 | AN15: =SUM(AB15:AM15) -> 4004 | AQ15: 456 | AR15: 583 | AS15: 2256 | AT15: 3098 | AU15: 1933 | BA15: =SUM(AO15:AZ15) -> 8326 | BD15: 124 | BE15: 2010 | BF15: 3168 | BG15: 3423 | BH15: 2555 | BI15: 1724 | BJ15: 619 | BN15: =SUM(BB15:BM15) -> 13623 | BQ15: 35.77 | BR15: 577.91 | BS15: 2085.499 | BT15: 2523.475 | BU15: 2398.546 | BV15: 2540.08 | BW15: 806.4 | CA15: 10967.68 | CD15: 199.8 | CE15: 918.328 | CF15: 2941.363 | CG15: 3126.867 | CH15: 2899.791 | CI15: 1853.18 | CJ15: 719.5 | CN15: 12658.829 | CQ15: 86.5 | CR15: 507.38 | CS15: 2228.134 | CT15: 2576.233 | CU15: 2192.38 | CV15: 1886.319 | CW15: 1217.75 | CX15: 48.52 | DA15: 10743.216 | DE15: 288.86 | DF15: 1072.38 | DG15: 1867.68 | DH15: 2419.75 | DI15: 2627.75 | DJ15: 1718.63 | DN15: 9995.05 | DO15: 0 | DP15: 0 | DQ15: 0 | DR15: 340.24 | DS15: 385.45 | DT15: 550.34 | DU15: 575.1 | DV15: 943.09 | DW15: 542.88 | DX15: 0 | DY15: 0 | DZ15: 0 | EA15: 3337.1 | EB15: 0 | EC15: 0 | ED15: 0 | EE15: 621.16 | EF15: 949.05 | EG15: 1662.09 | EH15: 1429.56 | EI15: 1178.05 | EJ15: 891.11 | EK15: 0 | EL15: 0 | EM15: 0 | EN15: 6731.02 | EO15: 0 | EP15: 0 | FA15: =SUM(EO15:EZ15) -> 0 | FC15: =IFERROR((( _xlfn.XLOOKUP((DATE(YEAR($FC$5),MONTH($FC$5),1)),UCA.AGRO.DATE,$B15:$FA15) / _xlfn.XLOOKUP((DATE(YEAR($FC$5)-1,MONTH($FC$5),1)),UCA.AGRO.DATE,$B15:$FA15) )-1)*100,"") | FD15: =IFERROR(((FF15/FE15)-1)*100,"") -> 101.70268 | FE15: =SUMIFS($B15:$FA15,UCA.AGRO.DATE,">="&DATE(YEAR($FC$5)-1,1,1),UCA.AGRO.DATE,"<="&DATE(YEAR($FC$5)-1,MONTH($FC$5),1)) -> 3337.1 | FF15: =SUMIFS($B15:$FA15,UCA.AGRO.DATE,">="&DATE(YEAR($FC$5),1,1),UCA.AGRO.DATE,"<="&$FC$5) -> 6731.02 | FH15: =SUM(B15:FA15) -> 180713.79 | FI15: Café | FJ15: =IF(EXACT(A15,FI15)=TRUE,"OK","VER") -> OK
A16: Camu Camu | B16: 251 | C16: 253 | D16: 260 | E16: 137 | F16: 152 | G16: 89 | H16: 53 | I16: 24 | J16: 33 | K16: 36 | L16: 51 | M16: 61 | N16: =SUM(B16:M16) -> 1400 | O16: 162 | P16: 114 | Q16: 318 | R16: 216 | S16: 286 | T16: 171 | U16: 59 | V16: 11 | W16: 21 | X16: 29 | Y16: 47 | Z16: 59 | AA16: =SUM(O16:Z16) -> 1493 | AB16: 172 | AC16: 194 | AD16: 280 | AE16: 242 | AF16: 325 | AG16: 41 | AH16: 6 | AI16: 6 | AJ16: 33 | AK16: 34 | AL16: 59 | AM16: 90 | AN16: =SUM(AB16:AM16) -> 1482 | AO16: 197 | AP16: 241 | AQ16: 290 | AR16: 381 | AS16: 265 | AT16: 46 | AU16: 10 | AV16: 13 | AW16: 38 | AX16: 36 | AY16: 71 | AZ16: 1638 | BA16: =SUM(AO16:AZ16) -> 3226 | BB16: 81 | BC16: 106 | BD16: 483 | BE16: 338 | BF16: 98 | BG16: 19 | BH16: 5 | BI16: 11 | BJ16: 32 | BK16: 137 | BL16: 117 | BM16: 206 | BN16: =SUM(BB16:BM16) -> 1633 | BO16: 121 | BP16: 185 | BQ16: 515 | BR16: 410 | BS16: 228.809 | BT16: 96 | BU16: 20 | BV16: 60 | BW16: 44 | BX16: 87 | BY16: 7 | BZ16: 149 | CA16: 1922.809 | CB16: 74.51 | CC16: 86.439 | CD16: 157.999 | CE16: 435.59 | CF16: 363.16 | CG16: 176.67 | CH16: 71.718 | CI16: 92.5 | CJ16: 75.45 | CK16: 141.628 | CL16: 66.57 | CM16: 262.35 | CN16: 2004.584 | CO16: 205.229 | CP16: 126.339 | CQ16: 381.518 | CR16: 382.16 | CS16: 298.529 | CT16: 213.54 | CU16: 104.94 | CV16: 69.519 | CW16: 36.85 | CX16: 76.48 | CY16: 112.96 | CZ16: 414.15 | DA16: 2422.214 | DB16: 297.2 | DC16: 163.703 | DD16: 169.32 | DE16: 219.87 | DF16: 108.3 | DG16: 84.87 | DH16: 20.05 | DI16: 23.5 | DJ16: 15.74 | DK16: 51.59 | DL16: 76.269 | DM16: 60.318 | DN16: 1290.73 | DO16: 65.75 | DP16: 105.46 | DQ16: 138.269 | DR16: 183.17 | DS16: 192.18 | DT16: 80.17 | DU16: 27.63 | DV16: 29.34 | DW16: 19.47 | DX16: 37.279 | DY16: 106.51 | DZ16: 128.44 | EA16: 1113.668 | EB16: 117.319 | EC16: 68 | ED16: 19.159 | EE16: 17.802 | EF16: 119.279 | EG16: 104.19 | EH16: 57.34 | EI16: 44.22 | EJ16: 19.47 | EK16: 45.16 | EL16: 449.81 | EM16: 479.77 | EN16: 1541.519 | EO16: 267.569 | EP16: 158.187 | FA16: =SUM(EO16:EZ16) -> 425.756 | FC16: =IFERROR((( _xlfn.XLOOKUP((DATE(YEAR($FC$5),MONTH($FC$5),1)),UCA.AGRO.DATE,$B16:$FA16) / _xlfn.XLOOKUP((DATE(YEAR($FC$5)-1,MONTH($FC$5),1)),UCA.AGRO.DATE,$B16:$FA16) )-1)*100,"") -> 322.31715 | FD16: =IFERROR(((FF16/FE16)-1)*100,"") -> 7.7668316 | FE16: =SUMIFS($B16:$FA16,UCA.AGRO.DATE,">="&DATE(YEAR($FC$5)-1,1,1),UCA.AGRO.DATE,"<="&DATE(YEAR($FC$5)-1,MONTH($FC$5),1)) -> 985.228 | FF16: =SUMIFS($B16:$FA16,UCA.AGRO.DATE,">="&DATE(YEAR($FC$5),1,1),UCA.AGRO.DATE,"<="&$FC$5) -> 1061.749 | FH16: =SUM(B16:FA16) -> 39910.56 | FI16: Camu Camu | FJ16: =IF(EXACT(A16,FI16)=TRUE,"OK","VER") -> OK
A17: Caña de Azúcar | B17: 2264 | C17: 2353 | D17: 1959 | E17: 2284 | F17: 1808 | G17: 1805 | H17: 1785 | I17: 1951 | J17: 1913 | K17: 1919 | L17: 2058 | M17: 2114 | N17: =SUM(B17:M17) -> 24213 | O17: 1579 | P17: 1777 | Q17: 1728 | R17: 1575 | S17: 1544 | T17: 1535 | U17: 1372 | V17: 1229 | W17: 1215 | X17: 1323 | Y17: 1463 | Z17: 1622 | AA17: =SUM(O17:Z17) -> 17962 | AB17: 1533 | AC17: 1456 | AD17: 1326 | AE17: 1102 | AF17: 1030 | AG17: 1192 | AH17: 968 | AI17: 711 | AJ17: 733 | AK17: 772 | AL17: 895 | AM17: 1025 | AN17: =SUM(AB17:AM17) -> 12743 | AO17: 930 | AP17: 926 | AQ17: 1082 | AR17: 844 | AS17: 901 | AT17: 837 | AU17: 727 | AV17: 687 | AW17: 674 | AX17: 688 | AY17: 638 | AZ17: 726 | BA17: =SUM(AO17:AZ17) -> 9660 | BB17: 646 | BC17: 853 | BD17: 800 | BE17: 664 | BF17: 621 | BG17: 537 | BH17: 691 | BI17: 717 | BJ17: 627 | BK17: 652 | BL17: 545 | BM17: 782 | BN17: =SUM(BB17:BM17) -> 8135 | BO17: 772 | BP17: 1019 | BQ17: 970 | BR17: 1088 | BS17: 1295.67 | BT17: 1247 | BU17: 1193 | BV17: 1100 | BW17: 998 | BX17: 1095 | BY17: 1007 | BZ17: 1051 | CA17: 12835.67 | CB17: 902.256 | CC17: 972.949 | CD17: 1657.45 | CE17: 2057.827 | CF17: 2433.46 | CG17: 2364.729 | CH17: 1978.02 | CI17: 1716.739 | CJ17: 1954.329 | CK17: 1858.389 | CL17: 1909.266 | CM17: 1699.479 | CN17: 21504.893 | CO17: 1437.618 | CP17: 580.677 | CQ17: 645.009 | CR17: 1182.067 | CS17: 1688.549 | CT17: 2302.199 | CU17: 2409.73 | CV17: 1901.009 | CW17: 1714.226 | CX17: 1470.469 | CY17: 1255.28 | CZ17: 1367.303 | DA17: 17954.136 | DB17: 1194.55 | DC17: 380.249 | DD17: 292.9 | DE17: 470.549 | DF17: 664.089 | DG17: 1230.199 | DH17: 1636.709 | DI17: 1817.788 | DJ17: 1823.999 | DK17: 1589.688 | DL17: 1113.986 | DM17: 539.58 | DN17: 12754.286 | DO17: 361.469 | DP17: 256.667 | DQ17: 161.519 | DR17: 102.193 | DS17: 182.549 | DT17: 302.096 | DU17: 483.829 | DV17: 1134.717 | DW17: 1168.164 | DX17: 1161.219 | DY17: 733.6 | DZ17: 490.017 | EA17: 6538.039 | EB17: 335.069 | EC17: 227.178 | ED17: 128.387 | EE17: 81.034 | EF17: 225.807 | EG17: 336.857 | EH17: 392.7 | EI17: 398.568 | EJ17: 425.069 | EK17: 474.186 | EL17: 539.307 | EM17: 529.056 | EN17: 4093.218 | EO17: 447.624 | EP17: 323.507 | FA17: =SUM(EO17:EZ17) -> 771.131 | FC17: =IFERROR((( _xlfn.XLOOKUP((DATE(YEAR($FC$5),MONTH($FC$5),1)),UCA.AGRO.DATE,$B17:$FA17) / _xlfn.XLOOKUP((DATE(YEAR($FC$5)-1,MONTH($FC$5),1)),UCA.AGRO.DATE,$B17:$FA17) )-1)*100,"") -> -26.484869 | FD17: =IFERROR(((FF17/FE17)-1)*100,"") -> -41.068964 | FE17: =SUMIFS($B17:$FA17,UCA.AGRO.DATE,">="&DATE(YEAR($FC$5)-1,1,1),UCA.AGRO.DATE,"<="&DATE(YEAR($FC$5)-1,MONTH($FC$5),1)) -> 6048.022 | FF17: =SUMIFS($B17:$FA17,UCA.AGRO.DATE,">="&DATE(YEAR($FC$5),1,1),UCA.AGRO.DATE,"<="&$FC$5) -> 3564.162 | FH17: =SUM(B17:FA17) -> 298328.75 | FI17: Caña de Azúcar | FJ17: =IF(EXACT(A17,FI17)=TRUE,"OK","VER") -> OK
A18: Cocotero | B18: 385 | C18: 401 | D18: 401 | E18: 363 | F18: 410 | G18: 408 | H18: 428 | I18: 469 | J18: 484 | K18: 471 | L18: 478 | M18: 491 | N18: =SUM(B18:M18) -> 5189 | O18: 447 | P18: 435 | Q18: 460 | R18: 436 | S18: 453 | T18: 466 | U18: 450 | V18: 425 | W18: 418 | X18: 451 | Y18: 445 | Z18: 492 | AA18: =SUM(O18:Z18) -> 5378 | AB18: 450 | AC18: 480 | AD18: 506 | AE18: 525 | AF18: 549 | AG18: 557 | AH18: 554 | AI18: 546 | AJ18: 597 | AK18: 635 | AL18: 642 | AM18: 729 | AN18: =SUM(AB18:AM18) -> 6770 | AO18: 559 | AP18: 583 | AQ18: 611 | AR18: 656 | AS18: 683 | AT18: 728 | AU18: 745 | AV18: 764 | AW18: 799 | AX18: 816 | AY18: 826 | AZ18: 784 | BA18: =SUM(AO18:AZ18) -> 8554 | BB18: 840 | BC18: 862 | BD18: 875 | BE18: 867 | BF18: 864 | BG18: 887 | BH18: 893 | BI18: 896 | BJ18: 911 | BK18: 916 | BL18: 924 | BM18: 938 | BN18: =SUM(BB18:BM18) -> 10673 | BO18: 922 | BP18: 949 | BQ18: 931 | BR18: 950 | BS18: 952.029 | BT18: 955 | BU18: 946 | BV18: 974 | BW18: 994 | BX18: 1024 | BY18: 1020 | BZ18: 1066 | CA18: 11683.029 | CB18: 926.57 | CC18: 964.229 | CD18: 970.88 | CE18: 986.248 | CF18: 1029.958 | CG18: 1019.43 | CH18: 1012.629 | CI18: 989.259 | CJ18: 1028.089 | CK18: 1046.519 | CL18: 1020.049 | CM18: 1062.15 | CN18: 12056.01 | CO18: 930.75 | CP18: 981.7 | CQ18: 926.978 | CR18: 936.809 | CS18: 991.778 | CT18: 1020.579 | CU18: 1041.589 | CV18: 1123.63 | CW18: 1102.881 | CX18: 1106.65 | CY18: 1080.28 | CZ18: 1092.429 | DA18: 12336.053 | DB18: 1042.61 | DC18: 1017.64 | DD18: 988.84 | DE18: 998.489 | DF18: 1013.96 | DG18: 1057.145 | DH18: 1070.06 | DI18: 1079.367 | DJ18: 1084.42 | DK18: 1092.647 | DL18: 1098.978 | DM18: 1102.239 | DN18: 12646.395 | DO18: 1098.705 | DP18: 1081.979 | DQ18: 1080.699 | DR18: 1027.299 | DS18: 1043.609 | DT18: 1043.154 | DU18: 1048.25 | DV18: 1052.497 | DW18: 1051.409 | DX18: 1053.451 | DY18: 1055.829 | DZ18: 1041.796 | EA18: 12678.677 | EB18: 1025.468 | EC18: 976.248 | ED18: 852.568 | EE18: 685.021 | EF18: 688.178 | EG18: 692.148 | EH18: 696.109 | EI18: 695.887 | EJ18: 698.295 | EK18: 701.526 | EL18: 592.578 | EM18: 560.47 | EN18: 8864.496 | EO18: 519.438 | EP18: 522.689 | FA18: =SUM(EO18:EZ18) -> 1042.127 | FC18: =IFERROR((( _xlfn.XLOOKUP((DATE(YEAR($FC$5),MONTH($FC$5),1)),UCA.AGRO.DATE,$B18:$FA18) / _xlfn.XLOOKUP((DATE(YEAR($FC$5)-1,MONTH($FC$5),1)),UCA.AGRO.DATE,$B18:$FA18) )-1)*100,"") -> -43.875571 | FD18: =IFERROR(((FF18/FE18)-1)*100,"") -> -28.640449 | FE18: =SUMIFS($B18:$FA18,UCA.AGRO.DATE,">="&DATE(YEAR($FC$5)-1,1,1),UCA.AGRO.DATE,"<="&DATE(YEAR($FC$5)-1,MONTH($FC$5),1)) -> 11636.881 | FF18: =SUMIFS($B18:$FA18,UCA.AGRO.DATE,">="&DATE(YEAR($FC$5),1,1),UCA.AGRO.DATE,"<="&$FC$5) -> 8304.026 | FH18: =SUM(B18:FA18) -> 215741.57 | FI18: Cocotero | FJ18: =IF(EXACT(A18,FI18)=TRUE,"OK","VER") -> OK
A19: Frijol Caupí Chiclayo | I19: 183 | J19: 560 | K19: 275 | L19: 4 | M19: 23 | N19: =SUM(B19:M19) -> 1045 | O19: 15 | P19: 1 | V19: 97 | W19: 260 | X19: 89 | AA19: =SUM(O19:Z19) -> 462 | AH19: 24 | AI19: 102 | AJ19: 175 | AK19: 319 | AL19: 32 | AN19: =SUM(AB19:AM19) -> 652 | AU19: 28 | AV19: 188 | AW19: 103 | AX19: 106 | BA19: =SUM(AO19:AZ19) -> 425 | BH19: 12 | BI19: 76 | BJ19: 176 | BK19: 286 | BL19: 80 | BM19: 3 | BN19: =SUM(BB19:BM19) -> 633 | BO19: 2.95 | BU19: 61.069 | BV19: 174.15 | BW19: 310.14 | BX19: 104.01 | BZ19: 65.1 | CA19: 717.419 | CB19: 50.874 | CC19: 73.7 | CG19: 60.83 | CH19: 88.16 | CI19: 261.143 | CJ19: 205.146 | CK19: 27.69 | CL19: 4.74 | CM19: 35.069 | CN19: 807.352 | CO19: 8.45 | CT19: 30.65 | CU19: 49.76 | CV19: 236.517 | CW19: 281.93 | CX19: 153.62 | CY19: 4.71 | DA19: 765.637 | DB19: 32.079 | DC19: 3.06 | DD19: 3.18 | DF19: 4.74 | DH19: 43.62 | DI19: 291.479 | DJ19: 684.887 | DK19: 349.989 | DL19: 40.18 | DM19: 23.01 | DN19: 1476.224 | DO19: 48.629 | DP19: 0 | DQ19: 0 | DR19: 0 | DS19: 0 | DT19: 0 | DU19: 12.21 | DV19: 217.765 | DW19: 332.649 | DX19: 172.74 | DY19: 32.49 | DZ19: 32.66 | EA19: 849.143 | EB19: 23.37 | EC19: 0 | ED19: 0 | EE19: 0 | EF19: 0 | EG19: 0 | EH19: 61.33 | EI19: 286.858 | EJ19: 253.68 | EK19: 171.078 | EL19: 25.749 | EM19: 186.548 | EN19: 1008.613 | EO19: 18.61 | EP19: 52.59 | FA19: =SUM(EO19:EZ19) -> 71.2 | FC19: =IFERROR((( _xlfn.XLOOKUP((DATE(YEAR($FC$5),MONTH($FC$5),1)),UCA.AGRO.DATE,$B19:$FA19) / _xlfn.XLOOKUP((DATE(YEAR($FC$5)-1,MONTH($FC$5),1)),UCA.AGRO.DATE,$B19:$FA19) )-1)*100,"") -> -20.747922 | FD19: =IFERROR(((FF19/FE19)-1)*100,"") -> 0.68366396 | FE19: =SUMIFS($B19:$FA19,UCA.AGRO.DATE,">="&DATE(YEAR($FC$5)-1,1,1),UCA.AGRO.DATE,"<="&DATE(YEAR($FC$5)-1,MONTH($FC$5),1)) -> 816.483 | FF19: =SUMIFS($B19:$FA19,UCA.AGRO.DATE,">="&DATE(YEAR($FC$5),1,1),UCA.AGRO.DATE,"<="&$FC$5) -> 822.065 | FH19: =SUM(B19:FA19) -> 17825.176 | FI19: Frijol Caupí Chiclayo | FJ19: =IF(EXACT(A19,FI19)=TRUE,"OK","VER") -> OK
A20: Frijol Grano Seco | B20: 40 | C20: 26 | H20: 170 | I20: 438 | J20: 992 | K20: 546 | L20: 590 | M20: 57 | N20: =SUM(B20:M20) -> 2859 | O20: 31 | P20: 9 | V20: 349 | W20: 716 | X20: 705 | Y20: 228 | Z20: 196 | AA20: =SUM(O20:Z20) -> 2234 | AI20: 356 | AJ20: 848 | AK20: 737 | AL20: 55 | AN20: =SUM(AB20:AM20) -> 1996 | AO20: 4 | AQ20: 9 | AU20: 36 | AV20: 175 | AW20: 260 | AX20: 382 | AY20: 181 | AZ20: 97 | BA20: =SUM(AO20:AZ20) -> 1144 | BH20: 42 | BI20: 69 | BJ20: 172 | BK20: 338 | BL20: 265 | BM20: 124 | BN20: =SUM(BB20:BM20) -> 1010 | BO20: 33.57 | BP20: 10.28 | BR20: 10.289 | BV20: 271.69 | BW20: 268.049 | BX20: 171.888 | BY20: 50.15 | BZ20: 77.17 | CA20: 893.086 | CB20: 103.969 | CC20: 67.19 | CD20: 35.34 | CH20: 142.31 | CI20: 171.679 | CJ20: 290.77 | CK20: 222.079 | CL20: 76.25 | CM20: 45.38 | CN20: 1154.967 | CO20: 36.15 | CP20: 54.4 | CQ20: 4.769 | CT20: 3.34 | CU20: 130.82 | CV20: 156.95 | CW20: 182.649 | CX20: 227.64 | CY20: 144.619 | CZ20: 71.83 | DA20: 1013.167 | DB20: 80.51 | DC20: 95.48 | DD20: 48.4 | DE20: 13.06 | DG20: 5.04 | DI20: 219.569 | DJ20: 221.765 | DK20: 345.388 | DL20: 152.819 | DN20: 1182.031 | DO20: 51.239 | DP20: 113.66 | DQ20: 0 | DR20: 0 | DS20: 0 | DT20: 0 | DU20: 0 | DV20: 14.22 | DW20: 350.228 | DX20: 444.829 | DY20: 153.547 | DZ20: 249.838 | EA20: 1377.561 | EB20: 213.539 | EC20: 48.739 | ED20: 23.47 | EE20: 0 | EF20: 0 | EG20: 0 | EH20: 0 | EI20: 12.48 | EJ20: 2293.24 | EK20: 381.498 | EL20: 254.428 | EM20: 91.8 | EN20: 3319.194 | EO20: 1046.228 | EP20: 220.575 | FA20: =SUM(EO20:EZ20) -> 1266.803 | FC20: =IFERROR((( _xlfn.XLOOKUP((DATE(YEAR($FC$5),MONTH($FC$5),1)),UCA.AGRO.DATE,$B20:$FA20) / _xlfn.XLOOKUP((DATE(YEAR($FC$5)-1,MONTH($FC$5),1)),UCA.AGRO.DATE,$B20:$FA20) )-1)*100,"") -> 65.700404 | FD20: =IFERROR(((FF20/FE20)-1)*100,"") -> 186.18677 | FE20: =SUMIFS($B20:$FA20,UCA.AGRO.DATE,">="&DATE(YEAR($FC$5)-1,1,1),UCA.AGRO.DATE,"<="&DATE(YEAR($FC$5)-1,MONTH($FC$5),1)) -> 1127.723 | FF20: =SUMIFS($B20:$FA20,UCA.AGRO.DATE,">="&DATE(YEAR($FC$5),1,1),UCA.AGRO.DATE,"<="&$FC$5) -> 3227.394 | FH20: =SUM(B20:FA20) -> 38899.618 | FI20: Frijol Grano Seco | FJ20: =IF(EXACT(A20,FI20)=TRUE,"OK","VER") -> OK
A21: Limón Sutil | B21: 1059 | C21: 1191 | D21: 1051 | E21: 772 | F21: 980 | G21: 1122 | H21: 800 | I21: 660 | J21: 536 | K21: 492 | L21: 385 | M21: 539 | N21: =SUM(B21:M21) -> 9587 | O21: 755 | P21: 1036 | Q21: 1087 | R21: 811 | S21: 948 | T21: 1022 | U21: 815 | V21: 525 | W21: 401 | X21: 455 | Y21: 467 | Z21: 627 | AA21: =SUM(O21:Z21) -> 8949 | AB21: 806 | AC21: 976 | AD21: 1105 | AE21: 934 | AF21: 924 | AG21: 1017 | AH21: 864 | AI21: 573 | AJ21: 526 | AK21: 618 | AL21: 602 | AM21: 731 | AN21: =SUM(AB21:AM21) -> 9676 | AO21: 751 | AP21: 1177 | AQ21: 1298 | AR21: 941 | AS21: 928 | AT21: 970 | AU21: 927 | AV21: 706 | AW21: 536 | AX21: 760 | AY21: 665 | AZ21: 921 | BA21: =SUM(AO21:AZ21) -> 10580 | BB21: 920 | BC21: 1227 | BD21: 1485 | BE21: 1045 | BF21: 1121 | BG21: 898 | BH21: 890 | BI21: 730 | BJ21: 490 | BK21: 876 | BL21: 770 | BM21: 866 | BN21: =SUM(BB21:BM21) -> 11318 | BO21: 1085.147 | BP21: 1467.189 | BQ21: 1727.738 | BR21: 1321.87 | BS21: 1349.84 | BT21: 1206.18 | BU21: 1213.95 | BV21: 963.38 | BW21: 843.34 | BX21: 932.219 | BY21: 1024.519 | BZ21: 1068.03 | CA21: 14203.402 | CB21: 1077.27 | CC21: 1490.5 | CD21: 1757.789 | CE21: 1462.859 | CF21: 1752.86 | CG21: 1407.579 | CH21: 1275.26 | CI21: 1093.38 | CJ21: 1020.388 | CK21: 1076.23 | CL21: 1194.56 | CM21: 1319.309 | CN21: 15927.984 | CO21: 1220.956 | CP21: 1550.43 | CQ21: 1684.231 | CR21: 1546.277 | CS21: 1710.7 | CT21: 1779.599 | CU21: 1506.61 | CV21: 1108.988 | CW21: 1040.31 | CX21: 809.359 | CY21: 579.33 | CZ21: 833.43 | DA21: 15370.22 | DB21: 1185.999 | DC21: 1421.41 | DD21: 1535.96 | DE21: 1381.999 | DF21: 1058.708 | DG21: 1140.68 | DH21: 1171.179 | DI21: 884.438 | DJ21: 817.999 | DK21: 767.959 | DL21: 654.394 | DM21: 716.089 | DN21: 12736.814 | DO21: 871.938 | DP21: 927.879 | DQ21: 998.94 | DR21: 1070.903 | DS21: 877.548 | DT21: 869.916 | DU21: 955.57 | DV21: 790.238 | DW21: 617.12 | DX21: 518.804 | DY21: 537.699 | DZ21: 593.279 | EA21: 9629.834 | EB21: 665.689 | EC21: 760.326 | ED21: 707.996 | EE21: 462.811 | EF21: 357.09 | EG21: 432.589 | EH21: 471.307 | EI21: 318.828 | EJ21: 249.398 | EK21: 276.516 | EL21: 339.592 | EM21: 389.046 | EN21: 5431.188 | EO21: 528.327 | EP21: 707.29 | FA21: =SUM(EO21:EZ21) -> 1235.617 | FC21: =IFERROR((( _xlfn.XLOOKUP((DATE(YEAR($FC$5),MONTH($FC$5),1)),UCA.AGRO.DATE,$B21:$FA21) / _xlfn.XLOOKUP((DATE(YEAR($FC$5)-1,MONTH($FC$5),1)),UCA.AGRO.DATE,$B21:$FA21) )-1)*100,"") -> -36.843476 | FD21: =IFERROR(((FF21/FE21)-1)*100,"") -> -44.20283 | FE21: =SUMIFS($B21:$FA21,UCA.AGRO.DATE,">="&DATE(YEAR($FC$5)-1,1,1),UCA.AGRO.DATE,"<="&DATE(YEAR($FC$5)-1,MONTH($FC$5),1)) -> 9036.555 | FF21: =SUMIFS($B21:$FA21,UCA.AGRO.DATE,">="&DATE(YEAR($FC$5),1,1),UCA.AGRO.DATE,"<="&$FC$5) -> 5042.142 | FH21: =SUM(B21:FA21) -> 249290.12 | FI21: Limón Sutil | FJ21: =IF(EXACT(A21,FI21)=TRUE,"OK","VER") -> OK
A22: Maíz Amarillo Duro | B22: 3537 | C22: 2596 | D22: 2248 | E22: 2239 | F22: 1317 | G22: 1036 | H22: 748 | I22: 1098 | J22: 2150 | K22: 3222 | L22: 4344 | M22: 3572 | N22: =SUM(B22:M22) -> 28107 | O22: 4278 | P22: 3047 | Q22: 2062 | R22: 1531 | S22: 1061 | T22: 837 | U22: 358 | V22: 1342 | W22: 1775 | X22: 4825 | Y22: 2146 | Z22: 2528 | AA22: =SUM(O22:Z22) -> 25790 | AB22: 3967 | AC22: 3347 | AD22: 1591 | AE22: 787 | AF22: 656 | AG22: 778 | AH22: 507 | AI22: 1960 | AJ22: 4487 | AK22: 9479 | AL22: 2664 | AM22: 3007 | AN22: =SUM(AB22:AM22) -> 33230 | AO22: 3634 | AP22: 2763 | AQ22: 1696 | AR22: 1246 | AS22: 742 | AT22: 586 | AU22: 561 | AV22: 1624 | AW22: 2542 | AX22: 4824 | AY22: 3604 | AZ22: 2730 | BA22: =SUM(AO22:AZ22) -> 26552 | BB22: 3848 | BC22: 2885 | BD22: 1974 | BE22: 1273 | BF22: 725 | BG22: 436 | BH22: 1116 | BI22: 1569 | BJ22: 2531 | BK22: 3000 | BL22: 2556 | BM22: 3599 | BN22: =SUM(BB22:BM22) -> 25512 | BO22: 3590.38 | BP22: 2227.45 | BQ22: 1527.099 | BR22: 1565.409 | BS22: 1495.439 | BT22: 905.24 | BU22: 501.769 | BV22: 2527.068 | BW22: 2072.077 | BX22: 2745.84 | BY22: 1741.988 | BZ22: 1936.23 | CA22: 22835.989 | CB22: 3463.858 | CC22: 2939.46 | CD22: 1592.2 | CE22: 919.42 | CF22: 478.068 | CG22: 262.96 | CH22: 300.939 | CI22: 1091.189 | CJ22: 2223.09 | CK22: 2978.83 | CL22: 950.289 | CM22: 4701.28 | CN22: 21901.583 | CO22: 5396.099 | CP22: 3255.06 | CQ22: 2828.529 | CR22: 522.35 | CS22: 475.01 | CT22: 295.119 | CU22: 313.668 | CV22: 1032.11 | CW22: 1900.32 | CX22: 3235.449 | CY22: 3218.409 | CZ22: 7827.15 | DA22: 30299.273 | DB22: 9210.66 | DC22: 5126.865 | DD22: 1702.86 | DE22: 3052.789 | DF22: 1368.379 | DG22: 1322.944 | DH22: 834.659 | DI22: 1274.949 | DJ22: 6354.656 | DK22: 5390.44 | DL22: 3453.728 | DM22: 1459.4 | DN22: 40552.329 | DO22: 3017.14 | DP22: 4346.639 | DQ22: 3519.24 | DR22: 1011.86 | DS22: 304 | DT22: 1051.61 | DU22: 853.77 | DV22: 1002.519 | DW22: 5705.909 | DX22: 9273.09 | DY22: 6577.91 | DZ22: 10705.809 | EA22: 47369.496 | EB22: 11962.28 | EC22: 6463.9 | ED22: 3541.45 | EE22: 649.545 | EF22: 320.518 | EG22: 548.35 | EH22: 506.04 | EI22: 1056.72 | EJ22: 6359.849 | EK22: 4741.488 | EL22: 3679.37 | EM22: 2359.099 | EN22: 42188.609 | EO22: 13762.456 | EP22: 9917.788 | FA22: =SUM(EO22:EZ22) -> 23680.244 | FC22: =IFERROR((( _xlfn.XLOOKUP((DATE(YEAR($FC$5),MONTH($FC$5),1)),UCA.AGRO.DATE,$B22:$FA22) / _xlfn.XLOOKUP((DATE(YEAR($FC$5)-1,MONTH($FC$5),1)),UCA.AGRO.DATE,$B22:$FA22) )-1)*100,"") -> -44.064756 | FD22: =IFERROR(((FF22/FE22)-1)*100,"") -> 8.6347644 | FE22: =SUMIFS($B22:$FA22,UCA.AGRO.DATE,">="&DATE(YEAR($FC$5)-1,1,1),UCA.AGRO.DATE,"<="&DATE(YEAR($FC$5)-1,MONTH($FC$5),1)) -> 36663.687 | FF22: =SUMIFS($B22:$FA22,UCA.AGRO.DATE,">="&DATE(YEAR($FC$5),1,1),UCA.AGRO.DATE,"<="&$FC$5) -> 39829.51 | FH22: =SUM(B22:FA22) -> 736037.05 | FI22: Maíz Amarillo Duro | FJ22: =IF(EXACT(A22,FI22)=TRUE,"OK","VER") -> OK
A23: Mandarina | B23: 438 | C23: 548 | D23: 652 | E23: 462 | F23: 662 | G23: 813 | H23: 352 | I23: 164 | J23: 88 | K23: 99 | L23: 158 | M23: 265 | N23: =SUM(B23:M23) -> 4701 | O23: 357 | P23: 481 | Q23: 647 | R23: 487 | S23: 635 | T23: 710 | U23: 380 | V23: 174 | W23: 87 | X23: 99 | Y23: 179 | Z23: 326 | AA23: =SUM(O23:Z23) -> 4562 | AB23: 432 | AC23: 537 | AD23: 692 | AE23: 627 | AF23: 683 | AG23: 718 | AH23: 415 | AI23: 204 | AJ23: 103 | AK23: 100 | AL23: 216 | AM23: 443 | AN23: =SUM(AB23:AM23) -> 5170 | AO23: 416 | AP23: 622 | AQ23: 888 | AR23: 685 | AS23: 656 | AT23: 558 | AU23: 360 | AV23: 178 | AW23: 72 | AX23: 76 | AY23: 168 | AZ23: 259 | BA23: =SUM(AO23:AZ23) -> 4938 | BB23: 265 | BC23: 310 | BD23: 839 | BE23: 744 | BF23: 977 | BG23: 646 | BH23: 486 | BI23: 395 | BJ23: 16 | BM23: 155 | BN23: =SUM(BB23:BM23) -> 4833 | BO23: 407.039 | BP23: 563.469 | BQ23: 948.359 | BR23: 919.008 | BS23: 1071.188 | BT23: 671.949 | BU23: 599.423 | BV23: 291.5 | BZ23: 279.729 | CA23: 5751.664 | CB23: 486.5 | CC23: 577.89 | CD23: 893.08 | CE23: 1261.309 | CF23: 1259.2 | CG23: 927.629 | CH23: 700.618 | CI23: 377.88 | CM23: 342.699 | CN23: 6826.805 | CO23: 530.56 | CP23: 700.438 | CQ23: 975.2 | CR23: 1089.739 | CS23: 1239.21 | CT23: 1195.237 | CU23: 745.34 | CV23: 444.039 | CW23: 45.82 | CZ23: 419.499 | DA23: 7385.082 | DB23: 548.793 | DC23: 572.819 | DD23: 789.258 | DE23: 824.75 | DF23: 1153.259 | DG23: 1163.824 | DH23: 800.709 | DI23: 327.439 | DM23: 267.508 | DN23: 6448.359 | DO23: 353.679 | DP23: 358.819 | DQ23: 415.909 | DR23: 542.847 | DS23: 1059.169 | DT23: 1129.448 | DU23: 870.547 | DV23: 457.55 | DW23: 0 | DX23: 0 | DY23: 0 | DZ23: 238.268 | EA23: 5426.236 | EB23: 334.17 | EC23: 329.478 | ED23: 378.899 | EE23: 451.449 | EF23: 573.368 | EG23: 719.768 | EH23: 628.15 | EI23: 377.179 | EJ23: 0 | EK23: 0 | EL23: 0 | EM23: 199.66 | EN23: 3992.121 | EO23: 234.339 | EP23: 271.968 | FA23: =SUM(EO23:EZ23) -> 506.307 | FC23: =IFERROR((( _xlfn.XLOOKUP((DATE(YEAR($FC$5),MONTH($FC$5),1)),UCA.AGRO.DATE,$B23:$FA23) / _xlfn.XLOOKUP((DATE(YEAR($FC$5)-1,MONTH($FC$5),1)),UCA.AGRO.DATE,$B23:$FA23) )-1)*100,"") | FD23: =IFERROR(((FF23/FE23)-1)*100,"") -> -26.898913 | FE23: =SUMIFS($B23:$FA23,UCA.AGRO.DATE,">="&DATE(YEAR($FC$5)-1,1,1),UCA.AGRO.DATE,"<="&DATE(YEAR($FC$5)-1,MONTH($FC$5),1)) -> 5187.968 | FF23: =SUMIFS($B23:$FA23,UCA.AGRO.DATE,">="&DATE(YEAR($FC$5),1,1),UCA.AGRO.DATE,"<="&$FC$5) -> 3792.461 | FH23: =SUM(B23:FA23) -> 121081.15 | FI23: Mandarina | FJ23: =IF(EXACT(A23,FI23)=TRUE,"OK","VER") -> OK
A24: Mango | B24: 972 | J24: 987 | K24: 1371 | L24: 1537 | M24: 1453 | N24: =SUM(B24:M24) -> 6320 | O24: 798 | V24: 10 | W24: 1156 | X24: 1454 | Y24: 1510 | Z24: 1482 | AA24: =SUM(O24:Z24) -> 6410 | AB24: 813 | AI24: 15 | AJ24: 934 | AK24: 1476 | AL24: 1753 | AM24: 1663 | AN24: =SUM(AB24:AM24) -> 6654 | AO24: 733 | AU24: 11 | AV24: 32 | AW24: 678 | AX24: 1177 | AY24: 1416 | AZ24: 440 | BA24: =SUM(AO24:AZ24) -> 4487 | BB24: 151 | BJ24: 168 | BK24: 1014 | BL24: 1364 | BM24: 970 | BN24: =SUM(BB24:BM24) -> 3667 | BO24: 403.68 | BW24: 709.599 | BX24: 1821.618 | BY24: 1932.22 | BZ24: 1257.27 | CA24: 6124.387 | CB24: 580.54 | CJ24: 720.666 | CK24: 1978.42 | CL24: 1952.498 | CM24: 1256.72 | CN24: 6488.844 | CO24: 560.35 | CV24: 39.85 | CW24: 550.97 | CX24: 2181.71 | CY24: 1571.34 | CZ24: 1181.089 | DA24: 6085.309 | DB24: 633.92 | DJ24: 490.587 | DK24: 1763.359 | DL24: 1116.579 | DM24: 447.099 | DN24: 4451.544 | DO24: 230.849 | DP24: 0 | DQ24: 0 | DR24: 0 | DS24: 0 | DT24: 0 | DU24: 0 | DV24: 0 | DW24: 641.908 | DX24: 1445.355 | DY24: 998.198 | DZ24: 426.63 | EA24: 3742.94 | EB24: 233.254 | EC24: 0 | ED24: 0 | EE24: 0 | EF24: 0 | EG24: 0 | EH24: 0 | EI24: 0 | EJ24: 329.379 | EK24: 1395.105 | EL24: 1085.669 | EM24: 677.516 | EN24: 3720.923 | EO24: 315.795 | EP24: 0 | FA24: =SUM(EO24:EZ24) -> 315.795 | FC24: =IFERROR((( _xlfn.XLOOKUP((DATE(YEAR($FC$5),MONTH($FC$5),1)),UCA.AGRO.DATE,$B24:$FA24) / _xlfn.XLOOKUP((DATE(YEAR($FC$5)-1,MONTH($FC$5),1)),UCA.AGRO.DATE,$B24:$FA24) )-1)*100,"") -> 8.7628907 | FD24: =IFERROR(((FF24/FE24)-1)*100,"") -> -8.2291161 | FE24: =SUMIFS($B24:$FA24,UCA.AGRO.DATE,">="&DATE(YEAR($FC$5)-1,1,1),UCA.AGRO.DATE,"<="&DATE(YEAR($FC$5)-1,MONTH($FC$5),1)) -> 3316.31 | FF24: =SUMIFS($B24:$FA24,UCA.AGRO.DATE,">="&DATE(YEAR($FC$5),1,1),UCA.AGRO.DATE,"<="&$FC$5) -> 3043.407 | FH24: =SUM(B24:FA24) -> 116935.48 | FI24: Mango | FJ24: =IF(EXACT(A24,FI24)=TRUE,"OK","VER") -> OK
A25: Maní | B25: 34 | I25: 8 | J25: 61 | K25: 95 | L25: 93 | M25: 13 | N25: =SUM(B25:M25) -> 304 | O25: 29 | P25: 15 | W25: 67 | X25: 124 | Y25: 100 | Z25: 127 | AA25: =SUM(O25:Z25) -> 462 | AI25: 41 | AJ25: 110 | AK25: 152 | AL25: 28 | AM25: 69 | AN25: =SUM(AB25:AM25) -> 400 | AU25: 24 | AV25: 55 | AW25: 57 | AX25: 129 | AY25: 99 | AZ25: 20 | BA25: =SUM(AO25:AZ25) -> 384 | BB25: 18 | BC25: 18 | BD25: 3 | BI25: 3 | BJ25: 22 | BK25: 80 | BL25: 105 | BM25: 38 | BN25: =SUM(BB25:BM25) -> 287 | BO25: 38 | BP25: 29 | BQ25: 25 | BV25: 24 | BW25: 75 | BX25: 81 | BY25: 32 | CA25: 304 | CB25: 32.639 | CC25: 16.519 | CD25: 35.21 | CE25: 1.48 | CH25: 16.169 | CI25: 61.28 | CJ25: 143.18 | CK25: 38.909 | CL25: 12.96 | CM25: 37.93 | CN25: 396.276 | CO25: 35.9 | CP25: 14.67 | CQ25: 25.308 | CV25: 40.32 | CW25: 136.82 | CX25: 159.559 | CY25: 93.998 | CZ25: 5.04 | DA25: 511.615 | DB25: 50.33 | DC25: 32.76 | DD25: 37.96 | DE25: 12.937 | DF25: 39.31 | DG25: 3.259 | DI25: 41.674 | DJ25: 127.499 | DK25: 203.849 | DL25: 134.429 | DM25: 14.9 | DN25: 698.907 | DO25: 27.22 | DP25: 89.56 | DQ25: 0 | DR25: 0 | DS25: 15.3 | DT25: 0 | DU25: 0 | DV25: 0 | DW25: 72.246 | DX25: 107.906 | DY25: 72.878 | DZ25: 4.769 | EA25: 389.879 | EB25: 0 | EC25: 6.379 | ED25: 21.56 | EE25: 0 | EF25: 0 | EG25: 0 | EH25: 0 | EI25: 15.9 | EJ25: 58.18 | EK25: 144.888 | EL25: 101.13 | EM25: 20.31 | EN25: 368.347 | EO25: 88.13 | EP25: 50.34 | FA25: =SUM(EO25:EZ25) -> 138.47 | FC25: =IFERROR((( _xlfn.XLOOKUP((DATE(YEAR($FC$5),MONTH($FC$5),1)),UCA.AGRO.DATE,$B25:$FA25) / _xlfn.XLOOKUP((DATE(YEAR($FC$5)-1,MONTH($FC$5),1)),UCA.AGRO.DATE,$B25:$FA25) )-1)*100,"") -> 38.766157 | FD25: =IFERROR(((FF25/FE25)-1)*100,"") -> -9.6266002 | FE25: =SUMIFS($B25:$FA25,UCA.AGRO.DATE,">="&DATE(YEAR($FC$5)-1,1,1),UCA.AGRO.DATE,"<="&DATE(YEAR($FC$5)-1,MONTH($FC$5),1)) -> 385.11 | FF25: =SUMIFS($B25:$FA25,UCA.AGRO.DATE,">="&DATE(YEAR($FC$5),1,1),UCA.AGRO.DATE,"<="&$FC$5) -> 348.037 | FH25: =SUM(B25:FA25) -> 9288.988 | FI25: Maní | FJ25: =IF(EXACT(A25,FI25)=TRUE,"OK","VER") -> OK
A26: Naranja | B26: 874 | C26: 1137 | D26: 1151 | E26: 795 | F26: 1037 | G26: 1060 | H26: 634 | I26: 306 | J26: 256 | K26: 234 | L26: 284 | M26: 476 | N26: =SUM(B26:M26) -> 8244 | O26: 717 | P26: 962 | Q26: 1145 | R26: 848 | S26: 1028 | T26: 1079 | U26: 701 | V26: 290 | W26: 167 | X26: 246 | Y26: 321 | Z26: 637 | AA26: =SUM(O26:Z26) -> 8141 | AB26: 863 | AC26: 1021 | AD26: 1273 | AE26: 1028 | AF26: 1172 | AG26: 1246 | AH26: 234 | AI26: 99 | AJ26: 94 | AK26: 136 | AL26: 315 | AM26: 830 | AN26: =SUM(AB26:AM26) -> 8311 | AO26: 879 | AP26: 1162 | AQ26: 1333 | AR26: 1219 | AS26: 1134 | AT26: 1083 | AU26: 474 | AV26: 94 | AW26: 102 | AX26: 131 | AY26: 192 | AZ26: 244 | BA26: =SUM(AO26:AZ26) -> 8047 | BB26: 620 | BC26: 1239 | BD26: 1699 | BE26: 1419 | BF26: 1212 | BG26: 1134 | BH26: 899 | BI26: 564 | BJ26: 46 | BM26: 480 | BN26: =SUM(BB26:BM26) -> 9312 | BO26: 1064.609 | BP26: 1625.919 | BQ26: 1929.48 | BR26: 1812.309 | BS26: 1814.199 | BT26: 1402.259 | BU26: 1170.022 | BV26: 635.079 | BZ26: 603.179 | CA26: 12057.055 | CB26: 1117.84 | CC26: 1299.859 | CD26: 1837.237 | CE26: 2206.2 | CF26: 2344.85 | CG26: 1708.04 | CH26: 1213.51 | CI26: 650.509 | CM26: 821.129 | CN26: 13199.174 | CO26: 1281.618 | CP26: 1619.658 | CQ26: 2010.816 | CR26: 2156.379 | CS26: 2425.268 | CT26: 2090.658 | CU26: 1543.928 | CV26: 768.82 | CW26: 74.519 | CY26: 26.48 | CZ26: 806.999 | DA26: 14805.143 | DB26: 1132.13 | DC26: 1486.318 | DD26: 1724.43 | DE26: 1776.43 | DF26: 2166.84 | DG26: 2043.47 | DH26: 1683.607 | DI26: 720.064 | DM26: 372.488 | DN26: 13105.777 | DO26: 598.65 | DP26: 815.209 | DQ26: 985.369 | DR26: 1207.4 | DS26: 1737.23 | DT26: 2034.719 | DU26: 1693.349 | DV26: 897.61 | DW26: 0 | DX26: 0 | DY26: 0 | DZ26: 336.358 | EA26: 10305.894 | EB26: 477.598 | EC26: 581.058 | ED26: 641.288 | EE26: 632.63 | EF26: 914.042 | EG26: 1231.866 | EH26: 1105.087 | EI26: 660.158 | EJ26: 0 | EK26: 0 | EL26: 0 | EM26: 258.129 | EN26: 6501.856 | EO26: 307.426 | EP26: 433.79 | FA26: =SUM(EO26:EZ26) -> 741.216 | FC26: =IFERROR((( _xlfn.XLOOKUP((DATE(YEAR($FC$5),MONTH($FC$5),1)),UCA.AGRO.DATE,$B26:$FA26) / _xlfn.XLOOKUP((DATE(YEAR($FC$5)-1,MONTH($FC$5),1)),UCA.AGRO.DATE,$B26:$FA26) )-1)*100,"") | FD26: =IFERROR(((FF26/FE26)-1)*100,"") -> -37.37194 | FE26: =SUMIFS($B26:$FA26,UCA.AGRO.DATE,">="&DATE(YEAR($FC$5)-1,1,1),UCA.AGRO.DATE,"<="&DATE(YEAR($FC$5)-1,MONTH($FC$5),1)) -> 9969.536 | FF26: =SUMIFS($B26:$FA26,UCA.AGRO.DATE,">="&DATE(YEAR($FC$5),1,1),UCA.AGRO.DATE,"<="&$FC$5) -> 6243.727 | FH26: =SUM(B26:FA26) -> 225542.23 | FI26: Naranja | FJ26: =IF(EXACT(A26,FI26)=TRUE,"OK","VER") -> OK
A27: Palma Aceitera | B27: 11839 | C27: 12007 | D27: 14204 | E27: 15811 | F27: 15211 | G27: 15018 | H27: 11604 | I27: 15227 | J27: 19909 | K27: 21436 | L27: 17600 | M27: 18268 | N27: =SUM(B27:M27) -> 188134 | O27: 15626 | P27: 16693 | Q27: 17245 | R27: 17281 | S27: 15831 | T27: 16854 | U27: 11589 | V27: 16496 | W27: 23055 | X27: 28644 | Y27: 19927 | Z27: 24005 | AA27: =SUM(O27:Z27) -> 223246 | AB27: 20010 | AC27: 21745 | AD27: 28991 | AE27: 23880 | AF27: 26242 | AG27: 23796 | AH27: 20770 | AI27: 25995 | AJ27: 28183 | AK27: 30605 | AL27: 24312 | AM27: 24123 | AN27: =SUM(AB27:AM27) -> 298652 | AO27: 24987 | AP27: 24714 | AQ27: 28010 | AR27: 28526 | AS27: 24204 | AT27: 20735 | AU27: 26005 | AV27: 34548 | AW27: 34740 | AX27: 37355 | AY27: 34999 | AZ27: 31423 | BA27: =SUM(AO27:AZ27) -> 350246 | BB27: 30558 | BC27: 26858 | BD27: 30364 | BE27: 28454 | BF27: 26938 | BG27: 23702 | BH27: 20394 | BI27: 25820 | BJ27: 29139 | BK27: 44587 | BL27: 37401 | BM27: 30350 | BN27: =SUM(BB27:BM27) -> 354565 | BO27: 31622.03 | BP27: 28427.2 | BQ27: 30252.65 | BR27: 17589.005 | BS27: 18405.61 | BT27: 17319.82 | BU27: 22283.79 | BV27: 30907.08 | BW27: 35604.859 | BX27: 34512.85 | BY27: 28125.77 | BZ27: 23914.22 | CA27: 318964.88 | CB27: 32916.05 | CC27: 37419.039 | CD27: 46225.54 | CE27: 44857.729 | CF27: 43882.819 | CG27: 37544.688 | CH27: 35909.57 | CI27: 43786.51 | CJ27: 69355.12 | CK27: 67555.049 | CL27: 63822.95 | CM27: 42163.72 | CN27: 565438.78 | CO27: 42302.17 | CP27: 42628.869 | CQ27: 52684.5 | CR27: 52076.03 | CS27: 49485.3 | CT27: 35201.239 | CU27: 35155.76 | CV27: 63038.91 | CW27: 62399.27 | CX27: 77887.03 | CY27: 75922.85 | CZ27: 75649.36 | DA27: 664431.29 | DB27: 59285.49 | DC27: 58925.3 | DD27: 47495.921 | DE27: 40575.055 | DF27: 37990.087 | DG27: 35956.799 | DH27: 32128.449 | DI27: 58279.92 | DJ27: 72459.85 | DK27: 93999.218 | DL27: 78274.539 | DM27: 51431.489 | DN27: 666802.12 | DO27: 41044.58 | DP27: 37102.98 | DQ27: 39880.11 | DR27: 39869.68 | DS27: 37321.65 | DT27: 28872.97 | DU27: 51905.22 | DV27: 79590.4 | DW27: 83373.009 | DX27: 105716.91 | DY27: 77739.77 | DZ27: 51809.999 | EA27: 674227.28 | EB27: 43094.739 | EC27: 45460.49 | ED27: 41760.44 | EE27: 38554.139 | EF27: 38566.25 | EG27: 31868.518 | EH27: 43945.358 | EI27: 65102.929 | EJ27: 95634.759 | EK27: 105328.07 | EL27: 102901.28 | EM27: 102582.76 | EN27: 754799.73 | EO27: 79930.95 | EP27: 79757.809 | FA27: =SUM(EO27:EZ27) -> 159688.76 | FC27: =IFERROR((( _xlfn.XLOOKUP((DATE(YEAR($FC$5),MONTH($FC$5),1)),UCA.AGRO.DATE,$B27:$FA27) / _xlfn.XLOOKUP((DATE(YEAR($FC$5)-1,MONTH($FC$5),1)),UCA.AGRO.DATE,$B27:$FA27) )-1)*100,"") -> 32.366328 | FD27: =IFERROR(((FF27/FE27)-1)*100,"") -> 4.7877353 | FE27: =SUMIFS($B27:$FA27,UCA.AGRO.DATE,">="&DATE(YEAR($FC$5)-1,1,1),UCA.AGRO.DATE,"<="&DATE(YEAR($FC$5)-1,MONTH($FC$5),1)) -> 622417.28 | FF27: =SUMIFS($B27:$FA27,UCA.AGRO.DATE,">="&DATE(YEAR($FC$5),1,1),UCA.AGRO.DATE,"<="&$FC$5) -> 652216.97 | FH27: =SUM(B27:FA27) -> 10438392 | FI27: Palma Aceitera | FJ27: =IF(EXACT(A27,FI27)=TRUE,"OK","VER") -> OK
