Workbook
Name SMN.AGRO.DATE: '01.XLS'!$B$5:$JN$5
Name SMN.AGRO.NAME: '01.XLS'!$A$7:$A$59
Name SMN.AGRO.VAL: '01.XLS'!$B$7:$JN$59
Name SMN.ASERRADA.DATE: '09.XLS'!$B$5:$LN$5
Name SMN.ASERRADA.NAME: '09.XLS'!$A$7:$A$39
Name SMN.ASERRADA.VAL: '09.XLS'!$B$7:$LN$39
Name SMN.COSECHA.DATE: '05.XLS'!$B$5:$KA$5
Name SMN.COSECHA.NAME: '05.XLS'!$A$7:$A$41
Name SMN.COSECHA.VAL: '05.XLS'!$B$7:$KA$41
Name SMN.GGL.DATE: 'GASTO G.L.'!$B$5:$IN$5
Name SMN.GGL.NAME: 'GASTO G.L.'!$A$7:$A$21
Name SMN.GGL.VAL: 'GASTO G.L.'!$B$7:$IN$21
Name SMN.GGN.DATE: 'GASTO G.N.'!$B$5:$IN$5
Name SMN.GGN.NAME: 'GASTO G.N.'!$A$7:$A$21
Name SMN.GGN.VAL: 'GASTO G.N.'!$B$7:$IN$21
Name SMN.GGR.DATE: 'GASTO G.R.'!$B$5:$IN$5
Name SMN.GGR.NAME: 'GASTO G.R.'!$A$7:$A$21
Name SMN.GGR.VAL: 'GASTO G.R.'!$B$7:$IN$21
Name SMN.IGL.DATE: 'INVERSION G.L.'!$B$5:$IN$5
Name SMN.IGL.NAME: 'INVERSION G.L.'!$A$7:$A$37
Name SMN.IGL.VAL: 'INVERSION G.L.'!$B$7:$IN$37
Name SMN.IGN.DATE: 'INVERSION G.N.'!$B$5:$IN$5
Name SMN.IGN.NAME: 'INVERSION G.N.'!$A$7:$A$37
Name SMN.IGN.VAL: 'INVERSION G.N.'!$B$7:$IN$37
Name SMN.IGR.DATE: 'INVERSION G.R.'!$B$5:$IN$5
Name SMN.IGR.NAME: 'INVERSION G.R.'!$A$7:$A$38
Name SMN.IGR.VAL: 'INVERSION G.R.'!$B$7:$IN$38
Name SMN.MANUFACTURA.DATE: '10 - Base 2007'!$B$5:$KA$5
Name SMN.MANUFACTURA.NAME: '10 - Base 2007'!$A$7:$A$20
Name SMN.MANUFACTURA.VAL: '10 - Base 2007'!$B$7:$KA$20
Name SMN.MANUFACTURAVAR.DATE: '10 - Base 2007'!$B$27:$KA$27
Name SMN.MANUFACTURAVAR.NAME: '10 - Base 2007'!$A$29:$A$42
Name SMN.MANUFACTURAVAR.VAL: '10 - Base 2007'!$B$29:$KA$42
Name SMN.PESCA.DATE: '07.XLS'!$B$5:$JN$5
Name SMN.PESCA.NAME: '07.XLS'!$A$7:$A$24
Name SMN.PESCA.VAL: '07.XLS'!$B$7:$JN$24
Name SMN.ROLLIZA.DATE: '08.XLS'!$B$5:$LN$5
Name SMN.ROLLIZA.NAME: '08.XLS'!$A$7:$A$39
Name SMN.ROLLIZA.VAL: '08.XLS'!$B$7:$LN$39
Name SMN.SIEMBRA.DATE: '03.XLS'!$B$5:$JN$5
Name SMN.SIEMBRA.NAME: '03.XLS'!$A$7:$A$38
Name SMN.SIEMBRA.VAL: '03.XLS'!$B$7:$JN$38
Name SMN.X.DATE: '14.XLS'!$B$5:$KA$5
Name SMN.X.NAME: '14.XLS'!$A$7:$A$36
Name SMN.X.VAL: '14.XLS'!$B$7:$KA$36

Sheet 01.XLS
A1: Cuadro Nº 01
A2: SAN MARTÍN: PRODUCCIÓN AGROPECUARIA 1/
A3: (VBP y toneladas métricas)
B4: =YEAR(B5) -> 2006 | N4: Total | O4: =YEAR(O5) -> 2007 | AA4: Total | AB4: =YEAR(AB5) -> 2008 | AN4: Total | AO4: =YEAR(AO5) -> 2009 | BA4: Total | BB4: =YEAR(BB5) -> 2010 | BN4: Total | BO4: =YEAR(BO5) -> 2011 | CA4: Total | CB4: =YEAR(CB5) -> 2012 | CN4: Total | CO4: =YEAR(CO5) -> 2013 | DA4: Total | DB4: =YEAR(DB5) -> 2014 | DN4: Total | DO4: =YEAR(DO5) -> 2015 | EA4: Total | EB4: =YEAR(EB5) -> 2016 | EN4: Total | EO4: =YEAR(EO5) -> 2017 | FA4: Total | FB4: =YEAR(FB5) -> 2018 | FN4: Total | FO4: =YEAR(FO5) -> 2019 | GA4: Total | GB4: =YEAR(GB5) -> 2020 | GN4: Total | GO4: =YEAR(GO5) -> 2021 | HA4: Total | HB4: =YEAR(HB5) -> 2022 | HN4: Total | HO4: =YEAR(HO5) -> 2023 | IA4: Total | IB4: =YEAR(IB5) -> 2024 | IN4: Total | IO4: =YEAR(IO5) -> 2025 | JA4: Total | JB4: =YEAR(JB5) -> 2026 | JN4: Total | JP4: =CONCATENATE("Var.% ",JS4,"/",JS4-1) -> Var.% 2025/2024 | JR4: =JS4-1 -> 2024 | JS4: =YEAR(JP5) -> 2025 | JU4: PARA COMPROBAR
B5: 38718 | C5: 38749 | D5: 38777 | E5: 38808 | F5: 38838 | G5: 38869 | H5: 38899 | I5: 38930 | J5: 38961 | K5: 38991 | L5: 39022 | M5: 39052 | N5: =YEAR(M5) -> 2006 | O5: 39083 | P5: 39114 | Q5: 39142 | R5: 39173 | S5: 39203 | T5: 39234 | U5: 39264 | V5: 39295 | W5: 39326 | X5: 39356 | Y5: 39387 | Z5: 39417 | AA5: =YEAR(Z5) -> 2007 | AB5: 39448 | AC5: 39479 | AD5: 39508 | AE5: 39539 | AF5: 39569 | AG5: 39600 | AH5: 39630 | AI5: 39661 | AJ5: 39692 | AK5: 39722 | AL5: 39753 | AM5: 39783 | AN5: =YEAR(AM5) -> 2008 | AO5: 39814 | AP5: 39845 | AQ5: 39873 | AR5: 39904 | AS5: 39934 | AT5: 39965 | AU5: 39995 | AV5: 40026 | AW5: 40057 | AX5: 40087 | AY5: 40118 | AZ5: 40148 | BA5: =YEAR(AZ5) -> 2009 | BB5: 40179 | BC5: 40210 | BD5: 40238 | BE5: 40269 | BF5: 40299 | BG5: 40330 | BH5: 40360 | BI5: 40391 | BJ5: 40422 | BK5: 40452 | BL5: 40483 | BM5: 40513 | BN5: =YEAR(BM5) -> 2010 | BO5: 40544 | BP5: 40575 | BQ5: 40603 | BR5: 40634 | BS5: 40664 | BT5: 40695 | BU5: 40725 | BV5: 40756 | BW5: 40787 | BX5: 40817 | BY5: 40848 | BZ5: 40878 | CA5: =YEAR(BZ5) -> 2011 | CB5: 40909 | CC5: 40940 | CD5: 40969 | CE5: 41000 | CF5: 41030 | CG5: 41061 | CH5: 41091 | CI5: 41122 | CJ5: 41153 | CK5: 41183 | CL5: 41214 | CM5: 41244 | CN5: =YEAR(CM5) -> 2012 | CO5: 41275 | CP5: 41306 | CQ5: 41334 | CR5: 41365 | CS5: 41395 | CT5: 41426 | CU5: 41456 | CV5: 41487 | CW5: 41518 | CX5: 41548 | CY5: 41579 | CZ5: 41609 | DA5: =YEAR(CZ5) -> 2013 | DB5: 41640 | DC5: 41671 | DD5: 41699 | DE5: 41730 | DF5: 41760 | DG5: 41791 | DH5: 41821 | DI5: 41852 | DJ5: 41883 | DK5: 41913 | DL5: 41944 | DM5: 41974 | DN5: =YEAR(DM5) -> 2014 | DO5: 42005 | DP5: 42036 | DQ5: 42064 | DR5: 42095 | DS5: 42125 | DT5: 42156 | DU5: 42186 | DV5: 42217 | DW5: 42248 | DX5: 42278 | DY5: 42309 | DZ5: 42339 | EA5: =YEAR(DZ5) -> 2015 | EB5: 42370 | EC5: 42401 | ED5: 42430 | EE5: 42461 | EF5: 42491 | EG5: 42522 | EH5: 42552 | EI5: 42583 | EJ5: 42614 | EK5: 42644 | EL5: 42675 | EM5: 42705 | EN5: =YEAR(EM5) -> 2016 | EO5: 42736 | EP5: 42767 | EQ5: 42795 | ER5: 42826 | ES5: 42856 | ET5: 42887 | EU5: 42917 | EV5: 42948 | EW5: 42979 | EX5: 43009 | EY5: 43040 | EZ5: 43070 | FA5: =YEAR(EZ5) -> 2017 | FB5: 43101 | FC5: 43132 | FD5: 43160 | FE5: 43191 | FF5: 43221 | FG5: 43252 | FH5: 43282 | FI5: 43313 | FJ5: 43344 | FK5: 43374 | FL5: 43405 | FM5: 43435 | FN5: =YEAR(FM5) -> 2018 | FO5: 43466 | FP5: 43497 | FQ5: 43525 | FR5: 43556 | FS5: 43586 | FT5: 43617 | FU5: 43647 | FV5: 43678 | FW5: 43709 | FX5: 43739 | FY5: 43770 | FZ5: 43800 | GA5: =YEAR(FZ5) -> 2019 | GB5: 43831 | GC5: 43862 | GD5: 43891 | GE5: 43922 | GF5: 43952 | GG5: 43983 | GH5: 44013 | GI5: 44044 | GJ5: 44075 | GK5: 44105 | GL5: 44136 | GM5: 44166 | GN5: =YEAR(GM5) -> 2020 | GO5: 44197 | GP5: 44228 | GQ5: 44256 | GR5: 44287 | GS5: 44317 | GT5: 44348 | GU5: 44378 | GV5: 44409 | GW5: 44440 | GX5: 44470 | GY5: 44501 | GZ5: 44531 | HA5: =YEAR(GZ5) -> 2021 | HB5: 44562 | HC5: 44593 | HD5: 44621 | HE5: 44652 | HF5: 44682 | HG5: 44713 | HH5: 44743 | HI5: 44774 | HJ5: 44805 | HK5: 44835 | HL5: 44866 | HM5: 44896 | HN5: =YEAR(HM5) -> 2022 | HO5: 44927 | HP5: 44958 | HQ5: 44986 | HR5: 45017 | HS5: 45047 | HT5: 45078 | HU5: 45108 | HV5: 45139 | HW5: 45170 | HX5: 45200 | HY5: 45231 | HZ5: 45261 | IA5: =YEAR(HZ5) -> 2023 | IB5: 45292 | IC5: 45323 | ID5: 45352 | IE5: 45383 | IF5: 45413 | IG5: 45444 | IH5: 45474 | II5: 45505 | IJ5: 45536 | IK5: 45566 | IL5: 45597 | IM5: 45627 | IN5: =YEAR(IM5) -> 2024 | IO5: 45658 | IP5: 45689 | IQ5: 45717 | IR5: 45748 | IS5: 45778 | IT5: 45809 | IU5: 45839 | IV5: 45870 | IW5: 45901 | IX5: 45931 | IY5: 45962 | IZ5: 45992 | JA5: =YEAR(IZ5) -> 2025 | JB5: 46023 | JC5: 46054 | JD5: 46082 | JE5: 46113 | JF5: 46143 | JG5: 46174 | JH5: 46204 | JI5: 46235 | JJ5: 46266 | JK5: 46296 | JL5: 46327 | JM5: 46357 | JN5: =YEAR(JM5) -> 2026 | JP5: =IZ5 -> 45992 | JQ5: =CONCATENATE("Ene.-",TEXT(JP5,"MMM.")) -> Ene.-Dic. | JR5: =JQ5 -> Ene.-Dic. | JS5: =JQ5 -> Ene.-Dic. | JU5: NO BORRRAR
A7: TOTAL AGROPECUARIO 2/ | B7: =SUM(B8:B9) -> 116436.32 | C7: =SUM(C8:C9) -> 93654.678 | D7: =SUM(D8:D9) -> 89011.912 | E7: =SUM(E8:E9) -> 114832.57 | F7: =SUM(F8:F9) -> 136755.18 | G7: =SUM(G8:G9) -> 127371.48 | H7: =SUM(H8:H9) -> 112513.93 | I7: =SUM(I8:I9) -> 90722.123 | ... M7: =SUM(M8:M9) -> 59007.12 | N7: =SUM(B7:M7) -> 1151958.2 | O7: =SUM(O8:O9) -> 76416.141 | P7: =SUM(P8:P9) -> 92823.466 | Q7: =SUM(Q8:Q9) -> 89473.759 | R7: =SUM(R8:R9) -> 106303.26 | S7: =SUM(S8:S9) -> 120719.38 | T7: =SUM(T8:T9) -> 112994.52 | U7: =SUM(U8:U9) -> 107860.58 | V7: =SUM(V8:V9) -> 105132.3 | ... Z7: =SUM(Z8:Z9) -> 78374.89 | AA7: =SUM(O7:Z7) -> 1119947.2 | AB7: =SUM(AB8:AB9) -> 91518.694 | AC7: =SUM(AC8:AC9) -> 120214.13 | AD7: =SUM(AD8:AD9) -> 121111.67 | AE7: =SUM(AE8:AE9) -> 126628.07 | AF7: =SUM(AF8:AF9) -> 145682.82 | AG7: =SUM(AG8:AG9) -> 123929.56 | AH7: =SUM(AH8:AH9) -> 126608.68 | AI7: =SUM(AI8:AI9) -> 98743.35 | ... AM7: =SUM(AM8:AM9) -> 99183.693 | AN7: =SUM(AB7:AM7) -> 1337755.3 | AO7: =SUM(AO8:AO9) -> 90986.466 | AP7: =SUM(AP8:AP9) -> 114990.97 | AQ7: =SUM(AQ8:AQ9) -> 126026.23 | AR7: =SUM(AR8:AR9) -> 158061.35 | AS7: =SUM(AS8:AS9) -> 163815.28 | AT7: =SUM(AT8:AT9) -> 149662.49 | AU7: =SUM(AU8:AU9) -> 125996.51 | AV7: =SUM(AV8:AV9) -> 101120.76 | ... AZ7: =SUM(AZ8:AZ9) -> 93261.074 | BA7: =SUM(AO7:AZ7) -> 1415023.8 | BB7: =SUM(BB8:BB9) -> 90457.141 | BC7: =SUM(BC8:BC9) -> 107749.79 | BD7: =SUM(BD8:BD9) -> 117490.06 | BE7: =SUM(BE8:BE9) -> 137328.3 | BF7: =SUM(BF8:BF9) -> 179714.17 | BG7: =SUM(BG8:BG9) -> 148783 | BH7: =SUM(BH8:BH9) -> 118285.66 | BI7: =SUM(BI8:BI9) -> 99755.084 | ... BM7: =SUM(BM8:BM9) -> 99683.061 | BN7: =SUM(BB7:BM7) -> 1410026.9 | BO7: =SUM(BO8:BO9) -> 91432.745 | BP7: =SUM(BP8:BP9) -> 113571.9 | BQ7: =SUM(BQ8:BQ9) -> 122888.63 | BR7: =SUM(BR8:BR9) -> 184087.08 | BS7: =SUM(BS8:BS9) -> 183431.99 | BT7: =SUM(BT8:BT9) -> 161677.38 | BU7: =SUM(BU8:BU9) -> 127986.75 | BV7: =SUM(BV8:BV9) -> 110754.67 | ... BZ7: =SUM(BZ8:BZ9) -> 99402.03 | CA7: =SUM(BO7:BZ7) -> 1503639.4 | CB7: =SUM(CB8:CB9) -> 124892.34 | CC7: =SUM(CC8:CC9) -> 133483.77 | CD7: =SUM(CD8:CD9) -> 123360.39 | CE7: =SUM(CE8:CE9) -> 188518.56 | CF7: =SUM(CF8:CF9) -> 215536.1 | CG7: =SUM(CG8:CG9) -> 192359.33 | CH7: =SUM(CH8:CH9) -> 140291.73 | CI7: =SUM(CI8:CI9) -> 113371.61 | ... CM7: =SUM(CM8:CM9) -> 105552.58 | CN7: =SUM(CB7:CM7) -> 1681144.8 | CO7: =SUM(CO8:CO9) -> 103907.23 | CP7: =SUM(CP8:CP9) -> 122368.48 | CQ7: =SUM(CQ8:CQ9) -> 140133.38 | CR7: =SUM(CR8:CR9) -> 171775.13 | CS7: =SUM(CS8:CS9) -> 182674.14 | CT7: =SUM(CT8:CT9) -> 174700.2 | CU7: =SUM(CU8:CU9) -> 126969.2 | CV7: =SUM(CV8:CV9) -> 120529.54 | ... CZ7: =SUM(CZ8:CZ9) -> 118249.21 | DA7: =SUM(CO7:CZ7) -> 1611319.1 | DB7: =SUM(DB8:DB9) -> 124239.64 | DC7: =SUM(DC8:DC9) -> 135953.24 | DD7: =SUM(DD8:DD9) -> 150064.82 | DE7: =SUM(DE8:DE9) -> 176177.08 | DF7: =SUM(DF8:DF9) -> 210017.86 | DG7: =SUM(DG8:DG9) -> 203398.47 | DH7: =SUM(DH8:DH9) -> 160358.2 | DI7: =SUM(DI8:DI9) -> 132271.23 | ... DM7: =SUM(DM8:DM9) -> 127603.98 | DN7: =SUM(DB7:DM7) -> 1787130.9 | DO7: =SUM(DO8:DO9) -> 116371.87 | DP7: =SUM(DP8:DP9) -> 132311.15 | DQ7: =SUM(DQ8:DQ9) -> 158283.69 | DR7: =SUM(DR8:DR9) -> 221459.28 | DS7: =SUM(DS8:DS9) -> 262569.88 | DT7: =SUM(DT8:DT9) -> 222808.71 | DU7: =SUM(DU8:DU9) -> 165863.96 | DV7: =SUM(DV8:DV9) -> 133179.79 | ... DZ7: =SUM(DZ8:DZ9) -> 150111.92 | EA7: =SUM(DO7:DZ7) -> 1942637.9 | EB7: =SUM(EB8:EB9) -> 117931.44 | EC7: =SUM(EC8:EC9) -> 143436.93 | ED7: =SUM(ED8:ED9) -> 138925.84 | EE7: =SUM(EE8:EE9) -> 245919.15 | EF7: =SUM(EF8:EF9) -> 269605.82 | EG7: =SUM(EG8:EG9) -> 228013.33 | EH7: =SUM(EH8:EH9) -> 172861.47 | EI7: =SUM(EI8:EI9) -> 138523.22 | ... EM7: =SUM(EM8:EM9) -> 145574.86 | EN7: =SUM(EB7:EM7) -> 1996861.8 | EO7: =SUM(EO8:EO9) -> 130238.12 | EP7: =SUM(EP8:EP9) -> 147756.95 | EQ7: =SUM(EQ8:EQ9) -> 166398.02 | ER7: =SUM(ER8:ER9) -> 271127.52 | ES7: =SUM(ES8:ES9) -> 293038.26 | ET7: =SUM(ET8:ET9) -> 237568.97 | EU7: =SUM(EU8:EU9) -> 183258.92 | EV7: =SUM(EV8:EV9) -> 148854.95 | ... EZ7: =SUM(EZ8:EZ9) -> 153475.19 | FA7: =SUM(EO7:EZ7) -> 2184103.2 | FB7: =SUM(FB8:FB9) -> 149748.41 | FC7: =SUM(FC8:FC9) -> 169078.13 | FD7: =SUM(FD8:FD9) -> 187666.98 | FE7: =SUM(FE8:FE9) -> 281507.62 | FF7: =SUM(FF8:FF9) -> 304931.15 | FG7: =SUM(FG8:FG9) -> 219169.43 | FH7: =SUM(FH8:FH9) -> 173199.56 | FI7: =SUM(FI8:FI9) -> 154873.18 | ... FM7: =SUM(FM8:FM9) -> 150344.53 | FN7: =SUM(FB7:FM7) -> 2206735.3 | FO7: =SUM(FO8:FO9) -> 149243.42 | FP7: =SUM(FP8:FP9) -> 166295.46 | FQ7: =SUM(FQ8:FQ9) -> 182401.32 | FR7: =SUM(FR8:FR9) -> 274682.24 | FS7: =SUM(FS8:FS9) -> 252237.34 | FT7: =SUM(FT8:FT9) -> 235349.64 | FU7: =SUM(FU8:FU9) -> 200074.5 | FV7: =SUM(FV8:FV9) -> 147181.8 | ... FZ7: =SUM(FZ8:FZ9) -> 162005.76 | GA7: =SUM(FO7:FZ7) -> 2189083.2 | GB7: =SUM(GB8:GB9) -> 166332.4 | GC7: =SUM(GC8:GC9) -> 201933.86 | GD7: =SUM(GD8:GD9) -> 212122.78 | GE7: =SUM(GE8:GE9) -> 296956.92 | GF7: =SUM(GF8:GF9) -> 271866.36 | GG7: =SUM(GG8:GG9) -> 241006.26 | GH7: =SUM(GH8:GH9) -> 188169.12 | GI7: =SUM(GI8:GI9) -> 166923.58 | ... GM7: =SUM(GM8:GM9) -> 162322.41 | GN7: =SUM(GB7:GM7) -> 2376516.6 | GO7: =SUM(GO8:GO9) -> 151091.36 | GP7: =SUM(GP8:GP9) -> 194691.96 | GQ7: =SUM(GQ8:GQ9) -> 187032.44 | GR7: =SUM(GR8:GR9) -> 278540.33 | GS7: =SUM(GS8:GS9) -> 272569.96 | GT7: =SUM(GT8:GT9) -> 257379.97 | GU7: =SUM(GU8:GU9) -> 210375.63 | GV7: =SUM(GV8:GV9) -> 162344.96 | ... GZ7: =SUM(GZ8:GZ9) -> 189829.5 | HA7: =SUM(GO7:GZ7) -> 2415615 | HB7: =SUM(HB8:HB9) -> 179593.61 | HC7: =SUM(HC8:HC9) -> 188242.01 | HD7: =SUM(HD8:HD9) -> 198297.76 | HE7: =SUM(HE8:HE9) -> 270144.64 | HF7: =SUM(HF8:HF9) -> 272155.56 | HG7: =SUM(HG8:HG9) -> 265138.03 | HH7: =SUM(HH8:HH9) -> 217722.38 | HI7: =SUM(HI8:HI9) -> 176808.33 | ... HM7: =SUM(HM8:HM9) -> 182672.46 | HN7: =SUM(HB7:HM7) -> 2444593.4 | HO7: =SUM(HO8:HO9) -> 196466.89 | HP7: =SUM(HP8:HP9) -> 203087.04 | HQ7: =SUM(HQ8:HQ9) -> 220183.18 | HR7: =SUM(HR8:HR9) -> 276672.84 | HS7: =SUM(HS8:HS9) -> 289703.08 | HT7: =SUM(HT8:HT9) -> 287343.94 | HU7: =SUM(HU8:HU9) -> 219942.09 | HV7: =SUM(HV8:HV9) -> 177320.79 | ... HZ7: =SUM(HZ8:HZ9) -> 182251.55 | IA7: =SUM(HO7:HZ7) -> 2574439.4 | IB7: =SUM(IB8:IB9) -> 188333.85 | IC7: =SUM(IC8:IC9) -> 198469.16 | ID7: =SUM(ID8:ID9) -> 208831.6 | IE7: =SUM(IE8:IE9) -> 275260.05 | IF7: =SUM(IF8:IF9) -> 300346.3 | IG7: =SUM(IG8:IG9) -> 285771.01 | IH7: =SUM(IH8:IH9) -> 242523.15 | II7: =SUM(II8:II9) -> 174956.98 | ... IM7: =SUM(IM8:IM9) -> 151007.6 | IN7: =SUM(IB7:IM7) -> 2467534.9 | IO7: =SUM(IO8:IO9) -> 156213.19 | IP7: =SUM(IP8:IP9) -> 171672.51 | IQ7: =SUM(IQ8:IQ9) -> 224579.59 | IR7: =SUM(IR8:IR9) -> 282017.29 | IS7: =SUM(IS8:IS9) -> 303935.6 | IT7: =SUM(IT8:IT9) -> 291408.41 | IU7: =SUM(IU8:IU9) -> 253305.93 | IV7: =SUM(IV8:IV9) -> 187659.61 | ... IZ7: =SUM(IZ8:IZ9) -> 163807.48 | JA7: =SUM(IO7:IZ7) -> 2490700.8 | JB7: =SUM(JB8:JB9) -> 171817.08 | JC7: =SUM(JC8:JC9) -> 169143.26 | JD7: =SUM(JD8:JD9) -> 0 | JE7: =SUM(JE8:JE9) -> 0 | JF7: =SUM(JF8:JF9) -> 0 | JG7: =SUM(JG8:JG9) -> 0 | JH7: =SUM(JH8:JH9) -> 0 | JI7: =SUM(JI8:JI9) -> 0 | ... JM7: =SUM(JM8:JM9) -> 0 | JN7: =SUM(JB7:JM7) -> 340960.34 | JP7: =IFERROR((( _xlfn.XLOOKUP((DATE(YEAR($JP$5),MONTH($JP$5),1)),SMN.AGRO.DATE,$B7:$JN7) / _xlfn.XLOOKUP((DATE(YEAR($JP$5)-1,MONTH($JP$5),1)),SMN.AGRO.DATE,$B7:$JN7) )-1)*100,"") -> 8.4763145 | JQ7: =IFERROR(((JS7/JR7)-1)*100,"") -> 0.93882513 | JR7: =SUMIFS($B7:$JN7,SMN.AGRO.DATE,">="&DATE(YEAR($JP$5)-1,1,1),SMN.AGRO.DATE,"<="&DATE(YEAR($JP$5)-1,MONTH($JP$5),1)) -> 2467534.9 | JS7: =SUMIFS($B7:$JN7,SMN.AGRO.DATE,">="&DATE(YEAR($JP$5),1,1),SMN.AGRO.DATE,"<="&$JP$5) -> 2490700.8
A8: TOTAL AGRÍCOLA 2/ | B8: 108531.77 | C8: 85945.052 | D8: 80660.203 | E8: 106313.83 | F8: 128519.71 | G8: 118497.68 | H8: 104340.73 | I8: 81941.2 | J8: 59079.982 | K8: 63520.534 | L8: 62314.486 | M8: 49561.85 | N8: =SUM(B8:M8) -> 1049227 | O8: 67274.001 | P8: 84148.432 | Q8: 79879.234 | R8: 96546.007 | S8: 111044.59 | T8: 102267.77 | U8: 97615.615 | V8: 94680.654 | W8: 63046.033 | X8: 60980.854 | Y8: 74687.501 | Z8: 67340.062 | AA8: =SUM(O8:Z8) -> 999510.75 | AB8: 79288.584 | AC8: 107551.71 | AD8: 107985.29 | AE8: 113608.19 | AF8: 132465.34 | AG8: 109841.36 | AH8: 113497.51 | AI8: 85175.387 | AJ8: 75196.329 | AK8: 73561.895 | AL8: 92792.11 | AM8: 83475.142 | AN8: =SUM(AB8:AM8) -> 1174438.8 | AO8: 76475.439 | AP8: 99950.081 | AQ8: 110327.62 | AR8: 143709.65 | AS8: 148146.22 | AT8: 132262.47 | AU8: 110265.84 | AV8: 87064.434 | AW8: 76290.307 | AX8: 78781.295 | AY8: 94934.41 | AZ8: 77212.074 | BA8: =SUM(AO8:AZ8) -> 1235419.8 | BB8: 78078.182 | BC8: 94758.629 | BD8: 104745.78 | BE8: 124620.93 | BF8: 166296.83 | BG8: 135561 | BH8: 105803.84 | BI8: 86841.577 | BJ8: 82228.685 | BK8: 85924.676 | BL8: 102035.79 | BM8: 86193.199 | BN8: =SUM(BB8:BM8) -> 1253089.1 | BO8: 77478.535 | BP8: 99460.454 | BQ8: 108379 | BR8: 169818.16 | BS8: 168764.49 | BT8: 146031.89 | BU8: 112528.9 | BV8: 95144.435 | BW8: 83672.187 | BX8: 87203.298 | BY8: 90571.55 | BZ8: 82143.311 | CA8: =SUM(BO8:BZ8) -> 1321196.2 | CB8: 108565.81 | CC8: 117373.41 | CD8: 108134.15 | CE8: 173489.61 | CF8: 198085.18 | CG8: 175683.38 | CH8: 123119.52 | CI8: 97172.46 | CJ8: 85893.789 | CK8: 93630.749 | CL8: 115539.31 | CM8: 90376.625 | CN8: =SUM(CB8:CM8) -> 1487064 | CO8: 88457.363 | CP8: 106253.72 | CQ8: 124953.75 | CR8: 155672.01 | CS8: 167317.65 | CT8: 158620.1 | CU8: 111134.37 | CV8: 105581.76 | CW8: 92838.116 | CX8: 100526 | CY8: 108301.15 | CZ8: 101252.98 | DA8: =SUM(CO8:CZ8) -> 1420909 | DB8: 107195.56 | DC8: 119358.63 | DD8: 131886.42 | DE8: 158651.52 | DF8: 192545.21 | DG8: 186110.8 | DH8: 141860.33 | DI8: 113553.8 | DJ8: 89157.906 | DK8: 108498.36 | DL8: 118530.29 | DM8: 110265.68 | DN8: =SUM(DB8:DM8) -> 1577614.5 | DO8: 98978.293 | DP8: 115550.95 | DQ8: 139901.12 | DR8: 203492.97 | DS8: 243770.48 | DT8: 204366.94 | DU8: 146566.19 | DV8: 114375.68 | DW8: 107696.35 | DX8: 102379.89 | DY8: 111967.67 | DZ8: 130103.19 | EA8: =SUM(DO8:DZ8) -> 1719149.7 | EB8: 99361.917 | EC8: 125255.3 | ED8: 119438.32 | EE8: 226310.73 | EF8: 250020.86 | EG8: 207652.14 | EH8: 151959.05 | EI8: 117820.72 | EJ8: 105137.98 | EK8: 107906.28 | EL8: 122568.38 | EM8: 123405.77 | EN8: =SUM(EB8:EM8) -> 1756837.5 | EO8: 110238.24 | EP8: 128405.14 | EQ8: 146428.48 | ER8: 250283.95 | ES8: 272296.08 | ET8: 217431.37 | EU8: 162553.04 | EV8: 127701.22 | EW8: 125022.22 | EX8: 137510.18 | EY8: 128270.12 | EZ8: 131244.15 | FA8: =SUM(EO8:EZ8) -> 1937384.2 | FB8: 128980.28 | FC8: 148882.92 | FD8: 166074.5 | FE8: 260263.15 | FF8: 282834.53 | FG8: 197958.29 | FH8: 151031.96 | FI8: 133121.46 | FJ8: 107072.13 | FK8: 113320.55 | FL8: 134184.03 | FM8: 127710.91 | FN8: =SUM(FB8:FM8) -> 1951434.7 | FO8: 122539.17 | FP8: 140566.61 | FQ8: 156002.91 | FR8: 246628.75 | FS8: 224447.04 | FT8: 208717.95 | FU8: 171798.18 | FV8: 119522.68 | FW8: 109880.96 | FX8: 106543.26 | FY8: 124307.94 | FZ8: 133054.65 | GA8: =SUM(FO8:FZ8) -> 1864010.1 | GB8: 141301.46 | GC8: 175352.62 | GD8: 186242.18 | GE8: 270067.6 | GF8: 244949.7 | GG8: 215809.73 | GH8: 161349.38 | GI8: 141226.01 | GJ8: 124918.51 | GK8: 126016.15 | GL8: 142843.13 | GM8: 134124.29 | GN8: =SUM(GB8:GM8) -> 2064200.8 | GO8: 126412.15 | GP8: 168971.65 | GQ8: 160717.15 | GR8: 251014.73 | GS8: 244394.74 | GT8: 230931.42 | GU8: 182544.95 | GV8: 136767.05 | GW8: 137596.82 | GX8: 135544.93 | GY8: 162126.95 | GZ8: 160418.6 | HA8: =SUM(GO8:GZ8) -> 2097441.1 | HB8: 153651.92 | HC8: 161911.93 | HD8: 170986.62 | HE8: 242137.43 | HF8: 244146.88 | HG8: 238483.89 | HH8: 191038.64 | HI8: 151477.55 | HJ8: 130552.46 | HK8: 130482.51 | HL8: 157498.67 | HM8: 154627.03 | HN8: =SUM(HB8:HM8) -> 2126995.5 | HO8: 171162.31 | HP8: 177721.89 | HQ8: 193748.6 | HR8: 249438.87 | HS8: 261838.47 | HT8: 261452.37 | HU8: 194094.03 | HV8: 153311.57 | HW8: 148697.64 | HX8: 140332.62 | HY8: 159567.69 | HZ8: 154781.84 | IA8: =SUM(HO8:HZ8) -> 2266147.9 | IB8: 163273.66 | IC8: 173939.01 | ID8: 182891.34 | IE8: 247598.41 | IF8: 272446.37 | IG8: 259229.34 | IH8: 216109.7 | II8: 150392.29 | IJ8: 119832.14 | IK8: 123363.48 | IL8: 124657.59 | IM8: 123734.51 | IN8: 2157467.8 | IO8: 129811.17 | IP8: 146425.18 | IQ8: 197686.25 | IR8: 253150.49 | IS8: 274201.03 | IT8: 263954.58 | IU8: 226045.69 | IV8: 162604.49 | IW8: 127980.05 | IX8: 124425.62 | IY8: 128229.47 | IZ8: 135615.76 | JA8: 2170129.8 | JB8: 144500.16 | JC8: 142773.53 | JN8: =SUM(JB8:JM8) -> 287273.7 | JP8: =IFERROR((( _xlfn.XLOOKUP((DATE(YEAR($JP$5),MONTH($JP$5),1)),SMN.AGRO.DATE,$B8:$JN8) / _xlfn.XLOOKUP((DATE(YEAR($JP$5)-1,MONTH($JP$5),1)),SMN.AGRO.DATE,$B8:$JN8) )-1)*100,"") -> 9.6022069 | JQ8: =IFERROR(((JS8/JR8)-1)*100,"") -> 0.58688825 | JR8: =SUMIFS($B8:$JN8,SMN.AGRO.DATE,">="&DATE(YEAR($JP$5)-1,1,1),SMN.AGRO.DATE,"<="&DATE(YEAR($JP$5)-1,MONTH($JP$5),1)) -> 2157467.8 | JS8: =SUMIFS($B8:$JN8,SMN.AGRO.DATE,">="&DATE(YEAR($JP$5),1,1),SMN.AGRO.DATE,"<="&$JP$5) -> 2170129.8
A9: TOTAL PECUARIO 2/ | B9: 7904.552 | C9: 7709.6252 | D9: 8351.7082 | E9: 8518.7363 | F9: 8235.4711 | G9: 8873.8017 | H9: 8173.1973 | I9: 8780.9237 | J9: 9085.9626 | K9: 8720.253 | L9: 8931.6574 | M9: 9445.2698 | N9: =SUM(B9:M9) -> 102731.16 | O9: 9142.1404 | P9: 8675.0336 | Q9: 9594.5249 | R9: 9757.2488 | S9: 9674.7847 | T9: 10726.755 | U9: 10244.969 | V9: 10451.644 | W9: 10463.464 | X9: 10345.366 | Y9: 10325.648 | Z9: 11034.828 | AA9: =SUM(O9:Z9) -> 120436.41 | AB9: 12230.111 | AC9: 12662.423 | AD9: 13126.381 | AE9: 13019.876 | AF9: 13217.475 | AG9: 14088.199 | AH9: 13111.17 | AI9: 13567.963 | AJ9: 13977.535 | AK9: 14728.905 | AL9: 13877.849 | AM9: 15708.551 | AN9: =SUM(AB9:AM9) -> 163316.44 | AO9: 14511.027 | AP9: 15040.884 | AQ9: 15698.613 | AR9: 14351.698 | AS9: 15669.062 | AT9: 17400.017 | AU9: 15730.667 | AV9: 14056.321 | AW9: 14052.637 | AX9: 13364 | AY9: 13680 | AZ9: 16049 | BA9: =SUM(AO9:AZ9) -> 179603.93 | BB9: 12378.959 | BC9: 12991.162 | BD9: 12744.278 | BE9: 12707.379 | BF9: 13417.337 | BG9: 13222.002 | BH9: 12481.822 | BI9: 12913.507 | BJ9: 13756.811 | BK9: 13776.167 | BL9: 13058.448 | BM9: 13489.862 | BN9: =SUM(BB9:BM9) -> 156937.73 | BO9: 13954.21 | BP9: 14111.448 | BQ9: 14509.627 | BR9: 14268.919 | BS9: 14667.507 | BT9: 15645.499 | BU9: 15457.854 | BV9: 15610.232 | BW9: 15364.176 | BX9: 14896.487 | BY9: 16698.518 | BZ9: 17258.718 | CA9: =SUM(BO9:BZ9) -> 182443.19 | CB9: 16326.535 | CC9: 16110.366 | CD9: 15226.231 | CE9: 15028.951 | CF9: 17450.915 | CG9: 16675.956 | CH9: 17172.204 | CI9: 16199.15 | CJ9: 17816.497 | CK9: 14730.845 | CL9: 16167.179 | CM9: 15175.956 | CN9: =SUM(CB9:CM9) -> 194080.78 | CO9: 15449.871 | CP9: 16114.758 | CQ9: 15179.629 | CR9: 16103.115 | CS9: 15356.487 | CT9: 16080.099 | CU9: 15834.832 | CV9: 14947.786 | CW9: 15462.428 | CX9: 15901.935 | CY9: 16982.94 | CZ9: 16996.239 | DA9: =SUM(CO9:CZ9) -> 190410.12 | DB9: 17044.086 | DC9: 16594.61 | DD9: 18178.401 | DE9: 17525.559 | DF9: 17472.655 | DG9: 17287.668 | DH9: 18497.872 | DI9: 18717.433 | DJ9: 17421.116 | DK9: 16794.047 | DL9: 16644.675 | DM9: 17338.293 | DN9: =SUM(DB9:DM9) -> 209516.41 | DO9: 17393.578 | DP9: 16760.193 | DQ9: 18382.564 | DR9: 17966.31 | DS9: 18799.404 | DT9: 18441.764 | DU9: 19297.775 | DV9: 18804.105 | DW9: 18839.137 | DX9: 19612.337 | DY9: 19182.22 | DZ9: 20008.739 | EA9: =SUM(DO9:DZ9) -> 223488.13 | EB9: 18569.522 | EC9: 18181.625 | ED9: 19487.517 | EE9: 19608.426 | EF9: 19584.953 | EG9: 20361.19 | EH9: 20902.421 | EI9: 20702.496 | EJ9: 20125.141 | EK9: 20308.473 | EL9: 20023.472 | EM9: 22169.093 | EN9: =SUM(EB9:EM9) -> 240024.33 | EO9: 19999.879 | EP9: 19351.819 | EQ9: 19969.542 | ER9: 20843.566 | ES9: 20742.18 | ET9: 20137.602 | EU9: 20705.876 | EV9: 21153.725 | EW9: 20882.32 | EX9: 20479.88 | EY9: 20221.599 | EZ9: 22231.037 | FA9: =SUM(EO9:EZ9) -> 246719.02 | FB9: 20768.127 | FC9: 20195.209 | FD9: 21592.482 | FE9: 21244.469 | FF9: 22096.615 | FG9: 21211.138 | FH9: 22167.599 | FI9: 21751.718 | FJ9: 20791.354 | FK9: 20628.52 | FL9: 20219.756 | FM9: 22633.628 | FN9: =SUM(FB9:FM9) -> 255300.62 | FO9: 26704.254 | FP9: 25728.845 | FQ9: 26398.417 | FR9: 28053.493 | FS9: 27790.298 | FT9: 26631.691 | FU9: 28276.322 | FV9: 27659.112 | FW9: 26784.194 | FX9: 26353.718 | FY9: 25741.626 | FZ9: 28951.101 | GA9: =SUM(FO9:FZ9) -> 325073.07 | GB9: 25030.947 | GC9: 26581.239 | GD9: 25880.593 | GE9: 26889.313 | GF9: 26916.663 | GG9: 25196.533 | GH9: 26819.739 | GI9: 25697.564 | GJ9: 25632.356 | GK9: 25023.349 | GL9: 24449.429 | GM9: 28198.114 | GN9: =SUM(GB9:GM9) -> 312315.84 | GO9: 24679.209 | GP9: 25720.308 | GQ9: 26315.283 | GR9: 27525.601 | GS9: 28175.218 | GT9: 26448.546 | GU9: 27830.682 | GV9: 25577.909 | GW9: 25298.099 | GX9: 25740.932 | GY9: 25451.212 | GZ9: 29410.903 | HA9: =SUM(GO9:GZ9) -> 318173.9 | HB9: 25941.691 | HC9: 26330.073 | HD9: 27311.142 | HE9: 28007.209 | HF9: 28008.683 | HG9: 26654.141 | HH9: 26683.744 | HI9: 25330.78 | HJ9: 25151.08 | HK9: 25277.621 | HL9: 24856.288 | HM9: 28045.426 | HN9: =SUM(HB9:HM9) -> 317597.88 | HO9: 25304.586 | HP9: 25365.152 | HQ9: 26434.581 | HR9: 27233.969 | HS9: 27864.603 | HT9: 25891.569 | HU9: 25848.065 | HV9: 24009.221 | HW9: 24067.138 | HX9: 24394.337 | HY9: 24408.566 | HZ9: 27469.713 | IA9: =SUM(HO9:HZ9) -> 308291.5 | IB9: 25060.19 | IC9: 24530.149 | ID9: 25940.261 | IE9: 27661.645 | IF9: 27899.936 | IG9: 26541.673 | IH9: 26413.449 | II9: 24564.686 | IJ9: 24632.987 | IK9: 24680.517 | IL9: 24868.5 | IM9: 27273.087 | IN9: 310067.08 | IO9: 26402.014 | IP9: 25247.336 | IQ9: 26893.334 | IR9: 28866.805 | IS9: 29734.566 | IT9: 27453.831 | IU9: 27260.242 | IV9: 25055.123 | IW9: 24873.636 | IX9: 25313.509 | IY9: 25278.875 | IZ9: 28191.722 | JA9: 320570.99 | JB9: 27316.914 | JC9: 26369.728 | JN9: =SUM(JB9:JM9) -> 53686.642 | JP9: =IFERROR((( _xlfn.XLOOKUP((DATE(YEAR($JP$5),MONTH($JP$5),1)),SMN.AGRO.DATE,$B9:$JN9) / _xlfn.XLOOKUP((DATE(YEAR($JP$5)-1,MONTH($JP$5),1)),SMN.AGRO.DATE,$B9:$JN9) )-1)*100,"") -> 3.3682844 | JQ9: =IFERROR(((JS9/JR9)-1)*100,"") -> 3.3876259 | JR9: =SUMIFS($B9:$JN9,SMN.AGRO.DATE,">="&DATE(YEAR($JP$5)-1,1,1),SMN.AGRO.DATE,"<="&DATE(YEAR($JP$5)-1,MONTH($JP$5),1)) -> 310067.08 | JS9: =SUMIFS($B9:$JN9,SMN.AGRO.DATE,">="&DATE(YEAR($JP$5),1,1),SMN.AGRO.DATE,"<="&$JP$5) -> 320570.99
A11: TOTAL AGRÍCOLA | B11: =SUM(B13:B41,B43) -> 347420 | C11: =SUM(C13:C41,C43) -> 320918.03 | D11: =SUM(D13:D41,D43) -> 300526 | E11: =SUM(E13:E41,E43) -> 287841 | F11: =SUM(F13:F41,F43) -> 300599 | G11: =SUM(G13:G41,G43) -> 305359.5 | H11: =SUM(H13:H41,H43) -> 307108.99 | I11: =SUM(I13:I41,I43) -> 273686.5 | ... M11: =SUM(M13:M41,M43) -> 253028.5 | N11: =SUM(B11:M11) -> 3471408 | O11: =SUM(O13:O41,O43) -> 303626 | P11: =SUM(P13:P41,P43) -> 321645 | Q11: =SUM(Q13:Q41,Q43) -> 313371 | R11: =SUM(R13:R41,R43) -> 286938 | S11: =SUM(S13:S41,S43) -> 306321 | T11: =SUM(T13:T41,T43) -> 310347 | U11: =SUM(U13:U41,U43) -> 314627.5 | V11: =SUM(V13:V41,V43) -> 324546 | ... Z11: =SUM(Z13:Z41,Z43) -> 292366 | AA11: =SUM(O11:Z11) -> 3617761.5 | AB11: =SUM(AB13:AB41,AB43) -> 319289 | AC11: =SUM(AC13:AC41,AC43) -> 349602 | AD11: =SUM(AD13:AD41,AD43) -> 331627 | AE11: =SUM(AE13:AE41,AE43) -> 313960 | AF11: =SUM(AF13:AF41,AF43) -> 335326 | AG11: =SUM(AG13:AG41,AG43) -> 328797 | AH11: =SUM(AH13:AH41,AH43) -> 366086 | AI11: =SUM(AI13:AI41,AI43) -> 324828 | ... AM11: =SUM(AM13:AM41,AM43) -> 320015 | AN11: =SUM(AB11:AM11) -> 3981629 | AO11: =SUM(AO13:AO41,AO43) -> 317324.5 | AP11: =SUM(AP13:AP41,AP43) -> 361841 | AQ11: =SUM(AQ13:AQ41,AQ43) -> 347473.25 | AR11: =SUM(AR13:AR41,AR43) -> 357350 | AS11: =SUM(AS13:AS41,AS43) -> 354325.9 | AT11: =SUM(AT13:AT41,AT43) -> 354375 | AU11: =SUM(AU13:AU41,AU43) -> 353351 | AV11: =SUM(AV13:AV41,AV43) -> 334921.33 | ... AZ11: =SUM(AZ13:AZ41,AZ43) -> 322210 | BA11: =SUM(AO11:AZ11) -> 4099924.1 | BB11: =SUM(BB13:BB41,BB43) -> 323805.95 | BC11: =SUM(BC13:BC41,BC43) -> 354298.4 | BD11: =SUM(BD13:BD41,BD43) -> 347644.87 | BE11: =SUM(BE13:BE41,BE43) -> 335629.17 | BF11: =SUM(BF13:BF41,BF43) -> 372026.51 | BG11: =SUM(BG13:BG41,BG43) -> 361658.3 | BH11: =SUM(BH13:BH41,BH43) -> 356062.23 | BI11: =SUM(BI13:BI41,BI43) -> 344368.08 | ... BM11: =SUM(BM13:BM41,BM43) -> 373437.16 | BN11: =SUM(BB11:BM11) -> 4255425.7 | BO11: =SUM(BO13:BO41,BO43) -> 353604.7 | BP11: =SUM(BP13:BP41,BP43) -> 396866.07 | BQ11: =SUM(BQ13:BQ41,BQ43) -> 384531.5 | BR11: =SUM(BR13:BR41,BR43) -> 413001 | BS11: =SUM(BS13:BS41,BS43) -> 400781.2 | BT11: =SUM(BT13:BT41,BT43) -> 387651.4 | BU11: =SUM(BU13:BU41,BU43) -> 385991 | BV11: =SUM(BV13:BV41,BV43) -> 384856 | ... BZ11: =SUM(BZ13:BZ41,BZ43) -> 389544.35 | CA11: =SUM(BO11:BZ11) -> 4650458.4 | CB11: =SUM(CB13:CB41,CB43) -> 389959 | CC11: =SUM(CC13:CC41,CC43) -> 403149 | CD11: =SUM(CD13:CD41,CD43) -> 360168 | CE11: =SUM(CE13:CE41,CE43) -> 381865 | CF11: =SUM(CF13:CF41,CF43) -> 394428 | CG11: =SUM(CG13:CG41,CG43) -> 405433 | CH11: =SUM(CH13:CH41,CH43) -> 391182 | CI11: =SUM(CI13:CI41,CI43) -> 368984 | ... CM11: =SUM(CM13:CM41,CM43) -> 393515 | CN11: =SUM(CB11:CM11) -> 4645392 | CO11: =SUM(CO13:CO41,CO43) -> 382241.55 | CP11: =SUM(CP13:CP41,CP43) -> 410064.65 | CQ11: =SUM(CQ13:CQ41,CQ43) -> 410643.95 | CR11: =SUM(CR13:CR41,CR43) -> 400190.35 | CS11: =SUM(CS13:CS41,CS43) -> 399684.66 | CT11: =SUM(CT13:CT41,CT43) -> 429937.2 | CU11: =SUM(CU13:CU41,CU43) -> 402609.4 | CV11: =SUM(CV13:CV41,CV43) -> 398597.68 | ... CZ11: =SUM(CZ13:CZ41,CZ43) -> 431575.35 | DA11: =SUM(CO11:CZ11) -> 4849853.8 | DB11: =SUM(DB13:DB41,DB43) -> 402135.35 | DC11: =SUM(DC13:DC41,DC43) -> 434754.3 | DD11: =SUM(DD13:DD41,DD43) -> 429154.4 | DE11: =SUM(DE13:DE41,DE43) -> 413229.15 | DF11: =SUM(DF13:DF41,DF43) -> 429619 | DG11: =SUM(DG13:DG41,DG43) -> 451348 | DH11: =SUM(DH13:DH41,DH43) -> 437276 | DI11: =SUM(DI13:DI41,DI43) -> 405912.1 | ... DM11: =SUM(DM13:DM41,DM43) -> 424471 | DN11: =SUM(DB11:DM11) -> 5064638.3 | DO11: =SUM(DO13:DO41,DO43) -> 413052 | DP11: =SUM(DP13:DP41,DP43) -> 422844.2 | DQ11: =SUM(DQ13:DQ41,DQ43) -> 443775.9 | DR11: =SUM(DR13:DR41,DR43) -> 433015.4 | DS11: =SUM(DS13:DS41,DS43) -> 443224.1 | DT11: =SUM(DT13:DT41,DT43) -> 461901.2 | DU11: =SUM(DU13:DU41,DU43) -> 447868.8 | DV11: =SUM(DV13:DV41,DV43) -> 433332.4 | ... DZ11: =SUM(DZ13:DZ41,DZ43) -> 460745.75 | EA11: =SUM(DO11:DZ11) -> 5246800.4 | EB11: =SUM(EB13:EB41,EB43) -> 414032 | EC11: =SUM(EC13:EC41,EC43) -> 463610 | ED11: =SUM(ED13:ED41,ED43) -> 421497 | EE11: =SUM(EE13:EE41,EE43) -> 448982.66 | EF11: =SUM(EF13:EF41,EF43) -> 445690 | EG11: =SUM(EG13:EG41,EG43) -> 454935 | EH11: =SUM(EH13:EH41,EH43) -> 461065 | EI11: =SUM(EI13:EI41,EI43) -> 423839 | ... EM11: =SUM(EM13:EM41,EM43) -> 478521.7 | EN11: =SUM(EB11:EM11) -> 5344396.4 | EO11: =SUM(EO13:EO41,EO43) -> 461526.2 | EP11: =SUM(EP13:EP41,EP43) -> 489465.2 | EQ11: =SUM(EQ13:EQ41,EQ43) -> 490873 | ER11: =SUM(ER13:ER41,ER43) -> 489355 | ES11: =SUM(ES13:ES41,ES43) -> 493854 | ET11: =SUM(ET13:ET41,ET43) -> 507267 | EU11: =SUM(EU13:EU41,EU43) -> 486298 | EV11: =SUM(EV13:EV41,EV43) -> 479286 | ... EZ11: =SUM(EZ13:EZ41,EZ43) -> 521336.2 | FA11: =SUM(EO11:EZ11) -> 5929984.6 | FB11: =SUM(FB13:FB41,FB43) -> 499441 | FC11: =SUM(FC13:FC41,FC43) -> 509942 | FD11: =SUM(FD13:FD41,FD43) -> 495409 | FE11: =SUM(FE13:FE41,FE43) -> 499768 | FF11: =SUM(FF13:FF41,FF43) -> 536325 | FG11: =SUM(FG13:FG41,FG43) -> 479096 | FH11: =SUM(FH13:FH41,FH43) -> 485143 | FI11: =SUM(FI13:FI41,FI43) -> 479642 | ... FM11: =SUM(FM13:FM41,FM43) -> 495397 | FN11: =SUM(FB11:FM11) -> 5898834 | FO11: =SUM(FO13:FO41,FO43) -> 470909 | FP11: =SUM(FP13:FP41,FP43) -> 478191 | FQ11: =SUM(FQ13:FQ41,FQ43) -> 456131 | FR11: =SUM(FR13:FR41,FR43) -> 466305 | FS11: =SUM(FS13:FS41,FS43) -> 474293 | FT11: =SUM(FT13:FT41,FT43) -> 470511 | FU11: =SUM(FU13:FU41,FU43) -> 471265 | FV11: =SUM(FV13:FV41,FV43) -> 432048 | ... FZ11: =SUM(FZ13:FZ41,FZ43) -> 478585 | GA11: =SUM(FO11:FZ11) -> 5509794 | GB11: =SUM(GB13:GB41,GB43) -> 518599.97 | GC11: =SUM(GC13:GC41,GC43) -> 550917.83 | GD11: =SUM(GD13:GD41,GD43) -> 515150.83 | GE11: =SUM(GE13:GE41,GE43) -> 518480.16 | GF11: =SUM(GF13:GF41,GF43) -> 543035.94 | GG11: =SUM(GG13:GG41,GG43) -> 514067.2 | GH11: =SUM(GH13:GH41,GH43) -> 496608.97 | GI11: =SUM(GI13:GI41,GI43) -> 481958.17 | ... GM11: =SUM(GM13:GM41,GM43) -> 516136.75 | GN11: =SUM(GB11:GM11) -> 6119827.8 | GO11: =SUM(GO13:GO41,GO43) -> 512654.49 | GP11: =SUM(GP13:GP41,GP43) -> 551538.56 | GQ11: =SUM(GQ13:GQ41,GQ43) -> 511957.89 | GR11: =SUM(GR13:GR41,GR43) -> 527713.85 | GS11: =SUM(GS13:GS41,GS43) -> 542640.19 | GT11: =SUM(GT13:GT41,GT43) -> 542086.75 | GU11: =SUM(GU13:GU41,GU43) -> 526540.29 | GV11: =SUM(GV13:GV41,GV43) -> 498228.43 | ... GZ11: =SUM(GZ13:GZ41,GZ43) -> 566098.68 | HA11: =SUM(GO11:GZ11) -> 6324236.7 | HB11: =SUM(HB13:HB41,HB43) -> 551351.05 | HC11: =SUM(HC13:HC41,HC43) -> 538428.89 | HD11: =SUM(HD13:HD41,HD43) -> 522245.3 | HE11: =SUM(HE13:HE41,HE43) -> 530109.03 | HF11: =SUM(HF13:HF41,HF43) -> 536660.23 | HG11: =SUM(HG13:HG41,HG43) -> 539397.71 | HH11: =SUM(HH13:HH41,HH43) -> 529850.79 | HI11: =SUM(HI13:HI41,HI43) -> 502596.01 | ... HM11: =SUM(HM13:HM41,HM43) -> 548090.11 | HN11: =SUM(HB11:HM11) -> 6300832.3 | HO11: =SUM(HO13:HO41,HO43) -> 573721.75 | HP11: =SUM(HP13:HP41,HP43) -> 566790.72 | HQ11: =SUM(HQ13:HQ41,HQ43) -> 549624.85 | HR11: =SUM(HR13:HR41,HR43) -> 545933.6 | HS11: =SUM(HS13:HS41,HS43) -> 565304.42 | HT11: =SUM(HT13:HT41,HT43) -> 591854.21 | HU11: =SUM(HU13:HU41,HU43) -> 562639.96 | HV11: =SUM(HV13:HV41,HV43) -> 528359.16 | ... HZ11: =SUM(HZ13:HZ41,HZ43) -> 578039.92 | IA11: =SUM(HO11:HZ11) -> 6656569.3 | IB11: =SUM(IB13:IB41,IB43) -> 577566.45 | IC11: =SUM(IC13:IC41,IC43) -> 587099.77 | ID11: =SUM(ID13:ID41,ID43) -> 543311.28 | IE11: =SUM(IE13:IE41,IE43) -> 565706.9 | IF11: =SUM(IF13:IF41,IF43) -> 565696.29 | IG11: =SUM(IG13:IG41,IG43) -> 571898.18 | IH11: =SUM(IH13:IH41,IH43) -> 560143.6 | II11: =SUM(II13:II41,II43) -> 485562.82 | ... IM11: =SUM(IM13:IM41,IM43) -> 551837.81 | IN11: =SUM(IB11:IM11) -> 6473458.3 | IO11: =SUM(IO13:IO41,IO43) -> 539334.99 | IP11: =SUM(IP13:IP41,IP43) -> 552677.81 | IQ11: =SUM(IQ13:IQ41,IQ43) -> 586044.05 | IR11: =SUM(IR13:IR41,IR43) -> 579863.91 | IS11: =SUM(IS13:IS41,IS43) -> 603796 | IT11: =SUM(IT13:IT41,IT43) -> 596284.92 | IU11: =SUM(IU13:IU41,IU43) -> 591808.21 | IV11: =SUM(IV13:IV41,IV43) -> 519557.33 | ... IZ11: =SUM(IZ13:IZ41,IZ43) -> 581479.97 | JA11: =SUM(IO11:IZ11) -> 6722679.3 | JB11: =SUM(JB13:JB41,JB43) -> 535390.78 | JC11: =SUM(JC13:JC41,JC43) -> 540297.51 | JD11: =SUM(JD13:JD41,JD43) -> 0 | JE11: =SUM(JE13:JE41,JE43) -> 0 | JF11: =SUM(JF13:JF41,JF43) -> 0 | JG11: =SUM(JG13:JG41,JG43) -> 0 | JH11: =SUM(JH13:JH41,JH43) -> 0 | JI11: =SUM(JI13:JI41,JI43) -> 0 | ... JM11: =SUM(JM13:JM41,JM43) -> 0 | JN11: =SUM(JB11:JM11) -> 1075688.3 | JP11: =IFERROR((( _xlfn.XLOOKUP((DATE(YEAR($JP$5),MONTH($JP$5),1)),SMN.AGRO.DATE,$B11:$JN11) / _xlfn.XLOOKUP((DATE(YEAR($JP$5)-1,MONTH($JP$5),1)),SMN.AGRO.DATE,$B11:$JN11) )-1)*100,"") -> 5.3715348 | JQ11: =IFERROR(((JS11/JR11)-1)*100,"") -> 3.8498901 | JR11: =SUMIFS($B11:$JN11,SMN.AGRO.DATE,">="&DATE(YEAR($JP$5)-1,1,1),SMN.AGRO.DATE,"<="&DATE(YEAR($JP$5)-1,MONTH($JP$5),1)) -> 6473458.3 | JS11: =SUMIFS($B11:$JN11,SMN.AGRO.DATE,">="&DATE(YEAR($JP$5),1,1),SMN.AGRO.DATE,"<="&$JP$5) -> 6722679.3
A13: Algodón | G13: 90 | H13: 3887 | I13: 6317 | J13: 3389 | K13: 20 | N13: =SUM(B13:M13) -> 13703 | S13: 2 | T13: 382 | U13: 1574 | V13: 2620 | W13: 2130 | X13: 893 | AA13: =SUM(O13:Z13) -> 7601 | AG13: 15 | AH13: 552 | AI13: 2286 | AJ13: 2079 | AK13: 384 | AL13: 42 | AN13: =SUM(AB13:AM13) -> 5358 | AT13: 2 | AU13: 171 | AV13: 1391 | AW13: 1621.73 | AX13: 504 | AY13: 64 | BA13: =SUM(AO13:AZ13) -> 3753.73 | BH13: 80 | BI13: 668 | BJ13: 886 | BK13: 400 | BL13: 102 | BN13: =SUM(BB13:BM13) -> 2136 | BU13: 88 | BV13: 1343 | BW13: 864 | BX13: 1644 | CA13: =SUM(BO13:BZ13) -> 3939 | CH13: 7 | CI13: 189 | CJ13: 411 | CK13: 1451 | CN13: =SUM(CB13:CM13) -> 2058 | CU13: 35.7 | CV13: 731.9 | CW13: 892.18 | CX13: 32.9 | CY13: 48.1 | DA13: =SUM(CO13:CZ13) -> 1740.78 | DH13: 99 | DI13: 233 | DJ13: 191 | DK13: 135 | DL13: 5 | DN13: =SUM(DB13:DM13) -> 663 | DV13: 155 | DW13: 81 | DX13: 50 | EA13: =SUM(DO13:DZ13) -> 286 | EH13: 10 | EI13: 79 | EJ13: 20 | EK13: 4 | EN13: =SUM(EB13:EM13) -> 113 | EV13: 1 | FA13: =SUM(EO13:EZ13) -> 1 | FN13: =SUM(FB13:FM13) -> 0 | GA13: =SUM(FO13:FZ13) -> 0 | GN13: =SUM(GB13:GM13) -> 0 | HA13: =SUM(GO13:GZ13) -> 0 | HI13: 153 | HJ13: 495.5 | HK13: 93 | HN13: =SUM(HB13:HM13) -> 741.5 | HV13: 99.4 | HW13: 865.8 | IA13: =SUM(HO13:HZ13) -> 965.2 | IB13: 0 | IC13: 0 | ID13: 0 | IE13: 0 | IF13: 0 | IG13: 0 | IH13: 0 | II13: 56 | IJ13: 109 | IK13: 451 | IL13: 0 | IM13: 0 | IN13: 616 | IO13: 0 | IP13: 0 | IQ13: 0 | IR13: 0 | IS13: 0 | IT13: 0 | IU13: 0 | IV13: 51.05 | IW13: 62.55 | IX13: 47.8 | IY13: 196 | IZ13: 0 | JA13: 357.4 | JB13: 0 | JC13: 0 | JN13: =SUM(JB13:JM13) -> 0 | JP13: =IFERROR((( _xlfn.XLOOKUP((DATE(YEAR($JP$5),MONTH($JP$5),1)),SMN.AGRO.DATE,$B13:$JN13) / _xlfn.XLOOKUP((DATE(YEAR($JP$5)-1,MONTH($JP$5),1)),SMN.AGRO.DATE,$B13:$JN13) )-1)*100,"") | JQ13: =IFERROR(((JS13/JR13)-1)*100,"") -> -41.980519 | JR13: =SUMIFS($B13:$JN13,SMN.AGRO.DATE,">="&DATE(YEAR($JP$5)-1,1,1),SMN.AGRO.DATE,"<="&DATE(YEAR($JP$5)-1,MONTH($JP$5),1)) -> 616 | JS13: =SUMIFS($B13:$JN13,SMN.AGRO.DATE,">="&DATE(YEAR($JP$5),1,1),SMN.AGRO.DATE,"<="&$JP$5) -> 357.4 | JU13: =SUM(B13:JN13) -> 88065.22 | JV13: Algodón | JW13: =IF(EXACT(A13,JV13)=TRUE,"OK","VER") -> OK
A14: Arroz Cáscara | B14: 78659 | C14: 40367 | D14: 25341 | E14: 25832 | F14: 55069 | G14: 58356 | H14: 32895 | I14: 24452 | J14: 26437 | K14: 42550 | L14: 39760 | M14: 25302 | N14: =SUM(B14:M14) -> 475020 | O14: 30915 | P14: 24750 | Q14: 19345 | R14: 19204 | S14: 35306 | T14: 44511 | U14: 38494 | V14: 28719 | W14: 29946 | X14: 31536 | Y14: 51525 | Z14: 40497 | AA14: =SUM(O14:Z14) -> 394748 | AB14: 33143 | AC14: 29904 | AD14: 37439 | AE14: 35744 | AF14: 51927 | AG14: 49072 | AH14: 48945 | AI14: 27185 | AJ14: 36652 | AK14: 37260 | AL14: 63651 | AM14: 55773 | AN14: =SUM(AB14:AM14) -> 506695 | AO14: 37949 | AP14: 36246 | AQ14: 31678 | AR14: 56263 | AS14: 61453 | AT14: 66196 | AU14: 43924 | AV14: 31348 | AW14: 37073.23 | AX14: 47620 | AY14: 67395 | AZ14: 44529 | BA14: =SUM(AO14:AZ14) -> 561674.23 | BB14: 34788 | BC14: 39163 | BD14: 34282 | BE14: 33829 | BF14: 54560 | BG14: 55289 | BH14: 39791 | BI14: 32943 | BJ14: 33831 | BK14: 39683 | BL14: 58862 | BM14: 43263 | BN14: =SUM(BB14:BM14) -> 500284 | BO14: 32263 | BP14: 34187 | BQ14: 32712 | BR14: 57896 | BS14: 55207 | BT14: 47317 | BU14: 42232 | BV14: 38752 | BW14: 39922 | BX14: 45449 | BY14: 46333 | BZ14: 46512 | CA14: =SUM(BO14:BZ14) -> 518782 | CB14: 61558 | CC14: 45399 | CD14: 37186 | CE14: 51517 | CF14: 50690 | CG14: 68188 | CH14: 47669 | CI14: 35800 | CJ14: 33424 | CK14: 37079 | CL14: 66678 | CM14: 40370 | CN14: =SUM(CB14:CM14) -> 575558 | CO14: 37058 | CP14: 38179 | CQ14: 50919 | CR14: 45532 | CS14: 55594 | CT14: 59729 | CU14: 43703 | CV14: 39016 | CW14: 39395 | CX14: 49253 | CY14: 54439 | CZ14: 47011 | DA14: =SUM(CO14:CZ14) -> 559828 | DB14: 42085 | DC14: 47631 | DD14: 51819 | DE14: 47912 | DF14: 59051 | DG14: 67499 | DH14: 58455 | DI14: 47950 | DJ14: 37336 | DK14: 58322 | DL14: 68410 | DM14: 60981 | DN14: =SUM(DB14:DM14) -> 647451 | DO14: 41125 | DP14: 44689 | DQ14: 47187 | DR14: 56862 | DS14: 61396 | DT14: 66681 | DU14: 65672 | DV14: 51747 | DW14: 47783 | DX14: 55097 | DY14: 63592 | DZ14: 80668 | EA14: =SUM(DO14:DZ14) -> 682499 | EB14: 46488 | EC14: 48162 | ED14: 47594 | EE14: 60302 | EF14: 63874 | EG14: 69944 | EH14: 62702 | EI14: 56592 | EJ14: 54479 | EK14: 56072 | EL14: 71000 | EM14: 73082 | EN14: =SUM(EB14:EM14) -> 710291 | EO14: 59296 | EP14: 60264 | EQ14: 62366 | ER14: 58530 | ES14: 68817 | ET14: 77999 | EU14: 69551 | EV14: 68009 | EW14: 67034 | EX14: 84529 | EY14: 68967 | EZ14: 77525 | FA14: =SUM(EO14:EZ14) -> 822887 | FB14: 72147 | FC14: 69594 | FD14: 63655 | FE14: 69021 | FF14: 70133 | FG14: 65346 | FH14: 68438 | FI14: 58861 | FJ14: 52385 | FK14: 56060 | FL14: 77920 | FM14: 74209 | FN14: =SUM(FB14:FM14) -> 797769 | FO14: 62866 | FP14: 57352 | FQ14: 56692 | FR14: 66722 | FS14: 71397 | FT14: 74439 | FU14: 72387 | FV14: 58205 | FW14: 54415 | FX14: 49906 | FY14: 66046 | FZ14: 74529 | GA14: =SUM(FO14:FZ14) -> 764956 | GB14: 67425 | GC14: 75251.69 | GD14: 79752.9 | GE14: 77880 | GF14: 83212.85 | GG14: 86109 | GH14: 65157.98 | GI14: 63093.89 | GJ14: 54573.5 | GK14: 59217.929 | GL14: 81317.859 | GM14: 70289.105 | GN14: =SUM(GB14:GM14) -> 863281.7 | GO14: 54058.408 | GP14: 71164.889 | GQ14: 59931.92 | GR14: 80060.39 | GS14: 81472.864 | GT14: 89099 | GU14: 74768.84 | GV14: 59971.92 | GW14: 66650.309 | GX14: 70435.09 | GY14: 85932.95 | GZ14: 82172.3 | HA14: =SUM(GO14:GZ14) -> 875718.88 | HB14: 54981.85 | HC14: 67254 | HD14: 68106.73 | HE14: 84434.55 | HF14: 82294.96 | HG14: 87878.81 | HH14: 72235 | HI14: 69547.4 | HJ14: 61911.39 | HK14: 63021.5 | HL14: 83036.5 | HM14: 73681.5 | HN14: =SUM(HB14:HM14) -> 868384.19 | HO14: 61448 | HP14: 70011.5 | HQ14: 70501 | HR14: 71591.5 | HS14: 79986 | HT14: 86673 | HU14: 70026.5 | HV14: 70482 | HW14: 73743.4 | HX14: 77064 | HY14: 93705.3 | HZ14: 86241 | IA14: =SUM(HO14:HZ14) -> 911473.2 | IB14: 65686 | IC14: 68139 | ID14: 66248 | IE14: 74587.7 | IF14: 81028 | IG14: 86307.1 | IH14: 82376.8 | II14: 66421.8 | IJ14: 59321.9 | IK14: 68908.4 | IL14: 72255.15 | IM14: 69212.9 | IN14: 860492.75 | IO14: 49265.7 | IP14: 60288.7 | IQ14: 68280.7 | IR14: 70947.8 | IS14: 81000.5 | IT14: 75799 | IU14: 85874 | IV14: 70397.6 | IW14: 67160.6 | IX14: 71077.6 | IY14: 75651.3 | IZ14: 71484.1 | JA14: 847227.6 | JB14: 59426 | JC14: 66775.86 | JN14: =SUM(JB14:JM14) -> 126201.86 | JP14: =IFERROR((( _xlfn.XLOOKUP((DATE(YEAR($JP$5),MONTH($JP$5),1)),SMN.AGRO.DATE,$B14:$JN14) / _xlfn.XLOOKUP((DATE(YEAR($JP$5)-1,MONTH($JP$5),1)),SMN.AGRO.DATE,$B14:$JN14) )-1)*100,"") -> 3.2814692 | JQ14: =IFERROR(((JS14/JR14)-1)*100,"") -> -1.541576 | JR14: =SUMIFS($B14:$JN14,SMN.AGRO.DATE,">="&DATE(YEAR($JP$5)-1,1,1),SMN.AGRO.DATE,"<="&DATE(YEAR($JP$5)-1,MONTH($JP$5),1)) -> 860492.75 | JS14: =SUMIFS($B14:$JN14,SMN.AGRO.DATE,">="&DATE(YEAR($JP$5),1,1),SMN.AGRO.DATE,"<="&$JP$5) -> 847227.6 | JU14: =SUM(B14:JN14) -> 27742445 | JV14: Arroz Cáscara | JW14: =IF(EXACT(A14,JV14)=TRUE,"OK","VER") -> OK
A15: Cacao | B15: 440 | C15: 461 | D15: 505 | E15: 567 | F15: 543 | G15: 533 | H15: 586 | I15: 532 | J15: 463 | K15: 491 | L15: 433 | M15: 410 | N15: =SUM(B15:M15) -> 5964 | O15: 570 | P15: 561 | Q15: 640 | R15: 738 | S15: 842 | T15: 925 | U15: 866 | V15: 750 | W15: 644 | X15: 635 | Y15: 622 | Z15: 619 | AA15: =SUM(O15:Z15) -> 8412 | AB15: 675 | AC15: 690 | AD15: 758 | AE15: 810 | AF15: 1141 | AG15: 978 | AH15: 913 | AI15: 884 | AJ15: 934 | AK15: 1024 | AL15: 984 | AM15: 1020 | AN15: =SUM(AB15:AM15) -> 10811 | AO15: 714 | AP15: 719 | AQ15: 849 | AR15: 1075 | AS15: 1424 | AT15: 1277 | AU15: 1066 | AV15: 1008 | AW15: 1181.22 | AX15: 1062.34 | AY15: 996 | AZ15: 1018 | BA15: =SUM(AO15:AZ15) -> 12389.56 | BB15: 1131 | BC15: 1135 | BD15: 1223 | BE15: 1353 | BF15: 1877 | BG15: 2022 | BH15: 1904 | BI15: 1728 | BJ15: 1848 | BK15: 2173 | BL15: 2348 | BM15: 2258 | BN15: =SUM(BB15:BM15) -> 21000 | BO15: 1410 | BP15: 1288 | BQ15: 1460 | BR15: 1699 | BS15: 1938 | BT15: 2087 | BU15: 1802 | BV15: 1490 | BW15: 1284 | BX15: 1490 | BY15: 2082 | BZ15: 1611 | CA15: =SUM(BO15:BZ15) -> 19641 | CB15: 1431 | CC15: 1432 | CD15: 1499 | CE15: 1863 | CF15: 2259 | CG15: 2453 | CH15: 2429 | CI15: 2621 | CJ15: 2428 | CK15: 2848 | CL15: 2707 | CM15: 2768 | CN15: =SUM(CB15:CM15) -> 26738 | CO15: 1764 | CP15: 2002 | CQ15: 1932 | CR15: 2310 | CS15: 2815 | CT15: 2927 | CU15: 2707 | CV15: 2695 | CW15: 2824 | CX15: 3071 | CY15: 3527 | CZ15: 3553 | DA15: =SUM(CO15:CZ15) -> 32127 | DB15: 2530 | DC15: 2628 | DD15: 2604 | DE15: 3080 | DF15: 3400 | DG15: 3725 | DH15: 3286 | DI15: 3380 | DJ15: 2981 | DK15: 3389 | DL15: 3512 | DM15: 3768 | DN15: =SUM(DB15:DM15) -> 38283 | DO15: 2750 | DP15: 3406 | DQ15: 2955 | DR15: 3146 | DS15: 3795 | DT15: 4589 | DU15: 3338 | DV15: 3182 | DW15: 4052 | DX15: 3350 | DY15: 3613 | DZ15: 4431 | EA15: =SUM(DO15:DZ15) -> 42607 | EB15: 2858 | EC15: 2966 | ED15: 3053 | EE15: 3552 | EF15: 4592 | EG15: 5195 | EH15: 4344 | EI15: 3595 | EJ15: 3433 | EK15: 4002 | EL15: 4196 | EM15: 4211 | EN15: =SUM(EB15:EM15) -> 45997 | EO15: 2657 | EP15: 3463 | EQ15: 3141 | ER15: 4094 | ES15: 5086 | ET15: 5038 | EU15: 4958 | EV15: 4418 | EW15: 4477 | EX15: 4543 | EY15: 5138 | EZ15: 4427 | FA15: =SUM(EO15:EZ15) -> 51440 | FB15: 3709 | FC15: 4096 | FD15: 3875 | FE15: 4532 | FF15: 5432 | FG15: 5409 | FH15: 5232 | FI15: 5063 | FJ15: 4402 | FK15: 4783 | FL15: 4790 | FM15: 4815 | FN15: =SUM(FB15:FM15) -> 56138 | FO15: 4036 | FP15: 4400 | FQ15: 4574 | FR15: 4572 | FS15: 5159 | FT15: 5594 | FU15: 4607 | FV15: 4209 | FW15: 3652 | FX15: 4381 | FY15: 5021 | FZ15: 3980 | GA15: =SUM(FO15:FZ15) -> 54185 | GB15: 5323.4 | GC15: 5443.2 | GD15: 5041.7 | GE15: 5927.5 | GF15: 5817.6 | GG15: 6405.4 | GH15: 5769.5 | GI15: 5583.9 | GJ15: 4971.7 | GK15: 5572.4 | GL15: 5564.54 | GM15: 5365.6 | GN15: =SUM(GB15:GM15) -> 66786.44 | GO15: 3771.6 | GP15: 4398 | GQ15: 4526.3 | GR15: 5439.8 | GS15: 6887.8 | GT15: 7498.5 | GU15: 5495.3 | GV15: 5257.3 | GW15: 4411.9 | GX15: 4713.41 | GY15: 5866.7 | GZ15: 5129.3 | HA15: =SUM(GO15:GZ15) -> 63395.91 | HB15: 4242.1 | HC15: 4793.7 | HD15: 5496.7 | HE15: 5799.3 | HF15: 6902.9 | HG15: 7554.5 | HH15: 6180.3 | HI15: 5118.7 | HJ15: 4768.2 | HK15: 4642.6 | HL15: 5317.1 | HM15: 5596.4 | HN15: =SUM(HB15:HM15) -> 66412.5 | HO15: 4385.6 | HP15: 5084.5 | HQ15: 5488.4 | HR15: 5703.3 | HS15: 7583.9 | HT15: 7781.5 | HU15: 6792.2 | HV15: 4837.7 | HW15: 5045.1 | HX15: 4120.5 | HY15: 4279.8 | HZ15: 4016.3 | IA15: =SUM(HO15:HZ15) -> 65118.8 | IB15: 4507.9 | IC15: 5041 | ID15: 5816.5 | IE15: 7607.5 | IF15: 8792.85 | IG15: 7956.03 | IH15: 6590.1 | II15: 4324.5 | IJ15: 4033.3 | IK15: 3080 | IL15: 3114.3 | IM15: 2897.5 | IN15: 63761.48 | IO15: 3339.5 | IP15: 3481.1 | IQ15: 5809.03 | IR15: 8955.7 | IS15: 9540.8 | IT15: 9429 | IU15: 7925.5 | IV15: 4546.7 | IW15: 3687.2 | IX15: 3040 | IY15: 2870 | IZ15: 3077.75 | JA15: 65702.28 | JB15: 2586.7 | JC15: 2934.25 | JN15: =SUM(JB15:JM15) -> 5520.95 | JP15: =IFERROR((( _xlfn.XLOOKUP((DATE(YEAR($JP$5),MONTH($JP$5),1)),SMN.AGRO.DATE,$B15:$JN15) / _xlfn.XLOOKUP((DATE(YEAR($JP$5)-1,MONTH($JP$5),1)),SMN.AGRO.DATE,$B15:$JN15) )-1)*100,"") -> 6.2208801 | JQ15: =IFERROR(((JS15/JR15)-1)*100,"") -> 3.043844 | JR15: =SUMIFS($B15:$JN15,SMN.AGRO.DATE,">="&DATE(YEAR($JP$5)-1,1,1),SMN.AGRO.DATE,"<="&DATE(YEAR($JP$5)-1,MONTH($JP$5),1)) -> 63761.48 | JS15: =SUMIFS($B15:$JN15,SMN.AGRO.DATE,">="&DATE(YEAR($JP$5),1,1),SMN.AGRO.DATE,"<="&$JP$5) -> 65702.28 | JU15: =SUM(B15:JN15) -> 1644861.8 | JV15: Cacao | JW15: =IF(EXACT(A15,JV15)=TRUE,"OK","VER") -> OK
A16: Café | B16: 173 | C16: 1048 | D16: 3732 | E16: 11054 | F16: 11248 | G16: 7515 | H16: 2921 | I16: 1605 | N16: =SUM(B16:M16) -> 39296 | O16: 269 | P16: 2377 | Q16: 5632 | R16: 10286 | S16: 10312 | T16: 6525 | U16: 2807 | V16: 951 | W16: 124 | X16: 17 | Y16: 8 | Z16: 6 | AA16: =SUM(O16:Z16) -> 39314 | AB16: 1613 | AC16: 4364 | AD16: 6938 | AE16: 10308 | AF16: 11150 | AG16: 6565 | AH16: 2322 | AI16: 1135 | AJ16: 39 | AK16: 27 | AL16: 10 | AM16: 3 | AN16: =SUM(AB16:AM16) -> 44474 | AO16: 1138 | AP16: 2577 | AQ16: 6794 | AR16: 12194 | AS16: 12227 | AT16: 8136 | AU16: 3936 | AV16: 1051 | AW16: 391.55 | AX16: 111.8 | AY16: 85 | AZ16: 2 | BA16: =SUM(AO16:AZ16) -> 48643.35 | BB16: 1024 | BC16: 2519 | BD16: 6315 | BE16: 12272 | BF16: 16117 | BG16: 8923 | BH16: 3947 | BI16: 992 | BJ16: 313 | BK16: 256 | BL16: 183 | BM16: 54 | BN16: =SUM(BB16:BM16) -> 52915 | BO16: 158 | BP16: 1772 | BQ16: 6038 | BR16: 16264 | BS16: 16265 | BT16: 12510 | BU16: 5050 | BV16: 1936 | BW16: 700 | BX16: 199 | BY16: 195 | BZ16: 84 | CA16: =SUM(BO16:BZ16) -> 61171 | CB16: 337 | CC16: 2510 | CD16: 5864 | CE16: 17714 | CF16: 21542 | CG16: 13512 | CH16: 4473 | CI16: 1343 | CJ16: 499 | CK16: 461 | CL16: 416 | CM16: 42 | CN16: =SUM(CB16:CM16) -> 68713 | CO16: 201 | CP16: 1415 | CQ16: 4678 | CR16: 14359 | CS16: 13779 | CT16: 9746 | CU16: 2455 | CV16: 834 | CW16: 168 | CX16: 169 | CY16: 31 | CZ16: 34 | DA16: =SUM(CO16:CZ16) -> 47869 | DB16: 192 | DC16: 1248 | DD16: 5519 | DE16: 12944 | DF16: 17410 | DG16: 12886 | DH16: 4690 | DI16: 1633 | DJ16: 150 | DK16: 148 | DL16: 1 | DN16: =SUM(DB16:DM16) -> 56821 | DO16: 284 | DP16: 2353 | DQ16: 7658 | DR16: 21059 | DS16: 27507 | DT16: 16420 | DU16: 5074 | DV16: 1015 | DW16: 372 | DX16: 211 | DY16: 104 | DZ16: 108 | EA16: =SUM(DO16:DZ16) -> 82165 | EB16: 199 | EC16: 2432 | ED16: 4456 | EE16: 24594 | EF16: 27495 | EG16: 15785 | EH16: 5855 | EI16: 1241 | EJ16: 85 | EK16: 119 | EL16: 37 | EM16: 22 | EN16: =SUM(EB16:EM16) -> 82320 | EO16: 196 | EP16: 1824 | EQ16: 6184 | ER16: 28993 | ES16: 30518 | ET16: 16511 | EU16: 6643 | EV16: 103 | EW16: 99 | EX16: 66 | EY16: 35 | EZ16: 25 | FA16: =SUM(EO16:EZ16) -> 91197 | FB16: 185 | FC16: 2582 | FD16: 9028 | FE16: 28455 | FF16: 31872 | FG16: 14757 | FH16: 3702 | FI16: 546 | FJ16: 113 | FK16: 97 | FL16: 38 | FM16: 49 | FN16: =SUM(FB16:FM16) -> 91424 | FO16: 183 | FP16: 3060 | FQ16: 9296 | FR16: 27302 | FS16: 20463 | FT16: 14741 | FU16: 6556 | FV16: 1422 | FW16: 622 | FX16: 60 | FY16: 42 | FZ16: 1693 | GA16: =SUM(FO16:FZ16) -> 85440 | GB16: 244.3 | GC16: 3570 | GD16: 10023.5 | GE16: 27525.5 | GF16: 20140.5 | GG16: 13350.5 | GH16: 4158.5 | GI16: 1834.5 | GJ16: 1702.5 | GK16: 124.5 | GL16: 73 | GM16: 61.6 | GN16: =SUM(GB16:GM16) -> 82808.9 | GO16: 640.5 | GP16: 4221.2 | GQ16: 8160 | GR16: 22655.5 | GS16: 18521.5 | GT16: 12119.8 | GU16: 6506.5 | GV16: 2029 | GW16: 2308 | GX16: 355.3 | GY16: 264.5 | GZ16: 211.8 | HA16: =SUM(GO16:GZ16) -> 77993.6 | HB16: 1647 | HC16: 4047.5 | HD16: 7454 | HE16: 19981.1 | HF16: 18962.5 | HG16: 13148.6 | HH16: 5802.5 | HI16: 2113.5 | HJ16: 1242.5 | HK16: 315.5 | HL16: 299 | HM16: 231 | HN16: =SUM(HB16:HM16) -> 75244.7 | HO16: 1766 | HP16: 4439 | HQ16: 10766 | HR16: 23006 | HS16: 21140 | HT16: 13305.5 | HU16: 3970 | HV16: 1979 | HW16: 365 | HX16: 146.5 | HY16: 123 | HZ16: 148 | IA16: =SUM(HO16:HZ16) -> 81154 | IB16: 1801 | IC16: 4239.5 | ID16: 9278.5 | IE16: 20453 | IF16: 22331 | IG16: 14085.5 | IH16: 6144 | II16: 3436.2 | IJ16: 1135 | IK16: 0 | IL16: 0 | IM16: 0 | IN16: 82903.7 | IO16: 1572.8 | IP16: 4027.5 | IQ16: 10431 | IR16: 20797 | IS16: 21573.7 | IT16: 14450.5 | IU16: 6169.5 | IV16: 4361.6 | IW16: 1235 | IX16: 0 | IY16: 0 | IZ16: 0 | JA16: 84618.6 | JB16: 1194 | JC16: 2497 | JN16: =SUM(JB16:JM16) -> 3691 | JP16: =IFERROR((( _xlfn.XLOOKUP((DATE(YEAR($JP$5),MONTH($JP$5),1)),SMN.AGRO.DATE,$B16:$JN16) / _xlfn.XLOOKUP((DATE(YEAR($JP$5)-1,MONTH($JP$5),1)),SMN.AGRO.DATE,$B16:$JN16) )-1)*100,"") | JQ16: =IFERROR(((JS16/JR16)-1)*100,"") -> 2.0685446 | JR16: =SUMIFS($B16:$JN16,SMN.AGRO.DATE,">="&DATE(YEAR($JP$5)-1,1,1),SMN.AGRO.DATE,"<="&DATE(YEAR($JP$5)-1,MONTH($JP$5),1)) -> 82903.7 | JS16: =SUMIFS($B16:$JN16,SMN.AGRO.DATE,">="&DATE(YEAR($JP$5),1,1),SMN.AGRO.DATE,"<="&$JP$5) -> 84618.6 | JU16: =SUM(B16:JN16) -> 2760353.7 | JV16: Café | JW16: =IF(EXACT(A16,JV16)=TRUE,"OK","VER") -> OK
A17: Camu Camu | N17: =SUM(B17:M17) -> 0 | AA17: =SUM(O17:Z17) -> 0 | AN17: =SUM(AB17:AM17) -> 0 | BA17: =SUM(AO17:AZ17) -> 0 | BN17: =SUM(BB17:BM17) -> 0 | CA17: =SUM(BO17:BZ17) -> 0 | CN17: =SUM(CB17:CM17) -> 0 | DA17: =SUM(CO17:CZ17) -> 0 | DN17: =SUM(DB17:DM17) -> 0 | EA17: =SUM(DO17:DZ17) -> 0 | EN17: =SUM(EB17:EM17) -> 0 | FA17: =SUM(EO17:EZ17) -> 0 | FN17: =SUM(FB17:FM17) -> 0 | GA17: =SUM(FO17:FZ17) -> 0 | GN17: =SUM(GB17:GM17) -> 0 | HA17: =SUM(GO17:GZ17) -> 0 | HN17: =SUM(HB17:HM17) -> 0 | IA17: =SUM(HO17:HZ17) -> 0 | IB17: 0 | IC17: 0 | ID17: 0 | IE17: 0 | IF17: 0 | IG17: 0 | IH17: 0 | II17: 0 | IJ17: 0 | IK17: 0 | IL17: 0 | IM17: 0 | IN17: 0 | IO17: 0 | IP17: 0 | IQ17: 0 | IR17: 0 | IS17: 0 | IT17: 0 | IU17: 0 | IV17: 0 | IW17: 0 | IX17: 0 | IY17: 0 | IZ17: 0 | JA17: 0 | JB17: 0 | JC17: 0 | JN17: =SUM(JB17:JM17) -> 0 | JP17: =IFERROR((( _xlfn.XLOOKUP((DATE(YEAR($JP$5),MONTH($JP$5),1)),SMN.AGRO.DATE,$B17:$JN17) / _xlfn.XLOOKUP((DATE(YEAR($JP$5)-1,MONTH($JP$5),1)),SMN.AGRO.DATE,$B17:$JN17) )-1)*100,"") | JQ17: =IFERROR(((JS17/JR17)-1)*100,"") | JR17: =SUMIFS($B17:$JN17,SMN.AGRO.DATE,">="&DATE(YEAR($JP$5)-1,1,1),SMN.AGRO.DATE,"<="&DATE(YEAR($JP$5)-1,MONTH($JP$5),1)) -> 0 | JS17: =SUMIFS($B17:$JN17,SMN.AGRO.DATE,">="&DATE(YEAR($JP$5),1,1),SMN.AGRO.DATE,"<="&$JP$5) -> 0 | JU17: =SUM(B17:JN17) -> 0 | JV17: Camu Camu | JW17: =IF(EXACT(A17,JV17)=TRUE,"OK","VER") -> OK
A18: Caña de Azúcar | B18: 14920 | C18: 15524 | D18: 16571 | E18: 17656 | F18: 17362 | G18: 17024 | H18: 17201 | I18: 16452 | J18: 15706 | K18: 14959 | L18: 14563 | M18: 15597 | N18: =SUM(B18:M18) -> 193535 | O18: 15932 | P18: 16800 | Q18: 17483 | R18: 17472 | S18: 18246 | T18: 18468 | U18: 18401 | V18: 18652 | W18: 17996 | X18: 17858 | Y18: 17535 | Z18: 25701 | AA18: =SUM(O18:Z18) -> 220544 | AB18: 17905 | AC18: 18684 | AD18: 18431 | AE18: 18684 | AF18: 19520 | AG18: 19515 | AH18: 19952 | AI18: 22301 | AJ18: 21188 | AK18: 21740 | AL18: 22067 | AM18: 19946 | AN18: =SUM(AB18:AM18) -> 239933 | AO18: 20271 | AP18: 22025 | AQ18: 20549 | AR18: 22652 | AS18: 20728 | AT18: 22945 | AU18: 23298 | AV18: 22711 | AW18: 22525 | AX18: 22530 | AY18: 22545 | AZ18: 12754 | BA18: =SUM(AO18:AZ18) -> 255533 | BB18: 20981 | BC18: 23722 | BD18: 20710 | BE18: 22142 | BF18: 22375 | BG18: 22593 | BH18: 22893 | BI18: 22780 | BJ18: 22183 | BK18: 24583 | BL18: 21936 | BM18: 21197 | BN18: =SUM(BB18:BM18) -> 268095 | BO18: 22047 | BP18: 22898 | BQ18: 25477 | BR18: 23164 | BS18: 24680 | BT18: 23419 | BU18: 25823 | BV18: 23500 | BW18: 26154 | BX18: 22886 | BY18: 25728 | BZ18: 18299 | CA18: =SUM(BO18:BZ18) -> 284075 | CB18: 15579 | CC18: 28819 | CD18: 15589 | CE18: 14939 | CF18: 15064 | CG18: 14575 | CH18: 18007 | CI18: 17715 | CJ18: 17178 | CK18: 17232 | CL18: 17050 | CM18: 16418 | CN18: =SUM(CB18:CM18) -> 208165 | CO18: 24512.95 | CP18: 22693.35 | CQ18: 22817.35 | CR18: 22274.2 | CS18: 22752.95 | CT18: 34401.05 | CU18: 27320.2 | CV18: 26591.5 | CW18: 26728.6 | CX18: 26613.83 | CY18: 27084.8 | CZ18: 26901.25 | DA18: =SUM(CO18:CZ18) -> 310692.03 | DB18: 23599.9 | DC18: 23183 | DD18: 23981 | DE18: 23808 | DF18: 24610 | DG18: 31888 | DH18: 28465 | DI18: 28161 | DJ18: 27804 | DK18: 27861 | DL18: 27897 | DM18: 24458 | DN18: =SUM(DB18:DM18) -> 315715.9 | DO18: 21954 | DP18: 21856 | DQ18: 27856 | DR18: 18955 | DS18: 23317 | DT18: 23816 | DU18: 23993 | DV18: 23051 | DW18: 24738 | DX18: 23834 | DY18: 24537 | DZ18: 25894 | EA18: =SUM(DO18:DZ18) -> 283801 | EB18: 16627 | EC18: 17988 | ED18: 19782 | EE18: 18330 | EF18: 22129 | EG18: 21135 | EH18: 19274 | EI18: 16900 | EJ18: 19175 | EK18: 18232 | EL18: 19819 | EM18: 19282 | EN18: =SUM(EB18:EM18) -> 228673 | EO18: 13898 | EP18: 17462 | EQ18: 17256 | ER18: 13718 | ES18: 16473 | ET18: 12861 | EU18: 10086 | EV18: 12766 | EW18: 15310 | EX18: 14553 | EY18: 16835 | EZ18: 14663 | FA18: =SUM(EO18:EZ18) -> 175881 | FB18: 12173 | FC18: 12689 | FD18: 12023 | FE18: 10746 | FF18: 15506 | FG18: 8618 | FH18: 9625 | FI18: 8421 | FJ18: 11818 | FK18: 9801 | FL18: 12191 | FM18: 11310 | FN18: =SUM(FB18:FM18) -> 134921 | FO18: 13826 | FP18: 15081 | FQ18: 13648 | FR18: 13578 | FS18: 13898 | FT18: 10738 | FU18: 10477 | FV18: 10546 | FW18: 12580 | FX18: 15039 | FY18: 12415 | FZ18: 11701 | GA18: =SUM(FO18:FZ18) -> 153527 | GB18: 11065 | GC18: 13229 | GD18: 12072 | GE18: 12034 | GF18: 12405 | GG18: 9703 | GH18: 9304 | GI18: 7196 | GJ18: 10616 | GK18: 9275 | GL18: 10000 | GM18: 9839 | GN18: =SUM(GB18:GM18) -> 126738 | GO18: 16209 | GP18: 17618 | GQ18: 18089 | GR18: 15814 | GS18: 15081 | GT18: 13308 | GU18: 13369 | GV18: 12372 | GW18: 14454 | GX18: 11624 | GY18: 10124 | GZ18: 10964.5 | HA18: =SUM(GO18:GZ18) -> 169026.5 | HB18: 11184.5 | HC18: 14558 | HD18: 16675 | HE18: 14935 | HF18: 14060 | HG18: 13737 | HH18: 12335 | HI18: 12656.5 | HJ18: 13763 | HK18: 11337 | HL18: 10832 | HM18: 10462 | HN18: =SUM(HB18:HM18) -> 156535 | HO18: 11106.1 | HP18: 12883 | HQ18: 18247 | HR18: 16386 | HS18: 13974.45 | HT18: 14744 | HU18: 12225 | HV18: 12370.5 | HW18: 14687 | HX18: 11619 | HY18: 10155 | HZ18: 9138 | IA18: =SUM(HO18:HZ18) -> 157535.05 | IB18: 12112 | IC18: 13203 | ID18: 14579 | IE18: 13667 | IF18: 14223 | IG18: 12939 | IH18: 13031 | II18: 11457 | IJ18: 11582 | IK18: 10920.5 | IL18: 11240 | IM18: 12016 | IN18: 150969.5 | IO18: 14006 | IP18: 13868 | IQ18: 15022 | IR18: 13350 | IS18: 14052 | IT18: 11035 | IU18: 11378 | IV18: 10421 | IW18: 9446 | IX18: 10110 | IY18: 9530 | IZ18: 9606 | JA18: 141824 | JB18: 9609 | JC18: 11079 | JN18: =SUM(JB18:JM18) -> 20688 | JP18: =IFERROR((( _xlfn.XLOOKUP((DATE(YEAR($JP$5),MONTH($JP$5),1)),SMN.AGRO.DATE,$B18:$JN18) / _xlfn.XLOOKUP((DATE(YEAR($JP$5)-1,MONTH($JP$5),1)),SMN.AGRO.DATE,$B18:$JN18) )-1)*100,"") -> -20.056591 | JQ18: =IFERROR(((JS18/JR18)-1)*100,"") -> -6.0578461 | JR18: =SUMIFS($B18:$JN18,SMN.AGRO.DATE,">="&DATE(YEAR($JP$5)-1,1,1),SMN.AGRO.DATE,"<="&DATE(YEAR($JP$5)-1,MONTH($JP$5),1)) -> 150969.5 | JS18: =SUMIFS($B18:$JN18,SMN.AGRO.DATE,">="&DATE(YEAR($JP$5),1,1),SMN.AGRO.DATE,"<="&$JP$5) -> 141824 | JU18: =SUM(B18:JN18) -> 8392814 | JV18: Caña de Azúcar | JW18: =IF(EXACT(A18,JV18)=TRUE,"OK","VER") -> OK
